Workbook

Sheet 行为概览
F2: 等级下限 | G2: 等级上限 | H2: 平均每日耗时(m) | I2: 每日耗时(h) | J2: 经验效率 | K2: 宠物经验效率 | L2: 银币权重 | M2: 金币权重 | N2: 符石 | O2: 公会DKP | P2: 职业贡献 | Q2: 声望值 | R2: 荣誉值 | S2: 节日积分 | T2: 每日活跃度 | U2: 每日活跃度 | W2: 消耗类属性
A3: 单人 | B3: 师门任务 | C3: 日常活动 | D3: 职业日常 | E3: 每日2轮 | F3: 15 | G3: 150 | H3: 20 | I3: =H3/60 -> 0.33333333 | J3: 50 | K3: 3 | L3: 4 | M3: 8 | W3: 经验
A4: 多人(至少3人) | B4: 抓鬼 | D4: 日常副本 | E4: 每日5轮普通 | F4: 20 | G4: 150 | H4: 120 | I4: =H4/60 -> 2 | J4: 3.3 | K4: 0.55 | L4: 1.65 | W4: 宠物经验
A5: 单人 | B5: 平定安邦 | D5: 英雄试炼 | E5: 每日1次 | F5: 20 | G5: 150 | H5: 5 | I5: =H5/60 -> 0.083333333 | J5: 30 | L5: 0.5 | W5: 银币
A6: 单人 | B6: 秘境降妖 | D6: 冰封王座 | E6: 每日25关 | F6: 40 | G6: 150 | H6: 60 | I6: =H6/60 -> 1 | J6: 15 | K6: 1.5 | L6: 1 | M6: 10 | W6: 金币
A7: 单人 | B7: 宝图 | D7: 考古 | E7: 每日10张图15次 | F7: 25 | G7: 150 | H7: 20 | I7: =H7/60 -> 0.33333333 | K7: 2 | W7: 符石
B8: 运镖 | D8: 运镖 | F8: 30 | G8: 150 | H8: 0 | I8: =H8/60 -> 0 | W8: 公会DKP | X8: 帮贡
A9: 多人(至少3人) | B9: 副本 | D9: 卡拉赞系列 | E9: 每日1次 | F9: 40 | G9: 150 | H9: 0 | I9: =H9/60 -> 0 | W9: 职业贡献 | X9: 门贡
A10: 多人(至少3人) | B10: 精英副本 | D10: 卡拉赞精英 | E10: 每周1次 | F10: 40 | G10: 150 | H10: 0 | I10: =H10/60 -> 0 | W10: 声望值 | X10: 侠义
B11: 前尘旧梦 | D11: 精英副本 | E11: 每日2次 | F11: 30 | G11: 150 | H11: 30 | I11: =H11/60 -> 0.5 | J11: 20 | K11: 2 | L11: 1 | M11: 10 | W11: 荣誉值 | X11: 武勋
A12: 单人 | B12: 帮派任务 | D12: 公会任务(周7轮) | E12: 每周7轮 | F12: 35 | G12: 150 | H12: 10 | I12: =H12/60 -> 0.16666667 | J12: 20 | L12: 1 | M12: 5 | W12: 节日积分
B13: 任务链 | D13: 暗夜马戏团(周20轮) | E13: 每周200次 | F13: 50 | G13: 150 | H13: 30 | I13: =H13/60 -> 0.5 | J13: 40
A14: 单人 | B14: 野外挂机/离线经验 | D14: 野外挂机/离线经验 | E14: 每日8小时 | F14: 10 | G14: 150 | H14: 720 | I14: =H14/60 -> 12 | J14: 1 | K14: 1 | W14: 每日活跃度
B15: 经验道具 | D15: 经验道具 | E15: 每日10个 | F15: 20 | G15: 150 | H15: 5 | I15: =H15/60 -> 0.083333333 | J15: 150 | W15: 活力
A16: 单人 | B16: 分享 | D16: 分享 | E16: 每日1次 | F16: 10 | G16: 150 | H16: 5 | I16: =H16/60 -> 0.083333333 | J16: 10 | L16: 0.5
B17: 双倍点数 | D17: 双倍点数 | E17: 每周1800点 | F17: 0 | G17: 150 | H17: 156 | I17: =H17/60 -> 2.6 | J17: 20 | K17: 2 | L17: 5 | M17: 10 | W17: 竞技场积分
B18: 援助战斗和道具 | D18: 援助战斗和道具 | E18: 每日获得奖励有上限 | F18: 30 | G18: 150 | H18: 60 | I18: =H18/60 -> 1 | J18: 6
A19: 单人或多人 | B19: 封妖 | C19: 限时活动 | D19: 古神爪牙 | E19: 每日10次 | F19: 25 | G19: 150 | H19: 20 | I19: =H19/60 -> 0.33333333 | J19: 20 | K19: 1.5 | L19: 1 | M19: 3
A20: 多人 | B20: 星宿护卫 | D20: 幼龙 | E20: 50级以下10次 | F20: 35 | G20: 49 | H20: 30 | I20: =H20/60 -> 0.5 | J20: 15 | K20: 1.5 | L20: 1
A21: 多人 | B21: 杀星 | D21: 屠龙 | E21: 50级以上5次 | F21: 50 | G21: 150 | H21: 20 | I21: =H21/60 -> 0.33333333 | J21: 15 | K21: 1.5 | L21: 1
A22: 多人 | B22: 妖王 | D22: 古神 | E22: 每日3次 | F22: 25 | G22: 150 | H22: 10 | I22: =H22/60 -> 0.16666667 | J22: 40 | K22: 2 | L22: 1.5 | M22: 4 | W22: (2+等级*0.075)*活跃度 | X22: 4000
A23: 单人 | B23: 三界奇缘 | D23: 艾泽拉斯地理探索 | E23: 每日1次 | F23: 30 | G23: 150 | H23: 10 | I23: =H23/60 -> 0.16666667 | J23: 15 | L23: 1
A24: 单人 | B24: 科举 | D24: 艾泽拉斯百科竞赛 | E24: 每日1次 决赛双倍，星期日没有 | F24: 30 | G24: 150 | H24: 10 | I24: =H24/60 -> 0.16666667 | J24: 30 | L24: 1 | W24: 20+等级*0.075*0.5
A25: 多人(最好每个职业一个) | B25: 门派闯关 | D25: 职业闯关(周2次) | E25: 每周2次 | F25: 40 | G25: 150 | H25: 15 | I25: =H25/60 -> 0.25 | J25: 25 | K25: 1 | L25: 1
A26: 单人 | B26: 竞技场 | D26: 竞技场（周5次） | E26: 每周2356，周日5v5 | F26: 40 | G26: 150 | H26: 35 | I26: =H26/60 -> 0.58333333 | J26: 15 | L26: 3 | M26: 10
A27: 多人 | B27: 帮派秘境 | D27: 公会副本(周1次) | E27: 每周1次 | F27: 40 | G27: 150 | H27: 10 | I27: =H27/60 -> 0.16666667 | J27: 15 | K27: 0.5 | L27: 0.5 | W27: 等级*0.075*0.5
A28: 多人 | B28: 帮派强盗 | D28: 帮派强盗 | E28: 每周2次 | F28: 40 | G28: 150 | H28: 0 | I28: =H28/60 -> 0
A29: 多人 | B29: 帮派采药 | D29: 帮派采药 | E29: 每周2次 | F29: 40 | G29: 150 | H29: 0 | I29: =H29/60 -> 0
A30: 看运营活动决定 | B30: 节日活动 | C30: 节日活动 | D30: 节日活动1 | F30: 20 | G30: 150 | H30: 0 | I30: =H30/60 -> 0
B31: 节日活动 | D31: 节日活动2 | F31: 40 | G31: 150 | H31: 0 | I31: =H31/60 -> 0
B32: 活跃度打卡 | D32: 活跃度打卡 | F32: 25 | G32: 150 | H32: 5 | I32: =H32/60 -> 0.083333333 | M32: 20
A33: 单人(打不过可找别人帮忙) | B33: 剧情任务 | C33: 一次性活动 | D33: 剧情任务
H34: 每日玩法时长 | I34: =SUM(I3:I33)-I5-I14-I15-I16-I21-I22-I32 -> 10.6
F39: 开启时间 | G39: 星期一 | H39: 星期二 | I39: 星期三 | J39: 星期四 | K39: 星期五 | L39: 星期六 | M39: 星期日
F40: 0.45833333 | G40: 人文探索 | H40: 人文探索 | I40: 人文探索 | J40: 人文探索 | K40: 人文探索 | L40: 人文探索 | M40: 人文探索
F41: 0.70833333 | G41: 智慧试炼初赛 | H41: 智慧试炼初赛 | I41: 智慧试炼初赛 | J41: 智慧试炼初赛 | K41: 智慧试炼初赛 | L41: 智慧试炼复赛 | M41: 公会副本
F42: 0.83333333 | G42: 冠军试炼 | H42: 1v1竞技场 | I42: 3v3竞技场 | J42: 冠军试炼 | K42: 1v1竞技场 | L42: 3v3竞技场 | M42: 奥山战场
G45: 等级下限 | H45: 等级上限 | I45: 经验 | J45: 宠物经验 | L45: 金币 | M45: 银币
F46: 职业日常 | G46: 15 | H46: 150 | I46: 40 | J46: 1.5 | L46: 10 | M46: 6
F47: 日常副本 | G47: 20 | H47: 150 | I47: 4 | J47: 0.5 | M47: 1.5
...

Sheet 玩法行为规划
B1: 日常活动 | R1: 定时活动 | AC1: 节日活动
A2: 角色等级 | B2: 职业日常 | C2: 日常副本 | D2: 英雄试炼 | E2: 冰封王座 | F2: 考古 | G2: 运镖 | H2: 卡拉赞系列 | I2: 卡拉赞精英 | J2: 精英副本 | K2: 公会任务(周7轮) | L2: 暗夜马戏团(周20轮) | M2: 野外挂机/离线经验 | N2: 经验道具 | O2: 分享 | P2: 双倍点数 | Q2: 援助战斗和道具 | R2: 古神爪牙 | S2: 幼龙 | T2: 屠龙 | U2: 古神 | V2: 艾泽拉斯地理探索 | W2: 艾泽拉斯百科竞赛 | X2: 职业闯关(周2次) | Y2: 竞技场（周5次） | Z2: 公会副本(周1次) | AA2: 帮派强盗 | AB2: 帮派采药 | AC2: 节日活动1 | AD2: 节日活动2 | AE2: 活跃度打卡 | AF2: 剧情任务
A3: 1 | B3: =ROUND(IF(OR($A3<VLOOKUP(B$2,行为概览!$D$3:$U$33,3,0),$A3>VLOOKUP(B$2,行为概览!$D$3:$U$33,4,0)),0,VLOOKUP(B$2,行为概览!$D$3:$U$33,6,0)),4) -> 0 | C3: =ROUND(IF(OR($A3<VLOOKUP(C$2,行为概览!$D$3:$U$33,3,0),$A3>VLOOKUP(C$2,行为概览!$D$3:$U$33,4,0)),0,VLOOKUP(C$2,行为概览!$D$3:$U$33,6,0)),4) -> 0 | D3: =ROUND(IF(OR($A3<VLOOKUP(D$2,行为概览!$D$3:$U$33,3,0),$A3>VLOOKUP(D$2,行为概览!$D$3:$U$33,4,0)),0,VLOOKUP(D$2,行为概览!$D$3:$U$33,6,0)),4) -> 0 | E3: =ROUND(IF(OR($A3<VLOOKUP(E$2,行为概览!$D$3:$U$33,3,0),$A3>VLOOKUP(E$2,行为概览!$D$3:$U$33,4,0)),0,VLOOKUP(E$2,行为概览!$D$3:$U$33,6,0)),4) -> 0 | F3: =ROUND(IF(OR($A3<VLOOKUP(F$2,行为概览!$D$3:$U$33,3,0),$A3>VLOOKUP(F$2,行为概览!$D$3:$U$33,4,0)),0,VLOOKUP(F$2,行为概览!$D$3:$U$33,6,0)),4) -> 0 | G3: =ROUND(IF(OR($A3<VLOOKUP(G$2,行为概览!$D$3:$U$33,3,0),$A3>VLOOKUP(G$2,行为概览!$D$3:$U$33,4,0)),0,VLOOKUP(G$2,行为概览!$D$3:$U$33,6,0)),4) -> 0 | H3: =ROUND(IF(OR($A3<VLOOKUP(H$2,行为概览!$D$3:$U$33,3,0),$A3>VLOOKUP(H$2,行为概览!$D$3:$U$33,4,0)),0,VLOOKUP(H$2,行为概览!$D$3:$U$33,6,0)),4) -> 0 | I3: =ROUND(IF(OR($A3<VLOOKUP(I$2,行为概览!$D$3:$U$33,3,0),$A3>VLOOKUP(I$2,行为概览!$D$3:$U$33,4,0)),0,VLOOKUP(I$2,行为概览!$D$3:$U$33,6,0)),4) -> 0 | ... AF3: =ROUND(IF(OR($A3<VLOOKUP(AF$2,行为概览!$D$3:$U$33,3,0),$A3>VLOOKUP(AF$2,行为概览!$D$3:$U$33,4,0)),0,VLOOKUP(AF$2,行为概览!$D$3:$U$33,6,0)),4) -> 0
A4: 2 | B4: =ROUND(IF(OR($A4<VLOOKUP(B$2,行为概览!$D$3:$U$33,3,0),$A4>VLOOKUP(B$2,行为概览!$D$3:$U$33,4,0)),0,VLOOKUP(B$2,行为概览!$D$3:$U$33,6,0)),4) -> 0 | C4: =ROUND(IF(OR($A4<VLOOKUP(C$2,行为概览!$D$3:$U$33,3,0),$A4>VLOOKUP(C$2,行为概览!$D$3:$U$33,4,0)),0,VLOOKUP(C$2,行为概览!$D$3:$U$33,6,0)),4) -> 0 | D4: =ROUND(IF(OR($A4<VLOOKUP(D$2,行为概览!$D$3:$U$33,3,0),$A4>VLOOKUP(D$2,行为概览!$D$3:$U$33,4,0)),0,VLOOKUP(D$2,行为概览!$D$3:$U$33,6,0)),4) -> 0 | E4: =ROUND(IF(OR($A4<VLOOKUP(E$2,行为概览!$D$3:$U$33,3,0),$A4>VLOOKUP(E$2,行为概览!$D$3:$U$33,4,0)),0,VLOOKUP(E$2,行为概览!$D$3:$U$33,6,0)),4) -> 0 | F4: =ROUND(IF(OR($A4<VLOOKUP(F$2,行为概览!$D$3:$U$33,3,0),$A4>VLOOKUP(F$2,行为概览!$D$3:$U$33,4,0)),0,VLOOKUP(F$2,行为概览!$D$3:$U$33,6,0)),4) -> 0 | G4: =ROUND(IF(OR($A4<VLOOKUP(G$2,行为概览!$D$3:$U$33,3,0),$A4>VLOOKUP(G$2,行为概览!$D$3:$U$33,4,0)),0,VLOOKUP(G$2,行为概览!$D$3:$U$33,6,0)),4) -> 0 | H4: =ROUND(IF(OR($A4<VLOOKUP(H$2,行为概览!$D$3:$U$33,3,0),$A4>VLOOKUP(H$2,行为概览!$D$3:$U$33,4,0)),0,VLOOKUP(H$2,行为概览!$D$3:$U$33,6,0)),4) -> 0 | I4: =ROUND(IF(OR($A4<VLOOKUP(I$2,行为概览!$D$3:$U$33,3,0),$A4>VLOOKUP(I$2,行为概览!$D$3:$U$33,4,0)),0,VLOOKUP(I$2,行为概览!$D$3:$U$33,6,0)),4) -> 0 | ... AF4: =ROUND(IF(OR($A4<VLOOKUP(AF$2,行为概览!$D$3:$U$33,3,0),$A4>VLOOKUP(AF$2,行为概览!$D$3:$U$33,4,0)),0,VLOOKUP(AF$2,行为概览!$D$3:$U$33,6,0)),4) -> 0
A5: 3 | B5: =ROUND(IF(OR($A5<VLOOKUP(B$2,行为概览!$D$3:$U$33,3,0),$A5>VLOOKUP(B$2,行为概览!$D$3:$U$33,4,0)),0,VLOOKUP(B$2,行为概览!$D$3:$U$33,6,0)),4) -> 0 | C5: =ROUND(IF(OR($A5<VLOOKUP(C$2,行为概览!$D$3:$U$33,3,0),$A5>VLOOKUP(C$2,行为概览!$D$3:$U$33,4,0)),0,VLOOKUP(C$2,行为概览!$D$3:$U$33,6,0)),4) -> 0 | D5: =ROUND(IF(OR($A5<VLOOKUP(D$2,行为概览!$D$3:$U$33,3,0),$A5>VLOOKUP(D$2,行为概览!$D$3:$U$33,4,0)),0,VLOOKUP(D$2,行为概览!$D$3:$U$33,6,0)),4) -> 0 | E5: =ROUND(IF(OR($A5<VLOOKUP(E$2,行为概览!$D$3:$U$33,3,0),$A5>VLOOKUP(E$2,行为概览!$D$3:$U$33,4,0)),0,VLOOKUP(E$2,行为概览!$D$3:$U$33,6,0)),4) -> 0 | F5: =ROUND(IF(OR($A5<VLOOKUP(F$2,行为概览!$D$3:$U$33,3,0),$A5>VLOOKUP(F$2,行为概览!$D$3:$U$33,4,0)),0,VLOOKUP(F$2,行为概览!$D$3:$U$33,6,0)),4) -> 0 | G5: =ROUND(IF(OR($A5<VLOOKUP(G$2,行为概览!$D$3:$U$33,3,0),$A5>VLOOKUP(G$2,行为概览!$D$3:$U$33,4,0)),0,VLOOKUP(G$2,行为概览!$D$3:$U$33,6,0)),4) -> 0 | H5: =ROUND(IF(OR($A5<VLOOKUP(H$2,行为概览!$D$3:$U$33,3,0),$A5>VLOOKUP(H$2,行为概览!$D$3:$U$33,4,0)),0,VLOOKUP(H$2,行为概览!$D$3:$U$33,6,0)),4) -> 0 | I5: =ROUND(IF(OR($A5<VLOOKUP(I$2,行为概览!$D$3:$U$33,3,0),$A5>VLOOKUP(I$2,行为概览!$D$3:$U$33,4,0)),0,VLOOKUP(I$2,行为概览!$D$3:$U$33,6,0)),4) -> 0 | ... AF5: =ROUND(IF(OR($A5<VLOOKUP(AF$2,行为概览!$D$3:$U$33,3,0),$A5>VLOOKUP(AF$2,行为概览!$D$3:$U$33,4,0)),0,VLOOKUP(AF$2,行为概览!$D$3:$U$33,6,0)),4) -> 0
A6: 4 | B6: =ROUND(IF(OR($A6<VLOOKUP(B$2,行为概览!$D$3:$U$33,3,0),$A6>VLOOKUP(B$2,行为概览!$D$3:$U$33,4,0)),0,VLOOKUP(B$2,行为概览!$D$3:$U$33,6,0)),4) -> 0 | C6: =ROUND(IF(OR($A6<VLOOKUP(C$2,行为概览!$D$3:$U$33,3,0),$A6>VLOOKUP(C$2,行为概览!$D$3:$U$33,4,0)),0,VLOOKUP(C$2,行为概览!$D$3:$U$33,6,0)),4) -> 0 | D6: =ROUND(IF(OR($A6<VLOOKUP(D$2,行为概览!$D$3:$U$33,3,0),$A6>VLOOKUP(D$2,行为概览!$D$3:$U$33,4,0)),0,VLOOKUP(D$2,行为概览!$D$3:$U$33,6,0)),4) -> 0 | E6: =ROUND(IF(OR($A6<VLOOKUP(E$2,行为概览!$D$3:$U$33,3,0),$A6>VLOOKUP(E$2,行为概览!$D$3:$U$33,4,0)),0,VLOOKUP(E$2,行为概览!$D$3:$U$33,6,0)),4) -> 0 | F6: =ROUND(IF(OR($A6<VLOOKUP(F$2,行为概览!$D$3:$U$33,3,0),$A6>VLOOKUP(F$2,行为概览!$D$3:$U$33,4,0)),0,VLOOKUP(F$2,行为概览!$D$3:$U$33,6,0)),4) -> 0 | G6: =ROUND(IF(OR($A6<VLOOKUP(G$2,行为概览!$D$3:$U$33,3,0),$A6>VLOOKUP(G$2,行为概览!$D$3:$U$33,4,0)),0,VLOOKUP(G$2,行为概览!$D$3:$U$33,6,0)),4) -> 0 | H6: =ROUND(IF(OR($A6<VLOOKUP(H$2,行为概览!$D$3:$U$33,3,0),$A6>VLOOKUP(H$2,行为概览!$D$3:$U$33,4,0)),0,VLOOKUP(H$2,行为概览!$D$3:$U$33,6,0)),4) -> 0 | I6: =ROUND(IF(OR($A6<VLOOKUP(I$2,行为概览!$D$3:$U$33,3,0),$A6>VLOOKUP(I$2,行为概览!$D$3:$U$33,4,0)),0,VLOOKUP(I$2,行为概览!$D$3:$U$33,6,0)),4) -> 0 | ... AF6: =ROUND(IF(OR($A6<VLOOKUP(AF$2,行为概览!$D$3:$U$33,3,0),$A6>VLOOKUP(AF$2,行为概览!$D$3:$U$33,4,0)),0,VLOOKUP(AF$2,行为概览!$D$3:$U$33,6,0)),4) -> 0
A7: 5 | B7: =ROUND(IF(OR($A7<VLOOKUP(B$2,行为概览!$D$3:$U$33,3,0),$A7>VLOOKUP(B$2,行为概览!$D$3:$U$33,4,0)),0,VLOOKUP(B$2,行为概览!$D$3:$U$33,6,0)),4) -> 0 | C7: =ROUND(IF(OR($A7<VLOOKUP(C$2,行为概览!$D$3:$U$33,3,0),$A7>VLOOKUP(C$2,行为概览!$D$3:$U$33,4,0)),0,VLOOKUP(C$2,行为概览!$D$3:$U$33,6,0)),4) -> 0 | D7: =ROUND(IF(OR($A7<VLOOKUP(D$2,行为概览!$D$3:$U$33,3,0),$A7>VLOOKUP(D$2,行为概览!$D$3:$U$33,4,0)),0,VLOOKUP(D$2,行为概览!$D$3:$U$33,6,0)),4) -> 0 | E7: =ROUND(IF(OR($A7<VLOOKUP(E$2,行为概览!$D$3:$U$33,3,0),$A7>VLOOKUP(E$2,行为概览!$D$3:$U$33,4,0)),0,VLOOKUP(E$2,行为概览!$D$3:$U$33,6,0)),4) -> 0 | F7: =ROUND(IF(OR($A7<VLOOKUP(F$2,行为概览!$D$3:$U$33,3,0),$A7>VLOOKUP(F$2,行为概览!$D$3:$U$33,4,0)),0,VLOOKUP(F$2,行为概览!$D$3:$U$33,6,0)),4) -> 0 | G7: =ROUND(IF(OR($A7<VLOOKUP(G$2,行为概览!$D$3:$U$33,3,0),$A7>VLOOKUP(G$2,行为概览!$D$3:$U$33,4,0)),0,VLOOKUP(G$2,行为概览!$D$3:$U$33,6,0)),4) -> 0 | H7: =ROUND(IF(OR($A7<VLOOKUP(H$2,行为概览!$D$3:$U$33,3,0),$A7>VLOOKUP(H$2,行为概览!$D$3:$U$33,4,0)),0,VLOOKUP(H$2,行为概览!$D$3:$U$33,6,0)),4) -> 0 | I7: =ROUND(IF(OR($A7<VLOOKUP(I$2,行为概览!$D$3:$U$33,3,0),$A7>VLOOKUP(I$2,行为概览!$D$3:$U$33,4,0)),0,VLOOKUP(I$2,行为概览!$D$3:$U$33,6,0)),4) -> 0 | ... AF7: =ROUND(IF(OR($A7<VLOOKUP(AF$2,行为概览!$D$3:$U$33,3,0),$A7>VLOOKUP(AF$2,行为概览!$D$3:$U$33,4,0)),0,VLOOKUP(AF$2,行为概览!$D$3:$U$33,6,0)),4) -> 0
A8: 6 | B8: =ROUND(IF(OR($A8<VLOOKUP(B$2,行为概览!$D$3:$U$33,3,0),$A8>VLOOKUP(B$2,行为概览!$D$3:$U$33,4,0)),0,VLOOKUP(B$2,行为概览!$D$3:$U$33,6,0)),4) -> 0 | C8: =ROUND(IF(OR($A8<VLOOKUP(C$2,行为概览!$D$3:$U$33,3,0),$A8>VLOOKUP(C$2,行为概览!$D$3:$U$33,4,0)),0,VLOOKUP(C$2,行为概览!$D$3:$U$33,6,0)),4) -> 0 | D8: =ROUND(IF(OR($A8<VLOOKUP(D$2,行为概览!$D$3:$U$33,3,0),$A8>VLOOKUP(D$2,行为概览!$D$3:$U$33,4,0)),0,VLOOKUP(D$2,行为概览!$D$3:$U$33,6,0)),4) -> 0 | E8: =ROUND(IF(OR($A8<VLOOKUP(E$2,行为概览!$D$3:$U$33,3,0),$A8>VLOOKUP(E$2,行为概览!$D$3:$U$33,4,0)),0,VLOOKUP(E$2,行为概览!$D$3:$U$33,6,0)),4) -> 0 | F8: =ROUND(IF(OR($A8<VLOOKUP(F$2,行为概览!$D$3:$U$33,3,0),$A8>VLOOKUP(F$2,行为概览!$D$3:$U$33,4,0)),0,VLOOKUP(F$2,行为概览!$D$3:$U$33,6,0)),4) -> 0 | G8: =ROUND(IF(OR($A8<VLOOKUP(G$2,行为概览!$D$3:$U$33,3,0),$A8>VLOOKUP(G$2,行为概览!$D$3:$U$33,4,0)),0,VLOOKUP(G$2,行为概览!$D$3:$U$33,6,0)),4) -> 0 | H8: =ROUND(IF(OR($A8<VLOOKUP(H$2,行为概览!$D$3:$U$33,3,0),$A8>VLOOKUP(H$2,行为概览!$D$3:$U$33,4,0)),0,VLOOKUP(H$2,行为概览!$D$3:$U$33,6,0)),4) -> 0 | I8: =ROUND(IF(OR($A8<VLOOKUP(I$2,行为概览!$D$3:$U$33,3,0),$A8>VLOOKUP(I$2,行为概览!$D$3:$U$33,4,0)),0,VLOOKUP(I$2,行为概览!$D$3:$U$33,6,0)),4) -> 0 | ... AF8: =ROUND(IF(OR($A8<VLOOKUP(AF$2,行为概览!$D$3:$U$33,3,0),$A8>VLOOKUP(AF$2,行为概览!$D$3:$U$33,4,0)),0,VLOOKUP(AF$2,行为概览!$D$3:$U$33,6,0)),4) -> 0
A9: 7 | B9: =ROUND(IF(OR($A9<VLOOKUP(B$2,行为概览!$D$3:$U$33,3,0),$A9>VLOOKUP(B$2,行为概览!$D$3:$U$33,4,0)),0,VLOOKUP(B$2,行为概览!$D$3:$U$33,6,0)),4) -> 0 | C9: =ROUND(IF(OR($A9<VLOOKUP(C$2,行为概览!$D$3:$U$33,3,0),$A9>VLOOKUP(C$2,行为概览!$D$3:$U$33,4,0)),0,VLOOKUP(C$2,行为概览!$D$3:$U$33,6,0)),4) -> 0 | D9: =ROUND(IF(OR($A9<VLOOKUP(D$2,行为概览!$D$3:$U$33,3,0),$A9>VLOOKUP(D$2,行为概览!$D$3:$U$33,4,0)),0,VLOOKUP(D$2,行为概览!$D$3:$U$33,6,0)),4) -> 0 | E9: =ROUND(IF(OR($A9<VLOOKUP(E$2,行为概览!$D$3:$U$33,3,0),$A9>VLOOKUP(E$2,行为概览!$D$3:$U$33,4,0)),0,VLOOKUP(E$2,行为概览!$D$3:$U$33,6,0)),4) -> 0 | F9: =ROUND(IF(OR($A9<VLOOKUP(F$2,行为概览!$D$3:$U$33,3,0),$A9>VLOOKUP(F$2,行为概览!$D$3:$U$33,4,0)),0,VLOOKUP(F$2,行为概览!$D$3:$U$33,6,0)),4) -> 0 | G9: =ROUND(IF(OR($A9<VLOOKUP(G$2,行为概览!$D$3:$U$33,3,0),$A9>VLOOKUP(G$2,行为概览!$D$3:$U$33,4,0)),0,VLOOKUP(G$2,行为概览!$D$3:$U$33,6,0)),4) -> 0 | H9: =ROUND(IF(OR($A9<VLOOKUP(H$2,行为概览!$D$3:$U$33,3,0),$A9>VLOOKUP(H$2,行为概览!$D$3:$U$33,4,0)),0,VLOOKUP(H$2,行为概览!$D$3:$U$33,6,0)),4) -> 0 | I9: =ROUND(IF(OR($A9<VLOOKUP(I$2,行为概览!$D$3:$U$33,3,0),$A9>VLOOKUP(I$2,行为概览!$D$3:$U$33,4,0)),0,VLOOKUP(I$2,行为概览!$D$3:$U$33,6,0)),4) -> 0 | ... AF9: =ROUND(IF(OR($A9<VLOOKUP(AF$2,行为概览!$D$3:$U$33,3,0),$A9>VLOOKUP(AF$2,行为概览!$D$3:$U$33,4,0)),0,VLOOKUP(AF$2,行为概览!$D$3:$U$33,6,0)),4) -> 0
A10: 8 | B10: =ROUND(IF(OR($A10<VLOOKUP(B$2,行为概览!$D$3:$U$33,3,0),$A10>VLOOKUP(B$2,行为概览!$D$3:$U$33,4,0)),0,VLOOKUP(B$2,行为概览!$D$3:$U$33,6,0)),4) -> 0 | C10: =ROUND(IF(OR($A10<VLOOKUP(C$2,行为概览!$D$3:$U$33,3,0),$A10>VLOOKUP(C$2,行为概览!$D$3:$U$33,4,0)),0,VLOOKUP(C$2,行为概览!$D$3:$U$33,6,0)),4) -> 0 | D10: =ROUND(IF(OR($A10<VLOOKUP(D$2,行为概览!$D$3:$U$33,3,0),$A10>VLOOKUP(D$2,行为概览!$D$3:$U$33,4,0)),0,VLOOKUP(D$2,行为概览!$D$3:$U$33,6,0)),4) -> 0 | E10: =ROUND(IF(OR($A10<VLOOKUP(E$2,行为概览!$D$3:$U$33,3,0),$A10>VLOOKUP(E$2,行为概览!$D$3:$U$33,4,0)),0,VLOOKUP(E$2,行为概览!$D$3:$U$33,6,0)),4) -> 0 | F10: =ROUND(IF(OR($A10<VLOOKUP(F$2,行为概览!$D$3:$U$33,3,0),$A10>VLOOKUP(F$2,行为概览!$D$3:$U$33,4,0)),0,VLOOKUP(F$2,行为概览!$D$3:$U$33,6,0)),4) -> 0 | G10: =ROUND(IF(OR($A10<VLOOKUP(G$2,行为概览!$D$3:$U$33,3,0),$A10>VLOOKUP(G$2,行为概览!$D$3:$U$33,4,0)),0,VLOOKUP(G$2,行为概览!$D$3:$U$33,6,0)),4) -> 0 | H10: =ROUND(IF(OR($A10<VLOOKUP(H$2,行为概览!$D$3:$U$33,3,0),$A10>VLOOKUP(H$2,行为概览!$D$3:$U$33,4,0)),0,VLOOKUP(H$2,行为概览!$D$3:$U$33,6,0)),4) -> 0 | I10: =ROUND(IF(OR($A10<VLOOKUP(I$2,行为概览!$D$3:$U$33,3,0),$A10>VLOOKUP(I$2,行为概览!$D$3:$U$33,4,0)),0,VLOOKUP(I$2,行为概览!$D$3:$U$33,6,0)),4) -> 0 | ... AF10: =ROUND(IF(OR($A10<VLOOKUP(AF$2,行为概览!$D$3:$U$33,3,0),$A10>VLOOKUP(AF$2,行为概览!$D$3:$U$33,4,0)),0,VLOOKUP(AF$2,行为概览!$D$3:$U$33,6,0)),4) -> 0
A11: 9 | B11: =ROUND(IF(OR($A11<VLOOKUP(B$2,行为概览!$D$3:$U$33,3,0),$A11>VLOOKUP(B$2,行为概览!$D$3:$U$33,4,0)),0,VLOOKUP(B$2,行为概览!$D$3:$U$33,6,0)),4) -> 0 | C11: =ROUND(IF(OR($A11<VLOOKUP(C$2,行为概览!$D$3:$U$33,3,0),$A11>VLOOKUP(C$2,行为概览!$D$3:$U$33,4,0)),0,VLOOKUP(C$2,行为概览!$D$3:$U$33,6,0)),4) -> 0 | D11: =ROUND(IF(OR($A11<VLOOKUP(D$2,行为概览!$D$3:$U$33,3,0),$A11>VLOOKUP(D$2,行为概览!$D$3:$U$33,4,0)),0,VLOOKUP(D$2,行为概览!$D$3:$U$33,6,0)),4) -> 0 | E11: =ROUND(IF(OR($A11<VLOOKUP(E$2,行为概览!$D$3:$U$33,3,0),$A11>VLOOKUP(E$2,行为概览!$D$3:$U$33,4,0)),0,VLOOKUP(E$2,行为概览!$D$3:$U$33,6,0)),4) -> 0 | F11: =ROUND(IF(OR($A11<VLOOKUP(F$2,行为概览!$D$3:$U$33,3,0),$A11>VLOOKUP(F$2,行为概览!$D$3:$U$33,4,0)),0,VLOOKUP(F$2,行为概览!$D$3:$U$33,6,0)),4) -> 0 | G11: =ROUND(IF(OR($A11<VLOOKUP(G$2,行为概览!$D$3:$U$33,3,0),$A11>VLOOKUP(G$2,行为概览!$D$3:$U$33,4,0)),0,VLOOKUP(G$2,行为概览!$D$3:$U$33,6,0)),4) -> 0 | H11: =ROUND(IF(OR($A11<VLOOKUP(H$2,行为概览!$D$3:$U$33,3,0),$A11>VLOOKUP(H$2,行为概览!$D$3:$U$33,4,0)),0,VLOOKUP(H$2,行为概览!$D$3:$U$33,6,0)),4) -> 0 | I11: =ROUND(IF(OR($A11<VLOOKUP(I$2,行为概览!$D$3:$U$33,3,0),$A11>VLOOKUP(I$2,行为概览!$D$3:$U$33,4,0)),0,VLOOKUP(I$2,行为概览!$D$3:$U$33,6,0)),4) -> 0 | ... AF11: =ROUND(IF(OR($A11<VLOOKUP(AF$2,行为概览!$D$3:$U$33,3,0),$A11>VLOOKUP(AF$2,行为概览!$D$3:$U$33,4,0)),0,VLOOKUP(AF$2,行为概览!$D$3:$U$33,6,0)),4) -> 0
A12: 10 | B12: =ROUND(IF(OR($A12<VLOOKUP(B$2,行为概览!$D$3:$U$33,3,0),$A12>VLOOKUP(B$2,行为概览!$D$3:$U$33,4,0)),0,VLOOKUP(B$2,行为概览!$D$3:$U$33,6,0)),4) -> 0 | C12: =ROUND(IF(OR($A12<VLOOKUP(C$2,行为概览!$D$3:$U$33,3,0),$A12>VLOOKUP(C$2,行为概览!$D$3:$U$33,4,0)),0,VLOOKUP(C$2,行为概览!$D$3:$U$33,6,0)),4) -> 0 | D12: =ROUND(IF(OR($A12<VLOOKUP(D$2,行为概览!$D$3:$U$33,3,0),$A12>VLOOKUP(D$2,行为概览!$D$3:$U$33,4,0)),0,VLOOKUP(D$2,行为概览!$D$3:$U$33,6,0)),4) -> 0 | E12: =ROUND(IF(OR($A12<VLOOKUP(E$2,行为概览!$D$3:$U$33,3,0),$A12>VLOOKUP(E$2,行为概览!$D$3:$U$33,4,0)),0,VLOOKUP(E$2,行为概览!$D$3:$U$33,6,0)),4) -> 0 | F12: =ROUND(IF(OR($A12<VLOOKUP(F$2,行为概览!$D$3:$U$33,3,0),$A12>VLOOKUP(F$2,行为概览!$D$3:$U$33,4,0)),0,VLOOKUP(F$2,行为概览!$D$3:$U$33,6,0)),4) -> 0 | G12: =ROUND(IF(OR($A12<VLOOKUP(G$2,行为概览!$D$3:$U$33,3,0),$A12>VLOOKUP(G$2,行为概览!$D$3:$U$33,4,0)),0,VLOOKUP(G$2,行为概览!$D$3:$U$33,6,0)),4) -> 0 | H12: =ROUND(IF(OR($A12<VLOOKUP(H$2,行为概览!$D$3:$U$33,3,0),$A12>VLOOKUP(H$2,行为概览!$D$3:$U$33,4,0)),0,VLOOKUP(H$2,行为概览!$D$3:$U$33,6,0)),4) -> 0 | I12: =ROUND(IF(OR($A12<VLOOKUP(I$2,行为概览!$D$3:$U$33,3,0),$A12>VLOOKUP(I$2,行为概览!$D$3:$U$33,4,0)),0,VLOOKUP(I$2,行为概览!$D$3:$U$33,6,0)),4) -> 0 | ... AF12: =ROUND(IF(OR($A12<VLOOKUP(AF$2,行为概览!$D$3:$U$33,3,0),$A12>VLOOKUP(AF$2,行为概览!$D$3:$U$33,4,0)),0,VLOOKUP(AF$2,行为概览!$D$3:$U$33,6,0)),4) -> 0
A13: 11 | B13: =ROUND(IF(OR($A13<VLOOKUP(B$2,行为概览!$D$3:$U$33,3,0),$A13>VLOOKUP(B$2,行为概览!$D$3:$U$33,4,0)),0,VLOOKUP(B$2,行为概览!$D$3:$U$33,6,0)),4) -> 0 | C13: =ROUND(IF(OR($A13<VLOOKUP(C$2,行为概览!$D$3:$U$33,3,0),$A13>VLOOKUP(C$2,行为概览!$D$3:$U$33,4,0)),0,VLOOKUP(C$2,行为概览!$D$3:$U$33,6,0)),4) -> 0 | D13: =ROUND(IF(OR($A13<VLOOKUP(D$2,行为概览!$D$3:$U$33,3,0),$A13>VLOOKUP(D$2,行为概览!$D$3:$U$33,4,0)),0,VLOOKUP(D$2,行为概览!$D$3:$U$33,6,0)),4) -> 0 | E13: =ROUND(IF(OR($A13<VLOOKUP(E$2,行为概览!$D$3:$U$33,3,0),$A13>VLOOKUP(E$2,行为概览!$D$3:$U$33,4,0)),0,VLOOKUP(E$2,行为概览!$D$3:$U$33,6,0)),4) -> 0 | F13: =ROUND(IF(OR($A13<VLOOKUP(F$2,行为概览!$D$3:$U$33,3,0),$A13>VLOOKUP(F$2,行为概览!$D$3:$U$33,4,0)),0,VLOOKUP(F$2,行为概览!$D$3:$U$33,6,0)),4) -> 0 | G13: =ROUND(IF(OR($A13<VLOOKUP(G$2,行为概览!$D$3:$U$33,3,0),$A13>VLOOKUP(G$2,行为概览!$D$3:$U$33,4,0)),0,VLOOKUP(G$2,行为概览!$D$3:$U$33,6,0)),4) -> 0 | H13: =ROUND(IF(OR($A13<VLOOKUP(H$2,行为概览!$D$3:$U$33,3,0),$A13>VLOOKUP(H$2,行为概览!$D$3:$U$33,4,0)),0,VLOOKUP(H$2,行为概览!$D$3:$U$33,6,0)),4) -> 0 | I13: =ROUND(IF(OR($A13<VLOOKUP(I$2,行为概览!$D$3:$U$33,3,0),$A13>VLOOKUP(I$2,行为概览!$D$3:$U$33,4,0)),0,VLOOKUP(I$2,行为概览!$D$3:$U$33,6,0)),4) -> 0 | ... AF13: =ROUND(IF(OR($A13<VLOOKUP(AF$2,行为概览!$D$3:$U$33,3,0),$A13>VLOOKUP(AF$2,行为概览!$D$3:$U$33,4,0)),0,VLOOKUP(AF$2,行为概览!$D$3:$U$33,6,0)),4) -> 0
A14: 12 | B14: =ROUND(IF(OR($A14<VLOOKUP(B$2,行为概览!$D$3:$U$33,3,0),$A14>VLOOKUP(B$2,行为概览!$D$3:$U$33,4,0)),0,VLOOKUP(B$2,行为概览!$D$3:$U$33,6,0)),4) -> 0 | C14: =ROUND(IF(OR($A14<VLOOKUP(C$2,行为概览!$D$3:$U$33,3,0),$A14>VLOOKUP(C$2,行为概览!$D$3:$U$33,4,0)),0,VLOOKUP(C$2,行为概览!$D$3:$U$33,6,0)),4) -> 0 | D14: =ROUND(IF(OR($A14<VLOOKUP(D$2,行为概览!$D$3:$U$33,3,0),$A14>VLOOKUP(D$2,行为概览!$D$3:$U$33,4,0)),0,VLOOKUP(D$2,行为概览!$D$3:$U$33,6,0)),4) -> 0 | E14: =ROUND(IF(OR($A14<VLOOKUP(E$2,行为概览!$D$3:$U$33,3,0),$A14>VLOOKUP(E$2,行为概览!$D$3:$U$33,4,0)),0,VLOOKUP(E$2,行为概览!$D$3:$U$33,6,0)),4) -> 0 | F14: =ROUND(IF(OR($A14<VLOOKUP(F$2,行为概览!$D$3:$U$33,3,0),$A14>VLOOKUP(F$2,行为概览!$D$3:$U$33,4,0)),0,VLOOKUP(F$2,行为概览!$D$3:$U$33,6,0)),4) -> 0 | G14: =ROUND(IF(OR($A14<VLOOKUP(G$2,行为概览!$D$3:$U$33,3,0),$A14>VLOOKUP(G$2,行为概览!$D$3:$U$33,4,0)),0,VLOOKUP(G$2,行为概览!$D$3:$U$33,6,0)),4) -> 0 | H14: =ROUND(IF(OR($A14<VLOOKUP(H$2,行为概览!$D$3:$U$33,3,0),$A14>VLOOKUP(H$2,行为概览!$D$3:$U$33,4,0)),0,VLOOKUP(H$2,行为概览!$D$3:$U$33,6,0)),4) -> 0 | I14: =ROUND(IF(OR($A14<VLOOKUP(I$2,行为概览!$D$3:$U$33,3,0),$A14>VLOOKUP(I$2,行为概览!$D$3:$U$33,4,0)),0,VLOOKUP(I$2,行为概览!$D$3:$U$33,6,0)),4) -> 0 | ... AF14: =ROUND(IF(OR($A14<VLOOKUP(AF$2,行为概览!$D$3:$U$33,3,0),$A14>VLOOKUP(AF$2,行为概览!$D$3:$U$33,4,0)),0,VLOOKUP(AF$2,行为概览!$D$3:$U$33,6,0)),4) -> 0
... A152: 150 | B152: =ROUND(IF(OR($A152<VLOOKUP(B$2,行为概览!$D$3:$U$33,3,0),$A152>VLOOKUP(B$2,行为概览!$D$3:$U$33,4,0)),0,VLOOKUP(B$2,行为概览!$D$3:$U$33,6,0)),4) -> 0.3333 | C152: =ROUND(IF(OR($A152<VLOOKUP(C$2,行为概览!$D$3:$U$33,3,0),$A152>VLOOKUP(C$2,行为概览!$D$3:$U$33,4,0)),0,VLOOKUP(C$2,行为概览!$D$3:$U$33,6,0)),4) -> 2 | D152: =ROUND(IF(OR($A152<VLOOKUP(D$2,行为概览!$D$3:$U$33,3,0),$A152>VLOOKUP(D$2,行为概览!$D$3:$U$33,4,0)),0,VLOOKUP(D$2,行为概览!$D$3:$U$33,6,0)),4) -> 0.0833 | E152: =ROUND(IF(OR($A152<VLOOKUP(E$2,行为概览!$D$3:$U$33,3,0),$A152>VLOOKUP(E$2,行为概览!$D$3:$U$33,4,0)),0,VLOOKUP(E$2,行为概览!$D$3:$U$33,6,0)),4) -> 1 | F152: =ROUND(IF(OR($A152<VLOOKUP(F$2,行为概览!$D$3:$U$33,3,0),$A152>VLOOKUP(F$2,行为概览!$D$3:$U$33,4,0)),0,VLOOKUP(F$2,行为概览!$D$3:$U$33,6,0)),4) -> 0.3333 | G152: =ROUND(IF(OR($A152<VLOOKUP(G$2,行为概览!$D$3:$U$33,3,0),$A152>VLOOKUP(G$2,行为概览!$D$3:$U$33,4,0)),0,VLOOKUP(G$2,行为概览!$D$3:$U$33,6,0)),4) -> 0 | H152: =ROUND(IF(OR($A152<VLOOKUP(H$2,行为概览!$D$3:$U$33,3,0),$A152>VLOOKUP(H$2,行为概览!$D$3:$U$33,4,0)),0,VLOOKUP(H$2,行为概览!$D$3:$U$33,6,0)),4) -> 0 | I152: =ROUND(IF(OR($A152<VLOOKUP(I$2,行为概览!$D$3:$U$33,3,0),$A152>VLOOKUP(I$2,行为概览!$D$3:$U$33,4,0)),0,VLOOKUP(I$2,行为概览!$D$3:$U$33,6,0)),4) -> 0 | ... AF152: =ROUND(IF(OR($A152<VLOOKUP(AF$2,行为概览!$D$3:$U$33,3,0),$A152>VLOOKUP(AF$2,行为概览!$D$3:$U$33,4,0)),0,VLOOKUP(AF$2,行为概览!$D$3:$U$33,6,0)),4) -> 0

Sheet 升级节奏
C1: 主角
B2: 等级 | C2: 基准效率1小时获得经验(h) | D2: 基准效率1小时获得宠物经验(h) | E2: 基准权重银币 | F2: 基准权重金币 | G2: 停留时间(d) | H2: 累计时间(d) | I2: 手调系数 | J2: 公会资金 | L2: 服务器等级天数 | M2: 持续天数
B3: 1 | C3: =400*B3 -> 400 | D3: =5000*B3 -> 5000 | E3: =1000*B3 -> 1000 | F3: =1*B3 -> 1 | G3: =0.2*(1+0.01*B3^2)/24*I3 -> 0 | H3: =SUM($G$3:G3) -> 0 | I3: 0 | J3: =2500+50*B3 -> 2550 | M3: =IF(L3="","",1)
B4: 2 | C4: =400*B4 -> 800 | D4: =5000*B4 -> 10000 | E4: =1000*B4 -> 2000 | F4: =1*B4 -> 2 | G4: =0.2*(1+0.01*B4^2)/24*I4 -> 0 | H4: =SUM($G$3:G4) -> 0 | I4: 0 | J4: =2500+50*B4 -> 2600 | M4: =IF(L4="","",1)
B5: 3 | C5: =400*B5 -> 1200 | D5: =5000*B5 -> 15000 | E5: =1000*B5 -> 3000 | F5: =1*B5 -> 3 | G5: =0.2*(1+0.01*B5^2)/24*I5 -> 0 | H5: =SUM($G$3:G5) -> 0 | I5: 0 | J5: =2500+50*B5 -> 2650 | M5: =IF(L5="","",1)
B6: 4 | C6: =400*B6 -> 1600 | D6: =5000*B6 -> 20000 | E6: =1000*B6 -> 4000 | F6: =1*B6 -> 4 | G6: =0.2*(1+0.01*B6^2)/24*I6 -> 0 | H6: =SUM($G$3:G6) -> 0 | I6: 0 | J6: =2500+50*B6 -> 2700 | M6: =IF(L6="","",1)
B7: 5 | C7: =400*B7 -> 2000 | D7: =5000*B7 -> 25000 | E7: =1000*B7 -> 5000 | F7: =1*B7 -> 5 | G7: =0.2*(1+0.01*B7^2)/24*I7 -> 0 | H7: =SUM($G$3:G7) -> 0 | I7: 0 | J7: =2500+50*B7 -> 2750 | M7: =IF(L7="","",1)
B8: 6 | C8: =400*B8 -> 2400 | D8: =5000*B8 -> 30000 | E8: =1000*B8 -> 6000 | F8: =1*B8 -> 6 | G8: =0.2*(1+0.01*B8^2)/24*I8 -> 0 | H8: =SUM($G$3:G8) -> 0 | I8: 0 | J8: =2500+50*B8 -> 2800 | M8: =IF(L8="","",1)
B9: 7 | C9: =400*B9 -> 2800 | D9: =5000*B9 -> 35000 | E9: =1000*B9 -> 7000 | F9: =1*B9 -> 7 | G9: =0.2*(1+0.01*B9^2)/24*I9 -> 0 | H9: =SUM($G$3:G9) -> 0 | I9: 0 | J9: =2500+50*B9 -> 2850 | M9: =IF(L9="","",1)
B10: 8 | C10: =400*B10 -> 3200 | D10: =5000*B10 -> 40000 | E10: =1000*B10 -> 8000 | F10: =1*B10 -> 8 | G10: =0.2*(1+0.01*B10^2)/24*I10 -> 0 | H10: =SUM($G$3:G10) -> 0 | I10: 0 | J10: =2500+50*B10 -> 2900 | M10: =IF(L10="","",1)
B11: 9 | C11: =400*B11 -> 3600 | D11: =5000*B11 -> 45000 | E11: =1000*B11 -> 9000 | F11: =1*B11 -> 9 | G11: =0.2*(1+0.01*B11^2)/24*I11 -> 0 | H11: =SUM($G$3:G11) -> 0 | I11: 0 | J11: =2500+50*B11 -> 2950 | M11: =IF(L11="","",1)
B12: 10 | C12: =400*B12 -> 4000 | D12: =5000*B12 -> 50000 | E12: =1000*B12 -> 10000 | F12: =1*B12 -> 10 | G12: =0.2*(1+0.01*B12^2)/24*I12 -> 0 | H12: =SUM($G$3:G12) -> 0 | I12: 0 | J12: =2500+50*B12 -> 3000 | M12: =IF(L12="","",1)
B13: 11 | C13: =400*B13 -> 4400 | D13: =5000*B13 -> 55000 | E13: =1000*B13 -> 11000 | F13: =1*B13 -> 11 | G13: =0.2*(1+0.01*B13^2)/24*I13 -> 0 | H13: =SUM($G$3:G13) -> 0 | I13: 0 | J13: =2500+50*B13 -> 3050 | M13: =IF(L13="","",1)
B14: 12 | C14: =400*B14 -> 4800 | D14: =5000*B14 -> 60000 | E14: =1000*B14 -> 12000 | F14: =1*B14 -> 12 | G14: =0.2*(1+0.01*B14^2)/24*I14 -> 0 | H14: =SUM($G$3:G14) -> 0 | I14: 0 | J14: =2500+50*B14 -> 3100 | M14: =IF(L14="","",1)
... B39: 37 | C39: =400*B39 -> 14800 | D39: =5000*B39 -> 185000 | E39: =1000*B39 -> 37000 | F39: =1*B39 -> 37 | G39: =0.2*(1+0.01*B39^2)/24*I39 -> 0.13465833 | H39: =SUM($G$3:G39) -> 0.93738333 | I39: 1.1 | J39: =2500+50*B39 -> 4350 | M39: =IF(L39="","",1)
B40: 38 | C40: =400*B40 -> 15200 | D40: =5000*B40 -> 190000 | E40: =1000*B40 -> 38000 | F40: =1*B40 -> 38 | G40: =0.2*(1+0.01*B40^2)/24*I40 -> 0.14153333 | H40: =SUM($G$3:G40) -> 1.0789167 | I40: 1.1 | J40: =2500+50*B40 -> 4400 | K40: =ROUNDUP(H39,0) -> 1 | M40: =IF(L40="","",1)
B41: 39 | C41: =400*B41 -> 15600 | D41: =5000*B41 -> 195000 | E41: =1000*B41 -> 39000 | F41: =1*B41 -> 39 | G41: =0.2*(1+0.01*B41^2)/24*I41 -> 0.17560833 | H41: =SUM($G$3:G41) -> 1.254525 | I41: 1.3 | J41: =2500+50*B41 -> 4450 | L41: 1 | M41: =IF(L41="","",1) -> 1
B42: 40 | C42: =400*B42 -> 16000 | D42: =5000*B42 -> 200000 | E42: =1000*B42 -> 40000 | F42: =1*B42 -> 40 | G42: =0.2*(1+0.01*B42^2)/24*I42 -> 0.18416667 | H42: =SUM($G$3:G42) -> 1.4386917 | I42: 1.3 | J42: =2500+50*B42 -> 4500 | M42: =IF(L42="","",1)
B43: 41 | C43: =400*B43 -> 16400 | D43: =5000*B43 -> 205000 | E43: =1000*B43 -> 41000 | F43: =1*B43 -> 41 | G43: =0.2*(1+0.01*B43^2)/24*I43 -> 0.19294167 | H43: =SUM($G$3:G43) -> 1.6316333 | I43: 1.3 | J43: =2500+50*B43 -> 4550 | M43: =IF(L43="","",1)
B44: 42 | C44: =400*B44 -> 16800 | D44: =5000*B44 -> 210000 | E44: =1000*B44 -> 42000 | F44: =1*B44 -> 42 | G44: =0.2*(1+0.01*B44^2)/24*I44 -> 0.20193333 | H44: =SUM($G$3:G44) -> 1.8335667 | I44: 1.3 | J44: =2500+50*B44 -> 4600 | M44: =IF(L44="","",1)
B45: 43 | C45: =400*B45 -> 17200 | D45: =5000*B45 -> 215000 | E45: =1000*B45 -> 43000 | F45: =1*B45 -> 43 | G45: =0.2*(1+0.01*B45^2)/24*I45 -> 0.21114167 | H45: =SUM($G$3:G45) -> 2.0447083 | I45: 1.3 | J45: =2500+50*B45 -> 4650 | K45: =ROUNDUP(H44,0) -> 2 | M45: =IF(L45="","",1)
B46: 44 | C46: =400*B46 -> 17600 | D46: =5000*B46 -> 220000 | E46: =1000*B46 -> 44000 | F46: =1*B46 -> 44 | G46: =0.2*(1+0.01*B46^2)/24*I46 -> 0.2545 | H46: =SUM($G$3:G46) -> 2.2992083 | I46: 1.5 | J46: =2500+50*B46 -> 4700 | L46: 2 | M46: 1
B47: 45 | C47: =400*B47 -> 18000 | D47: =5000*B47 -> 225000 | E47: =1000*B47 -> 45000 | F47: =1*B47 -> 45 | G47: =0.2*(1+0.01*B47^2)/24*I47 -> 0.265625 | H47: =SUM($G$3:G47) -> 2.5648333 | I47: 1.5 | J47: =2500+50*B47 -> 4750
B48: 46 | C48: =400*B48 -> 18400 | D48: =5000*B48 -> 230000 | E48: =1000*B48 -> 46000 | F48: =1*B48 -> 46 | G48: =0.2*(1+0.01*B48^2)/24*I48 -> 0.277 | H48: =SUM($G$3:G48) -> 2.8418333 | I48: 1.5 | J48: =2500+50*B48 -> 4800 | M48: =IF(L48="","",1)
B49: 47 | C49: =400*B49 -> 18800 | D49: =5000*B49 -> 235000 | E49: =1000*B49 -> 47000 | F49: =1*B49 -> 47 | G49: =0.2*(1+0.01*B49^2)/24*I49 -> 0.288625 | H49: =SUM($G$3:G49) -> 3.1304583 | I49: 1.5 | J49: =2500+50*B49 -> 4850 | K49: =ROUNDUP(H48,0) -> 3 | M49: =IF(L49="","",1)
B50: 48 | C50: =400*B50 -> 19200 | D50: =5000*B50 -> 240000 | E50: =1000*B50 -> 48000 | F50: =1*B50 -> 48 | G50: =0.2*(1+0.01*B50^2)/24*I50 -> 0.3005 | H50: =SUM($G$3:G50) -> 3.4309583 | I50: 1.5 | J50: =2500+50*B50 -> 4900 | L50: 3 | M50: =IF(L50="","",1) -> 1
B51: 49 | C51: =400*B51 -> 19600 | D51: =5000*B51 -> 245000 | E51: =1000*B51 -> 49000 | F51: =1*B51 -> 49 | G51: =0.2*(1+0.01*B51^2)/24*I51 -> 0.35430833 | H51: =SUM($G$3:G51) -> 3.7852667 | I51: 1.7 | J51: =2500+50*B51 -> 4950 | M51: =IF(L51="","",1)
B52: 50 | C52: =400*B52 -> 20000 | D52: =5000*B52 -> 250000 | E52: =1000*B52 -> 50000 | F52: =1*B52 -> 50 | G52: =0.2*(1+0.01*B52^2)/24*I52 -> 0.36833333 | H52: =SUM($G$3:G52) -> 4.1536 | I52: 1.7 | J52: =2500+50*B52 -> 5000 | K52: =ROUNDUP(H51,0) -> 4 | M52: =IF(L52="","",1)
B53: 51 | C53: =400*B53 -> 20400 | D53: =5000*B53 -> 255000 | E53: =1000*B53 -> 51000 | F53: =1*B53 -> 51 | G53: =0.2*(1+0.01*B53^2)/24*I53 -> 0.38264167 | H53: =SUM($G$3:G53) -> 4.5362417 | I53: 1.7 | J53: =2500+50*B53 -> 5050 | L53: 4 | M53: =IF(L53="","",1) -> 1
B54: 52 | C54: =400*B54 -> 20800 | D54: =5000*B54 -> 260000 | E54: =1000*B54 -> 52000 | F54: =1*B54 -> 52 | G54: =0.2*(1+0.01*B54^2)/24*I54 -> 0.39723333 | H54: =SUM($G$3:G54) -> 4.933475 | I54: 1.7 | J54: =2500+50*B54 -> 5100 | M54: =IF(L54="","",1)
B55: 53 | C55: =400*B55 -> 21200 | D55: =5000*B55 -> 265000 | E55: =1000*B55 -> 53000 | F55: =1*B55 -> 53 | G55: =0.2*(1+0.01*B55^2)/24*I55 -> 0.41210833 | H55: =SUM($G$3:G55) -> 5.3455833 | I55: 1.7 | J55: =2500+50*B55 -> 5150 | K55: =ROUNDUP(H54,0) -> 5 | M55: =IF(L55="","",1)
B56: 54 | C56: =400*B56 -> 21600 | D56: =5000*B56 -> 270000 | E56: =1000*B56 -> 54000 | F56: =1*B56 -> 54 | G56: =0.2*(1+0.01*B56^2)/24*I56 -> 0.50266667 | H56: =SUM($G$3:G56) -> 5.84825 | I56: 2 | J56: =2500+50*B56 -> 5200 | L56: 5 | M56: =IF(L56="","",1) -> 1
B57: 55 | C57: =400*B57 -> 22000 | D57: =5000*B57 -> 275000 | E57: =1000*B57 -> 55000 | F57: =1*B57 -> 55 | G57: =0.2*(1+0.01*B57^2)/24*I57 -> 0.52083333 | H57: =SUM($G$3:G57) -> 6.3690833 | I57: 2 | J57: =2500+50*B57 -> 5250 | K57: =ROUNDUP(H56,0) -> 6 | M57: =IF(L57="","",1)
B58: 56 | C58: =400*B58 -> 22400 | D58: =5000*B58 -> 280000 | E58: =1000*B58 -> 56000 | F58: =1*B58 -> 56 | G58: =0.2*(1+0.01*B58^2)/24*I58 -> 0.809 | H58: =SUM($G$3:G58) -> 7.1780833 | I58: 3 | J58: =2500+50*B58 -> 5300 | L58: 6 | M58: =IF(L58="","",1) -> 1
B59: 57 | C59: =400*B59 -> 22800 | D59: =5000*B59 -> 285000 | E59: =1000*B59 -> 57000 | F59: =1*B59 -> 57 | G59: =0.2*(1+0.01*B59^2)/24*I59 -> 0.83725 | H59: =SUM($G$3:G59) -> 8.0153333 | I59: 3 | J59: =2500+50*B59 -> 5350 | M59: =IF(L59="","",1)
B60: 58 | C60: =400*B60 -> 23200 | D60: =5000*B60 -> 290000 | E60: =1000*B60 -> 58000 | F60: =1*B60 -> 58 | G60: =0.2*(1+0.01*B60^2)/24*I60 -> 0.866 | H60: =SUM($G$3:G60) -> 8.8813333 | I60: 3 | J60: =2500+50*B60 -> 5400 | L60: 7 | M60: =IF(G60-INT(G60)>=0.2,ROUNDUP(G60,0),ROUNDDOWN(G60,0)) -> 1
B61: 59 | C61: =400*B61 -> 23600 | D61: =5000*B61 -> 295000 | E61: =1000*B61 -> 59000 | F61: =1*B61 -> 59 | G61: =0.2*(1+0.01*B61^2)/24*I61 -> 0.89525 | H61: =SUM($G$3:G61) -> 9.7765833 | I61: 3 | J61: =2500+50*B61 -> 5450 | L61: =L60+M60 -> 8 | M61: =IF(G61-INT(G61)>=0.2,ROUNDUP(G61,0),ROUNDDOWN(G61,0)) -> 1
B62: 60 | C62: =400*B62 -> 24000 | D62: =5000*B62 -> 300000 | E62: =1000*B62 -> 60000 | F62: =1*B62 -> 60 | G62: =0.2*(1+0.01*B62^2)/24*I62 -> 1.2333333 | H62: =SUM($G$3:G62) -> 11.009917 | I62: 4 | J62: =2500+50*B62 -> 5500 | K62: =ROUNDUP(H61,0) -> 10 | L62: =L61+M61 -> 9 | M62: =IF(G62-INT(G62)>=0.2,ROUNDUP(G62,0),ROUNDDOWN(G62,0)) -> 2
B63: 61 | C63: =400*B63 -> 24400 | D63: =5000*B63 -> 305000 | E63: =1000*B63 -> 61000 | F63: =1*B63 -> 61 | G63: =0.2*(1+0.01*B63^2)/24*I63 -> 1.5920833 | H63: =SUM($G$3:G63) -> 12.602 | I63: 5 | J63: =2500+50*B63 -> 5550 | L63: =L62+M62 -> 11 | M63: =IF(G63-INT(G63)>=0.2,ROUNDUP(G63,0),ROUNDDOWN(G63,0)) -> 2
B64: 62 | C64: =400*B64 -> 24800 | D64: =5000*B64 -> 310000 | E64: =1000*B64 -> 62000 | F64: =1*B64 -> 62 | G64: =0.2*(1+0.01*B64^2)/24*I64 -> 1.972 | H64: =SUM($G$3:G64) -> 14.574 | I64: 6 | J64: =2500+50*B64 -> 5600 | L64: =L63+M63 -> 13 | M64: =IF(G64-INT(G64)>=0.2,ROUNDUP(G64,0),ROUNDDOWN(G64,0)) -> 2
...

Sheet 主角经验
C1: 产出效率 | AF1: 日常活动每日产出权重 | AV1: 定时活动每日产出权重 | BG1: 节日活动每日产出权重
A2: 角色等级 | B2: 基准效率1小时获得经验(h） | C2: 职业日常 | D2: 日常副本 | E2: 英雄试炼 | F2: 冰封王座 | G2: 考古 | H2: 运镖 | I2: 卡拉赞系列 | J2: 卡拉赞精英 | K2: 精英副本 | L2: 公会任务(周7轮) | M2: 暗夜马戏团(周20轮) | N2: 野外挂机/离线经验 | O2: 经验道具 | P2: 分享 | Q2: 双倍点数 | R2: 援助战斗和道具 | S2: 古神爪牙 | T2: 幼龙 | U2: 屠龙 | V2: 古神 | W2: 艾泽拉斯地理探索 | X2: 艾泽拉斯百科竞赛 | Y2: 职业闯关(周2次) | Z2: 竞技场（周5次） | AA2: 公会副本(周1次) | AB2: 帮派强盗 | AC2: 帮派采药 | AD2: 节日活动1 | AE2: 节日活动2 | AF2: 职业日常 | AG2: 日常副本 | AH2: 英雄试炼 | AI2: 冰封王座 | AJ2: 考古 | AK2: 运镖 | AL2: 卡拉赞系列 | AM2: 卡拉赞精英 | AN2: 精英副本 | AO2: 公会任务(周7轮) | AP2: 暗夜马戏团(周20轮) | AQ2: 野外挂机/离线经验 | AR2: 经验道具 | AS2: 分享 | AT2: 双倍点数 | AU2: 援助战斗和道具 | AV2: 古神爪牙 | AW2: 幼龙 | AX2: 屠龙 | AY2: 古神 | AZ2: 艾泽拉斯地理探索 | BA2: 艾泽拉斯百科竞赛 | BB2: 职业闯关(周2次) | BC2: 竞技场（周5次） | BD2: 公会副本(周1次) | BE2: 帮派强盗 | BF2: 帮派采药 | BG2: 节日活动1 | BH2: 节日活动2 | BI2: 每日循环总量 | BJ2: 每日循环收益 | BK2: 剧情任务收益 | BL2: 剧情任务分段经验 | BM2: 剧情任务经验占比 | BN2: 主角升级经验 *暂时不算上节日活动的经验 | BO2: 刷野战斗经验
A3: 1 | B3: =升级节奏!C3 -> 400 | C3: =IF(VLOOKUP(C$2,行为概览!$D$3:$J$33,7,0)="","",VLOOKUP(C$2,行为概览!$D$3:$J$33,7,0)) -> 50 | D3: =IF(VLOOKUP(D$2,行为概览!$D$3:$J$33,7,0)="","",VLOOKUP(D$2,行为概览!$D$3:$J$33,7,0)) -> 3.3 | E3: =IF(VLOOKUP(E$2,行为概览!$D$3:$J$33,7,0)="","",VLOOKUP(E$2,行为概览!$D$3:$J$33,7,0)) -> 30 | F3: =IF(VLOOKUP(F$2,行为概览!$D$3:$J$33,7,0)="","",VLOOKUP(F$2,行为概览!$D$3:$J$33,7,0)) -> 15 | G3: =IF(VLOOKUP(G$2,行为概览!$D$3:$J$33,7,0)="","",VLOOKUP(G$2,行为概览!$D$3:$J$33,7,0)) | H3: =IF(VLOOKUP(H$2,行为概览!$D$3:$J$33,7,0)="","",VLOOKUP(H$2,行为概览!$D$3:$J$33,7,0)) | I3: =IF(VLOOKUP(I$2,行为概览!$D$3:$J$33,7,0)="","",VLOOKUP(I$2,行为概览!$D$3:$J$33,7,0)) | J3: =IF(VLOOKUP(J$2,行为概览!$D$3:$J$33,7,0)="","",VLOOKUP(J$2,行为概览!$D$3:$J$33,7,0)) | ... AE3: =IF(VLOOKUP(AE$2,行为概览!$D$3:$J$33,7,0)="","",VLOOKUP(AE$2,行为概览!$D$3:$J$33,7,0)) | AF3: =IF(C3="","",ROUND(C3*玩法行为规划!B3,2)) -> 0 | AG3: =IF(D3="","",ROUND(D3*玩法行为规划!C3,2)) -> 0 | AH3: =IF(E3="","",ROUND(E3*玩法行为规划!D3,2)) -> 0 | AI3: =IF(F3="","",ROUND(F3*玩法行为规划!E3,2)) -> 0 | AJ3: =IF(G3="","",ROUND(G3*玩法行为规划!F3,2)) | AK3: =IF(H3="","",ROUND(H3*玩法行为规划!G3,2)) | AL3: =IF(I3="","",ROUND(I3*玩法行为规划!H3,2)) | AM3: =IF(J3="","",ROUND(J3*玩法行为规划!I3,2)) | ... BH3: =IF(AE3="","",ROUND(AE3*玩法行为规划!AD3,2)) | BI3: =SUM(AF3:BF3) -> 52 | BJ3: =B3*BI3 -> 20800 | BK3: =ROUND(B3*(4+MAX(A3-30,0)*0.6),-2) -> 1600 | BL3: =SUM(BK3:BK11) -> 72000 | BM3: =BK3/BN3 -> 1 | BN3: =INT(BJ3*升级节奏!G3+BK3) -> 1600 | BO3: =ROUND(B3/90,0) -> 4
A4: 2 | B4: =升级节奏!C4 -> 800 | C4: =IF(VLOOKUP(C$2,行为概览!$D$3:$J$33,7,0)="","",VLOOKUP(C$2,行为概览!$D$3:$J$33,7,0)) -> 50 | D4: =IF(VLOOKUP(D$2,行为概览!$D$3:$J$33,7,0)="","",VLOOKUP(D$2,行为概览!$D$3:$J$33,7,0)) -> 3.3 | E4: =IF(VLOOKUP(E$2,行为概览!$D$3:$J$33,7,0)="","",VLOOKUP(E$2,行为概览!$D$3:$J$33,7,0)) -> 30 | F4: =IF(VLOOKUP(F$2,行为概览!$D$3:$J$33,7,0)="","",VLOOKUP(F$2,行为概览!$D$3:$J$33,7,0)) -> 15 | G4: =IF(VLOOKUP(G$2,行为概览!$D$3:$J$33,7,0)="","",VLOOKUP(G$2,行为概览!$D$3:$J$33,7,0)) | H4: =IF(VLOOKUP(H$2,行为概览!$D$3:$J$33,7,0)="","",VLOOKUP(H$2,行为概览!$D$3:$J$33,7,0)) | I4: =IF(VLOOKUP(I$2,行为概览!$D$3:$J$33,7,0)="","",VLOOKUP(I$2,行为概览!$D$3:$J$33,7,0)) | J4: =IF(VLOOKUP(J$2,行为概览!$D$3:$J$33,7,0)="","",VLOOKUP(J$2,行为概览!$D$3:$J$33,7,0)) | ... AE4: =IF(VLOOKUP(AE$2,行为概览!$D$3:$J$33,7,0)="","",VLOOKUP(AE$2,行为概览!$D$3:$J$33,7,0)) | AF4: =IF(C4="","",ROUND(C4*玩法行为规划!B4,2)) -> 0 | AG4: =IF(D4="","",ROUND(D4*玩法行为规划!C4,2)) -> 0 | AH4: =IF(E4="","",ROUND(E4*玩法行为规划!D4,2)) -> 0 | AI4: =IF(F4="","",ROUND(F4*玩法行为规划!E4,2)) -> 0 | AJ4: =IF(G4="","",ROUND(G4*玩法行为规划!F4,2)) | AK4: =IF(H4="","",ROUND(H4*玩法行为规划!G4,2)) | AL4: =IF(I4="","",ROUND(I4*玩法行为规划!H4,2)) | AM4: =IF(J4="","",ROUND(J4*玩法行为规划!I4,2)) | ... BH4: =IF(AE4="","",ROUND(AE4*玩法行为规划!AD4,2)) | BI4: =SUM(AF4:BF4) -> 52 | BJ4: =B4*BI4 -> 41600 | BK4: =ROUND(B4*(4+MAX(A4-30,0)*0.6),-2) -> 3200 | BM4: =BK4/BN4 -> 1 | BN4: =INT(BJ4*升级节奏!G4+BK4) -> 3200 | BO4: =ROUND(B4/90,0) -> 9
A5: 3 | B5: =升级节奏!C5 -> 1200 | C5: =IF(VLOOKUP(C$2,行为概览!$D$3:$J$33,7,0)="","",VLOOKUP(C$2,行为概览!$D$3:$J$33,7,0)) -> 50 | D5: =IF(VLOOKUP(D$2,行为概览!$D$3:$J$33,7,0)="","",VLOOKUP(D$2,行为概览!$D$3:$J$33,7,0)) -> 3.3 | E5: =IF(VLOOKUP(E$2,行为概览!$D$3:$J$33,7,0)="","",VLOOKUP(E$2,行为概览!$D$3:$J$33,7,0)) -> 30 | F5: =IF(VLOOKUP(F$2,行为概览!$D$3:$J$33,7,0)="","",VLOOKUP(F$2,行为概览!$D$3:$J$33,7,0)) -> 15 | G5: =IF(VLOOKUP(G$2,行为概览!$D$3:$J$33,7,0)="","",VLOOKUP(G$2,行为概览!$D$3:$J$33,7,0)) | H5: =IF(VLOOKUP(H$2,行为概览!$D$3:$J$33,7,0)="","",VLOOKUP(H$2,行为概览!$D$3:$J$33,7,0)) | I5: =IF(VLOOKUP(I$2,行为概览!$D$3:$J$33,7,0)="","",VLOOKUP(I$2,行为概览!$D$3:$J$33,7,0)) | J5: =IF(VLOOKUP(J$2,行为概览!$D$3:$J$33,7,0)="","",VLOOKUP(J$2,行为概览!$D$3:$J$33,7,0)) | ... AE5: =IF(VLOOKUP(AE$2,行为概览!$D$3:$J$33,7,0)="","",VLOOKUP(AE$2,行为概览!$D$3:$J$33,7,0)) | AF5: =IF(C5="","",ROUND(C5*玩法行为规划!B5,2)) -> 0 | AG5: =IF(D5="","",ROUND(D5*玩法行为规划!C5,2)) -> 0 | AH5: =IF(E5="","",ROUND(E5*玩法行为规划!D5,2)) -> 0 | AI5: =IF(F5="","",ROUND(F5*玩法行为规划!E5,2)) -> 0 | AJ5: =IF(G5="","",ROUND(G5*玩法行为规划!F5,2)) | AK5: =IF(H5="","",ROUND(H5*玩法行为规划!G5,2)) | AL5: =IF(I5="","",ROUND(I5*玩法行为规划!H5,2)) | AM5: =IF(J5="","",ROUND(J5*玩法行为规划!I5,2)) | ... BH5: =IF(AE5="","",ROUND(AE5*玩法行为规划!AD5,2)) | BI5: =SUM(AF5:BF5) -> 52 | BJ5: =B5*BI5 -> 62400 | BK5: =ROUND(B5*(4+MAX(A5-30,0)*0.6),-2) -> 4800 | BM5: =BK5/BN5 -> 1 | BN5: =INT(BJ5*升级节奏!G5+BK5) -> 4800 | BO5: =ROUND(B5/90,0) -> 13
A6: 4 | B6: =升级节奏!C6 -> 1600 | C6: =IF(VLOOKUP(C$2,行为概览!$D$3:$J$33,7,0)="","",VLOOKUP(C$2,行为概览!$D$3:$J$33,7,0)) -> 50 | D6: =IF(VLOOKUP(D$2,行为概览!$D$3:$J$33,7,0)="","",VLOOKUP(D$2,行为概览!$D$3:$J$33,7,0)) -> 3.3 | E6: =IF(VLOOKUP(E$2,行为概览!$D$3:$J$33,7,0)="","",VLOOKUP(E$2,行为概览!$D$3:$J$33,7,0)) -> 30 | F6: =IF(VLOOKUP(F$2,行为概览!$D$3:$J$33,7,0)="","",VLOOKUP(F$2,行为概览!$D$3:$J$33,7,0)) -> 15 | G6: =IF(VLOOKUP(G$2,行为概览!$D$3:$J$33,7,0)="","",VLOOKUP(G$2,行为概览!$D$3:$J$33,7,0)) | H6: =IF(VLOOKUP(H$2,行为概览!$D$3:$J$33,7,0)="","",VLOOKUP(H$2,行为概览!$D$3:$J$33,7,0)) | I6: =IF(VLOOKUP(I$2,行为概览!$D$3:$J$33,7,0)="","",VLOOKUP(I$2,行为概览!$D$3:$J$33,7,0)) | J6: =IF(VLOOKUP(J$2,行为概览!$D$3:$J$33,7,0)="","",VLOOKUP(J$2,行为概览!$D$3:$J$33,7,0)) | ... AE6: =IF(VLOOKUP(AE$2,行为概览!$D$3:$J$33,7,0)="","",VLOOKUP(AE$2,行为概览!$D$3:$J$33,7,0)) | AF6: =IF(C6="","",ROUND(C6*玩法行为规划!B6,2)) -> 0 | AG6: =IF(D6="","",ROUND(D6*玩法行为规划!C6,2)) -> 0 | AH6: =IF(E6="","",ROUND(E6*玩法行为规划!D6,2)) -> 0 | AI6: =IF(F6="","",ROUND(F6*玩法行为规划!E6,2)) -> 0 | AJ6: =IF(G6="","",ROUND(G6*玩法行为规划!F6,2)) | AK6: =IF(H6="","",ROUND(H6*玩法行为规划!G6,2)) | AL6: =IF(I6="","",ROUND(I6*玩法行为规划!H6,2)) | AM6: =IF(J6="","",ROUND(J6*玩法行为规划!I6,2)) | ... BH6: =IF(AE6="","",ROUND(AE6*玩法行为规划!AD6,2)) | BI6: =SUM(AF6:BF6) -> 52 | BJ6: =B6*BI6 -> 83200 | BK6: =ROUND(B6*(4+MAX(A6-30,0)*0.6),-2) -> 6400 | BM6: =BK6/BN6 -> 1 | BN6: =INT(BJ6*升级节奏!G6+BK6) -> 6400 | BO6: =ROUND(B6/90,0) -> 18
A7: 5 | B7: =升级节奏!C7 -> 2000 | C7: =IF(VLOOKUP(C$2,行为概览!$D$3:$J$33,7,0)="","",VLOOKUP(C$2,行为概览!$D$3:$J$33,7,0)) -> 50 | D7: =IF(VLOOKUP(D$2,行为概览!$D$3:$J$33,7,0)="","",VLOOKUP(D$2,行为概览!$D$3:$J$33,7,0)) -> 3.3 | E7: =IF(VLOOKUP(E$2,行为概览!$D$3:$J$33,7,0)="","",VLOOKUP(E$2,行为概览!$D$3:$J$33,7,0)) -> 30 | F7: =IF(VLOOKUP(F$2,行为概览!$D$3:$J$33,7,0)="","",VLOOKUP(F$2,行为概览!$D$3:$J$33,7,0)) -> 15 | G7: =IF(VLOOKUP(G$2,行为概览!$D$3:$J$33,7,0)="","",VLOOKUP(G$2,行为概览!$D$3:$J$33,7,0)) | H7: =IF(VLOOKUP(H$2,行为概览!$D$3:$J$33,7,0)="","",VLOOKUP(H$2,行为概览!$D$3:$J$33,7,0)) | I7: =IF(VLOOKUP(I$2,行为概览!$D$3:$J$33,7,0)="","",VLOOKUP(I$2,行为概览!$D$3:$J$33,7,0)) | J7: =IF(VLOOKUP(J$2,行为概览!$D$3:$J$33,7,0)="","",VLOOKUP(J$2,行为概览!$D$3:$J$33,7,0)) | ... AE7: =IF(VLOOKUP(AE$2,行为概览!$D$3:$J$33,7,0)="","",VLOOKUP(AE$2,行为概览!$D$3:$J$33,7,0)) | AF7: =IF(C7="","",ROUND(C7*玩法行为规划!B7,2)) -> 0 | AG7: =IF(D7="","",ROUND(D7*玩法行为规划!C7,2)) -> 0 | AH7: =IF(E7="","",ROUND(E7*玩法行为规划!D7,2)) -> 0 | AI7: =IF(F7="","",ROUND(F7*玩法行为规划!E7,2)) -> 0 | AJ7: =IF(G7="","",ROUND(G7*玩法行为规划!F7,2)) | AK7: =IF(H7="","",ROUND(H7*玩法行为规划!G7,2)) | AL7: =IF(I7="","",ROUND(I7*玩法行为规划!H7,2)) | AM7: =IF(J7="","",ROUND(J7*玩法行为规划!I7,2)) | ... BH7: =IF(AE7="","",ROUND(AE7*玩法行为规划!AD7,2)) | BI7: =SUM(AF7:BF7) -> 52 | BJ7: =B7*BI7 -> 104000 | BK7: =ROUND(B7*(4+MAX(A7-30,0)*0.6),-2) -> 8000 | BM7: =BK7/BN7 -> 1 | BN7: =INT(BJ7*升级节奏!G7+BK7) -> 8000 | BO7: =ROUND(B7/90,0) -> 22
A8: 6 | B8: =升级节奏!C8 -> 2400 | C8: =IF(VLOOKUP(C$2,行为概览!$D$3:$J$33,7,0)="","",VLOOKUP(C$2,行为概览!$D$3:$J$33,7,0)) -> 50 | D8: =IF(VLOOKUP(D$2,行为概览!$D$3:$J$33,7,0)="","",VLOOKUP(D$2,行为概览!$D$3:$J$33,7,0)) -> 3.3 | E8: =IF(VLOOKUP(E$2,行为概览!$D$3:$J$33,7,0)="","",VLOOKUP(E$2,行为概览!$D$3:$J$33,7,0)) -> 30 | F8: =IF(VLOOKUP(F$2,行为概览!$D$3:$J$33,7,0)="","",VLOOKUP(F$2,行为概览!$D$3:$J$33,7,0)) -> 15 | G8: =IF(VLOOKUP(G$2,行为概览!$D$3:$J$33,7,0)="","",VLOOKUP(G$2,行为概览!$D$3:$J$33,7,0)) | H8: =IF(VLOOKUP(H$2,行为概览!$D$3:$J$33,7,0)="","",VLOOKUP(H$2,行为概览!$D$3:$J$33,7,0)) | I8: =IF(VLOOKUP(I$2,行为概览!$D$3:$J$33,7,0)="","",VLOOKUP(I$2,行为概览!$D$3:$J$33,7,0)) | J8: =IF(VLOOKUP(J$2,行为概览!$D$3:$J$33,7,0)="","",VLOOKUP(J$2,行为概览!$D$3:$J$33,7,0)) | ... AE8: =IF(VLOOKUP(AE$2,行为概览!$D$3:$J$33,7,0)="","",VLOOKUP(AE$2,行为概览!$D$3:$J$33,7,0)) | AF8: =IF(C8="","",ROUND(C8*玩法行为规划!B8,2)) -> 0 | AG8: =IF(D8="","",ROUND(D8*玩法行为规划!C8,2)) -> 0 | AH8: =IF(E8="","",ROUND(E8*玩法行为规划!D8,2)) -> 0 | AI8: =IF(F8="","",ROUND(F8*玩法行为规划!E8,2)) -> 0 | AJ8: =IF(G8="","",ROUND(G8*玩法行为规划!F8,2)) | AK8: =IF(H8="","",ROUND(H8*玩法行为规划!G8,2)) | AL8: =IF(I8="","",ROUND(I8*玩法行为规划!H8,2)) | AM8: =IF(J8="","",ROUND(J8*玩法行为规划!I8,2)) | ... BH8: =IF(AE8="","",ROUND(AE8*玩法行为规划!AD8,2)) | BI8: =SUM(AF8:BF8) -> 52 | BJ8: =B8*BI8 -> 124800 | BK8: =ROUND(B8*(4+MAX(A8-30,0)*0.6),-2) -> 9600 | BM8: =BK8/BN8 -> 1 | BN8: =INT(BJ8*升级节奏!G8+BK8) -> 9600 | BO8: =ROUND(B8/90,0) -> 27
A9: 7 | B9: =升级节奏!C9 -> 2800 | C9: =IF(VLOOKUP(C$2,行为概览!$D$3:$J$33,7,0)="","",VLOOKUP(C$2,行为概览!$D$3:$J$33,7,0)) -> 50 | D9: =IF(VLOOKUP(D$2,行为概览!$D$3:$J$33,7,0)="","",VLOOKUP(D$2,行为概览!$D$3:$J$33,7,0)) -> 3.3 | E9: =IF(VLOOKUP(E$2,行为概览!$D$3:$J$33,7,0)="","",VLOOKUP(E$2,行为概览!$D$3:$J$33,7,0)) -> 30 | F9: =IF(VLOOKUP(F$2,行为概览!$D$3:$J$33,7,0)="","",VLOOKUP(F$2,行为概览!$D$3:$J$33,7,0)) -> 15 | G9: =IF(VLOOKUP(G$2,行为概览!$D$3:$J$33,7,0)="","",VLOOKUP(G$2,行为概览!$D$3:$J$33,7,0)) | H9: =IF(VLOOKUP(H$2,行为概览!$D$3:$J$33,7,0)="","",VLOOKUP(H$2,行为概览!$D$3:$J$33,7,0)) | I9: =IF(VLOOKUP(I$2,行为概览!$D$3:$J$33,7,0)="","",VLOOKUP(I$2,行为概览!$D$3:$J$33,7,0)) | J9: =IF(VLOOKUP(J$2,行为概览!$D$3:$J$33,7,0)="","",VLOOKUP(J$2,行为概览!$D$3:$J$33,7,0)) | ... AE9: =IF(VLOOKUP(AE$2,行为概览!$D$3:$J$33,7,0)="","",VLOOKUP(AE$2,行为概览!$D$3:$J$33,7,0)) | AF9: =IF(C9="","",ROUND(C9*玩法行为规划!B9,2)) -> 0 | AG9: =IF(D9="","",ROUND(D9*玩法行为规划!C9,2)) -> 0 | AH9: =IF(E9="","",ROUND(E9*玩法行为规划!D9,2)) -> 0 | AI9: =IF(F9="","",ROUND(F9*玩法行为规划!E9,2)) -> 0 | AJ9: =IF(G9="","",ROUND(G9*玩法行为规划!F9,2)) | AK9: =IF(H9="","",ROUND(H9*玩法行为规划!G9,2)) | AL9: =IF(I9="","",ROUND(I9*玩法行为规划!H9,2)) | AM9: =IF(J9="","",ROUND(J9*玩法行为规划!I9,2)) | ... BH9: =IF(AE9="","",ROUND(AE9*玩法行为规划!AD9,2)) | BI9: =SUM(AF9:BF9) -> 52 | BJ9: =B9*BI9 -> 145600 | BK9: =ROUND(B9*(4+MAX(A9-30,0)*0.6),-2) -> 11200 | BM9: =BK9/BN9 -> 1 | BN9: =INT(BJ9*升级节奏!G9+BK9) -> 11200 | BO9: =ROUND(B9/90,0) -> 31
A10: 8 | B10: =升级节奏!C10 -> 3200 | C10: =IF(VLOOKUP(C$2,行为概览!$D$3:$J$33,7,0)="","",VLOOKUP(C$2,行为概览!$D$3:$J$33,7,0)) -> 50 | D10: =IF(VLOOKUP(D$2,行为概览!$D$3:$J$33,7,0)="","",VLOOKUP(D$2,行为概览!$D$3:$J$33,7,0)) -> 3.3 | E10: =IF(VLOOKUP(E$2,行为概览!$D$3:$J$33,7,0)="","",VLOOKUP(E$2,行为概览!$D$3:$J$33,7,0)) -> 30 | F10: =IF(VLOOKUP(F$2,行为概览!$D$3:$J$33,7,0)="","",VLOOKUP(F$2,行为概览!$D$3:$J$33,7,0)) -> 15 | G10: =IF(VLOOKUP(G$2,行为概览!$D$3:$J$33,7,0)="","",VLOOKUP(G$2,行为概览!$D$3:$J$33,7,0)) | H10: =IF(VLOOKUP(H$2,行为概览!$D$3:$J$33,7,0)="","",VLOOKUP(H$2,行为概览!$D$3:$J$33,7,0)) | I10: =IF(VLOOKUP(I$2,行为概览!$D$3:$J$33,7,0)="","",VLOOKUP(I$2,行为概览!$D$3:$J$33,7,0)) | J10: =IF(VLOOKUP(J$2,行为概览!$D$3:$J$33,7,0)="","",VLOOKUP(J$2,行为概览!$D$3:$J$33,7,0)) | ... AE10: =IF(VLOOKUP(AE$2,行为概览!$D$3:$J$33,7,0)="","",VLOOKUP(AE$2,行为概览!$D$3:$J$33,7,0)) | AF10: =IF(C10="","",ROUND(C10*玩法行为规划!B10,2)) -> 0 | AG10: =IF(D10="","",ROUND(D10*玩法行为规划!C10,2)) -> 0 | AH10: =IF(E10="","",ROUND(E10*玩法行为规划!D10,2)) -> 0 | AI10: =IF(F10="","",ROUND(F10*玩法行为规划!E10,2)) -> 0 | AJ10: =IF(G10="","",ROUND(G10*玩法行为规划!F10,2)) | AK10: =IF(H10="","",ROUND(H10*玩法行为规划!G10,2)) | AL10: =IF(I10="","",ROUND(I10*玩法行为规划!H10,2)) | AM10: =IF(J10="","",ROUND(J10*玩法行为规划!I10,2)) | ... BH10: =IF(AE10="","",ROUND(AE10*玩法行为规划!AD10,2)) | BI10: =SUM(AF10:BF10) -> 52 | BJ10: =B10*BI10 -> 166400 | BK10: =ROUND(B10*(4+MAX(A10-30,0)*0.6),-2) -> 12800 | BM10: =BK10/BN10 -> 1 | BN10: =INT(BJ10*升级节奏!G10+BK10) -> 12800 | BO10: =ROUND(B10/90,0) -> 36
A11: 9 | B11: =升级节奏!C11 -> 3600 | C11: =IF(VLOOKUP(C$2,行为概览!$D$3:$J$33,7,0)="","",VLOOKUP(C$2,行为概览!$D$3:$J$33,7,0)) -> 50 | D11: =IF(VLOOKUP(D$2,行为概览!$D$3:$J$33,7,0)="","",VLOOKUP(D$2,行为概览!$D$3:$J$33,7,0)) -> 3.3 | E11: =IF(VLOOKUP(E$2,行为概览!$D$3:$J$33,7,0)="","",VLOOKUP(E$2,行为概览!$D$3:$J$33,7,0)) -> 30 | F11: =IF(VLOOKUP(F$2,行为概览!$D$3:$J$33,7,0)="","",VLOOKUP(F$2,行为概览!$D$3:$J$33,7,0)) -> 15 | G11: =IF(VLOOKUP(G$2,行为概览!$D$3:$J$33,7,0)="","",VLOOKUP(G$2,行为概览!$D$3:$J$33,7,0)) | H11: =IF(VLOOKUP(H$2,行为概览!$D$3:$J$33,7,0)="","",VLOOKUP(H$2,行为概览!$D$3:$J$33,7,0)) | I11: =IF(VLOOKUP(I$2,行为概览!$D$3:$J$33,7,0)="","",VLOOKUP(I$2,行为概览!$D$3:$J$33,7,0)) | J11: =IF(VLOOKUP(J$2,行为概览!$D$3:$J$33,7,0)="","",VLOOKUP(J$2,行为概览!$D$3:$J$33,7,0)) | ... AE11: =IF(VLOOKUP(AE$2,行为概览!$D$3:$J$33,7,0)="","",VLOOKUP(AE$2,行为概览!$D$3:$J$33,7,0)) | AF11: =IF(C11="","",ROUND(C11*玩法行为规划!B11,2)) -> 0 | AG11: =IF(D11="","",ROUND(D11*玩法行为规划!C11,2)) -> 0 | AH11: =IF(E11="","",ROUND(E11*玩法行为规划!D11,2)) -> 0 | AI11: =IF(F11="","",ROUND(F11*玩法行为规划!E11,2)) -> 0 | AJ11: =IF(G11="","",ROUND(G11*玩法行为规划!F11,2)) | AK11: =IF(H11="","",ROUND(H11*玩法行为规划!G11,2)) | AL11: =IF(I11="","",ROUND(I11*玩法行为规划!H11,2)) | AM11: =IF(J11="","",ROUND(J11*玩法行为规划!I11,2)) | ... BH11: =IF(AE11="","",ROUND(AE11*玩法行为规划!AD11,2)) | BI11: =SUM(AF11:BF11) -> 52 | BJ11: =B11*BI11 -> 187200 | BK11: =ROUND(B11*(4+MAX(A11-30,0)*0.6),-2) -> 14400 | BM11: =BK11/BN11 -> 1 | BN11: =INT(BJ11*升级节奏!G11+BK11) -> 14400 | BO11: =ROUND(B11/90,0) -> 40
A12: 10 | B12: =升级节奏!C12 -> 4000 | C12: =IF(VLOOKUP(C$2,行为概览!$D$3:$J$33,7,0)="","",VLOOKUP(C$2,行为概览!$D$3:$J$33,7,0)) -> 50 | D12: =IF(VLOOKUP(D$2,行为概览!$D$3:$J$33,7,0)="","",VLOOKUP(D$2,行为概览!$D$3:$J$33,7,0)) -> 3.3 | E12: =IF(VLOOKUP(E$2,行为概览!$D$3:$J$33,7,0)="","",VLOOKUP(E$2,行为概览!$D$3:$J$33,7,0)) -> 30 | F12: =IF(VLOOKUP(F$2,行为概览!$D$3:$J$33,7,0)="","",VLOOKUP(F$2,行为概览!$D$3:$J$33,7,0)) -> 15 | G12: =IF(VLOOKUP(G$2,行为概览!$D$3:$J$33,7,0)="","",VLOOKUP(G$2,行为概览!$D$3:$J$33,7,0)) | H12: =IF(VLOOKUP(H$2,行为概览!$D$3:$J$33,7,0)="","",VLOOKUP(H$2,行为概览!$D$3:$J$33,7,0)) | I12: =IF(VLOOKUP(I$2,行为概览!$D$3:$J$33,7,0)="","",VLOOKUP(I$2,行为概览!$D$3:$J$33,7,0)) | J12: =IF(VLOOKUP(J$2,行为概览!$D$3:$J$33,7,0)="","",VLOOKUP(J$2,行为概览!$D$3:$J$33,7,0)) | ... AE12: =IF(VLOOKUP(AE$2,行为概览!$D$3:$J$33,7,0)="","",VLOOKUP(AE$2,行为概览!$D$3:$J$33,7,0)) | AF12: =IF(C12="","",ROUND(C12*玩法行为规划!B12,2)) -> 0 | AG12: =IF(D12="","",ROUND(D12*玩法行为规划!C12,2)) -> 0 | AH12: =IF(E12="","",ROUND(E12*玩法行为规划!D12,2)) -> 0 | AI12: =IF(F12="","",ROUND(F12*玩法行为规划!E12,2)) -> 0 | AJ12: =IF(G12="","",ROUND(G12*玩法行为规划!F12,2)) | AK12: =IF(H12="","",ROUND(H12*玩法行为规划!G12,2)) | AL12: =IF(I12="","",ROUND(I12*玩法行为规划!H12,2)) | AM12: =IF(J12="","",ROUND(J12*玩法行为规划!I12,2)) | ... BH12: =IF(AE12="","",ROUND(AE12*玩法行为规划!AD12,2)) | BI12: =SUM(AF12:BF12) -> 64.83 | BJ12: =B12*BI12 -> 259320 | BK12: =ROUND(B12*(4+MAX(A12-30,0)*0.6),-2) -> 16000 | BL12: =IF(--RIGHT(A12,1)=0,SUM(BK12:BK21),"") -> 232000 | BM12: =BK12/BN12 -> 1 | BN12: =INT(BJ12*升级节奏!G12+BK12) -> 16000 | BO12: =ROUND(B12/90,0) -> 44
A13: 11 | B13: =升级节奏!C13 -> 4400 | C13: =IF(VLOOKUP(C$2,行为概览!$D$3:$J$33,7,0)="","",VLOOKUP(C$2,行为概览!$D$3:$J$33,7,0)) -> 50 | D13: =IF(VLOOKUP(D$2,行为概览!$D$3:$J$33,7,0)="","",VLOOKUP(D$2,行为概览!$D$3:$J$33,7,0)) -> 3.3 | E13: =IF(VLOOKUP(E$2,行为概览!$D$3:$J$33,7,0)="","",VLOOKUP(E$2,行为概览!$D$3:$J$33,7,0)) -> 30 | F13: =IF(VLOOKUP(F$2,行为概览!$D$3:$J$33,7,0)="","",VLOOKUP(F$2,行为概览!$D$3:$J$33,7,0)) -> 15 | G13: =IF(VLOOKUP(G$2,行为概览!$D$3:$J$33,7,0)="","",VLOOKUP(G$2,行为概览!$D$3:$J$33,7,0)) | H13: =IF(VLOOKUP(H$2,行为概览!$D$3:$J$33,7,0)="","",VLOOKUP(H$2,行为概览!$D$3:$J$33,7,0)) | I13: =IF(VLOOKUP(I$2,行为概览!$D$3:$J$33,7,0)="","",VLOOKUP(I$2,行为概览!$D$3:$J$33,7,0)) | J13: =IF(VLOOKUP(J$2,行为概览!$D$3:$J$33,7,0)="","",VLOOKUP(J$2,行为概览!$D$3:$J$33,7,0)) | ... AE13: =IF(VLOOKUP(AE$2,行为概览!$D$3:$J$33,7,0)="","",VLOOKUP(AE$2,行为概览!$D$3:$J$33,7,0)) | AF13: =IF(C13="","",ROUND(C13*玩法行为规划!B13,2)) -> 0 | AG13: =IF(D13="","",ROUND(D13*玩法行为规划!C13,2)) -> 0 | AH13: =IF(E13="","",ROUND(E13*玩法行为规划!D13,2)) -> 0 | AI13: =IF(F13="","",ROUND(F13*玩法行为规划!E13,2)) -> 0 | AJ13: =IF(G13="","",ROUND(G13*玩法行为规划!F13,2)) | AK13: =IF(H13="","",ROUND(H13*玩法行为规划!G13,2)) | AL13: =IF(I13="","",ROUND(I13*玩法行为规划!H13,2)) | AM13: =IF(J13="","",ROUND(J13*玩法行为规划!I13,2)) | ... BH13: =IF(AE13="","",ROUND(AE13*玩法行为规划!AD13,2)) | BI13: =SUM(AF13:BF13) -> 64.83 | BJ13: =B13*BI13 -> 285252 | BK13: =ROUND(B13*(4+MAX(A13-30,0)*0.6),-2) -> 17600 | BL13: =IF(--RIGHT(A13,1)=0,SUM(BK13:BK22),"") | BM13: =BK13/BN13 -> 1 | BN13: =INT(BJ13*升级节奏!G13+BK13) -> 17600 | BO13: =ROUND(B13/90,0) -> 49
A14: 12 | B14: =升级节奏!C14 -> 4800 | C14: =IF(VLOOKUP(C$2,行为概览!$D$3:$J$33,7,0)="","",VLOOKUP(C$2,行为概览!$D$3:$J$33,7,0)) -> 50 | D14: =IF(VLOOKUP(D$2,行为概览!$D$3:$J$33,7,0)="","",VLOOKUP(D$2,行为概览!$D$3:$J$33,7,0)) -> 3.3 | E14: =IF(VLOOKUP(E$2,行为概览!$D$3:$J$33,7,0)="","",VLOOKUP(E$2,行为概览!$D$3:$J$33,7,0)) -> 30 | F14: =IF(VLOOKUP(F$2,行为概览!$D$3:$J$33,7,0)="","",VLOOKUP(F$2,行为概览!$D$3:$J$33,7,0)) -> 15 | G14: =IF(VLOOKUP(G$2,行为概览!$D$3:$J$33,7,0)="","",VLOOKUP(G$2,行为概览!$D$3:$J$33,7,0)) | H14: =IF(VLOOKUP(H$2,行为概览!$D$3:$J$33,7,0)="","",VLOOKUP(H$2,行为概览!$D$3:$J$33,7,0)) | I14: =IF(VLOOKUP(I$2,行为概览!$D$3:$J$33,7,0)="","",VLOOKUP(I$2,行为概览!$D$3:$J$33,7,0)) | J14: =IF(VLOOKUP(J$2,行为概览!$D$3:$J$33,7,0)="","",VLOOKUP(J$2,行为概览!$D$3:$J$33,7,0)) | ... AE14: =IF(VLOOKUP(AE$2,行为概览!$D$3:$J$33,7,0)="","",VLOOKUP(AE$2,行为概览!$D$3:$J$33,7,0)) | AF14: =IF(C14="","",ROUND(C14*玩法行为规划!B14,2)) -> 0 | AG14: =IF(D14="","",ROUND(D14*玩法行为规划!C14,2)) -> 0 | AH14: =IF(E14="","",ROUND(E14*玩法行为规划!D14,2)) -> 0 | AI14: =IF(F14="","",ROUND(F14*玩法行为规划!E14,2)) -> 0 | AJ14: =IF(G14="","",ROUND(G14*玩法行为规划!F14,2)) | AK14: =IF(H14="","",ROUND(H14*玩法行为规划!G14,2)) | AL14: =IF(I14="","",ROUND(I14*玩法行为规划!H14,2)) | AM14: =IF(J14="","",ROUND(J14*玩法行为规划!I14,2)) | ... BH14: =IF(AE14="","",ROUND(AE14*玩法行为规划!AD14,2)) | BI14: =SUM(AF14:BF14) -> 64.83 | BJ14: =B14*BI14 -> 311184 | BK14: =ROUND(B14*(4+MAX(A14-30,0)*0.6),-2) -> 19200 | BL14: =IF(--RIGHT(A14,1)=0,SUM(BK14:BK23),"") | BM14: =BK14/BN14 -> 1 | BN14: =INT(BJ14*升级节奏!G14+BK14) -> 19200 | BO14: =ROUND(B14/90,0) -> 53
A15: 13 | B15: =升级节奏!C15 -> 5200 | C15: =IF(VLOOKUP(C$2,行为概览!$D$3:$J$33,7,0)="","",VLOOKUP(C$2,行为概览!$D$3:$J$33,7,0)) -> 50 | D15: =IF(VLOOKUP(D$2,行为概览!$D$3:$J$33,7,0)="","",VLOOKUP(D$2,行为概览!$D$3:$J$33,7,0)) -> 3.3 | E15: =IF(VLOOKUP(E$2,行为概览!$D$3:$J$33,7,0)="","",VLOOKUP(E$2,行为概览!$D$3:$J$33,7,0)) -> 30 | F15: =IF(VLOOKUP(F$2,行为概览!$D$3:$J$33,7,0)="","",VLOOKUP(F$2,行为概览!$D$3:$J$33,7,0)) -> 15 | G15: =IF(VLOOKUP(G$2,行为概览!$D$3:$J$33,7,0)="","",VLOOKUP(G$2,行为概览!$D$3:$J$33,7,0)) | H15: =IF(VLOOKUP(H$2,行为概览!$D$3:$J$33,7,0)="","",VLOOKUP(H$2,行为概览!$D$3:$J$33,7,0)) | I15: =IF(VLOOKUP(I$2,行为概览!$D$3:$J$33,7,0)="","",VLOOKUP(I$2,行为概览!$D$3:$J$33,7,0)) | J15: =IF(VLOOKUP(J$2,行为概览!$D$3:$J$33,7,0)="","",VLOOKUP(J$2,行为概览!$D$3:$J$33,7,0)) | ... AE15: =IF(VLOOKUP(AE$2,行为概览!$D$3:$J$33,7,0)="","",VLOOKUP(AE$2,行为概览!$D$3:$J$33,7,0)) | AF15: =IF(C15="","",ROUND(C15*玩法行为规划!B15,2)) -> 0 | AG15: =IF(D15="","",ROUND(D15*玩法行为规划!C15,2)) -> 0 | AH15: =IF(E15="","",ROUND(E15*玩法行为规划!D15,2)) -> 0 | AI15: =IF(F15="","",ROUND(F15*玩法行为规划!E15,2)) -> 0 | AJ15: =IF(G15="","",ROUND(G15*玩法行为规划!F15,2)) | AK15: =IF(H15="","",ROUND(H15*玩法行为规划!G15,2)) | AL15: =IF(I15="","",ROUND(I15*玩法行为规划!H15,2)) | AM15: =IF(J15="","",ROUND(J15*玩法行为规划!I15,2)) | ... BH15: =IF(AE15="","",ROUND(AE15*玩法行为规划!AD15,2)) | BI15: =SUM(AF15:BF15) -> 64.83 | BJ15: =B15*BI15 -> 337116 | BK15: =ROUND(B15*(4+MAX(A15-30,0)*0.6),-2) -> 20800 | BL15: =IF(--RIGHT(A15,1)=0,SUM(BK15:BK24),"") | BM15: =BK15/BN15 -> 1 | BN15: =INT(BJ15*升级节奏!G15+BK15) -> 20800 | BO15: =ROUND(B15/90,0) -> 58
A16: 14 | B16: =升级节奏!C16 -> 5600 | C16: =IF(VLOOKUP(C$2,行为概览!$D$3:$J$33,7,0)="","",VLOOKUP(C$2,行为概览!$D$3:$J$33,7,0)) -> 50 | D16: =IF(VLOOKUP(D$2,行为概览!$D$3:$J$33,7,0)="","",VLOOKUP(D$2,行为概览!$D$3:$J$33,7,0)) -> 3.3 | E16: =IF(VLOOKUP(E$2,行为概览!$D$3:$J$33,7,0)="","",VLOOKUP(E$2,行为概览!$D$3:$J$33,7,0)) -> 30 | F16: =IF(VLOOKUP(F$2,行为概览!$D$3:$J$33,7,0)="","",VLOOKUP(F$2,行为概览!$D$3:$J$33,7,0)) -> 15 | G16: =IF(VLOOKUP(G$2,行为概览!$D$3:$J$33,7,0)="","",VLOOKUP(G$2,行为概览!$D$3:$J$33,7,0)) | H16: =IF(VLOOKUP(H$2,行为概览!$D$3:$J$33,7,0)="","",VLOOKUP(H$2,行为概览!$D$3:$J$33,7,0)) | I16: =IF(VLOOKUP(I$2,行为概览!$D$3:$J$33,7,0)="","",VLOOKUP(I$2,行为概览!$D$3:$J$33,7,0)) | J16: =IF(VLOOKUP(J$2,行为概览!$D$3:$J$33,7,0)="","",VLOOKUP(J$2,行为概览!$D$3:$J$33,7,0)) | ... AE16: =IF(VLOOKUP(AE$2,行为概览!$D$3:$J$33,7,0)="","",VLOOKUP(AE$2,行为概览!$D$3:$J$33,7,0)) | AF16: =IF(C16="","",ROUND(C16*玩法行为规划!B16,2)) -> 0 | AG16: =IF(D16="","",ROUND(D16*玩法行为规划!C16,2)) -> 0 | AH16: =IF(E16="","",ROUND(E16*玩法行为规划!D16,2)) -> 0 | AI16: =IF(F16="","",ROUND(F16*玩法行为规划!E16,2)) -> 0 | AJ16: =IF(G16="","",ROUND(G16*玩法行为规划!F16,2)) | AK16: =IF(H16="","",ROUND(H16*玩法行为规划!G16,2)) | AL16: =IF(I16="","",ROUND(I16*玩法行为规划!H16,2)) | AM16: =IF(J16="","",ROUND(J16*玩法行为规划!I16,2)) | ... BH16: =IF(AE16="","",ROUND(AE16*玩法行为规划!AD16,2)) | BI16: =SUM(AF16:BF16) -> 64.83 | BJ16: =B16*BI16 -> 363048 | BK16: =ROUND(B16*(4+MAX(A16-30,0)*0.6),-2) -> 22400 | BL16: =IF(--RIGHT(A16,1)=0,SUM(BK16:BK25),"") | BM16: =BK16/BN16 -> 1 | BN16: =INT(BJ16*升级节奏!G16+BK16) -> 22400 | BO16: =ROUND(B16/90,0) -> 62
A17: 15 | B17: =升级节奏!C17 -> 6000 | C17: =IF(VLOOKUP(C$2,行为概览!$D$3:$J$33,7,0)="","",VLOOKUP(C$2,行为概览!$D$3:$J$33,7,0)) -> 50 | D17: =IF(VLOOKUP(D$2,行为概览!$D$3:$J$33,7,0)="","",VLOOKUP(D$2,行为概览!$D$3:$J$33,7,0)) -> 3.3 | E17: =IF(VLOOKUP(E$2,行为概览!$D$3:$J$33,7,0)="","",VLOOKUP(E$2,行为概览!$D$3:$J$33,7,0)) -> 30 | F17: =IF(VLOOKUP(F$2,行为概览!$D$3:$J$33,7,0)="","",VLOOKUP(F$2,行为概览!$D$3:$J$33,7,0)) -> 15 | G17: =IF(VLOOKUP(G$2,行为概览!$D$3:$J$33,7,0)="","",VLOOKUP(G$2,行为概览!$D$3:$J$33,7,0)) | H17: =IF(VLOOKUP(H$2,行为概览!$D$3:$J$33,7,0)="","",VLOOKUP(H$2,行为概览!$D$3:$J$33,7,0)) | I17: =IF(VLOOKUP(I$2,行为概览!$D$3:$J$33,7,0)="","",VLOOKUP(I$2,行为概览!$D$3:$J$33,7,0)) | J17: =IF(VLOOKUP(J$2,行为概览!$D$3:$J$33,7,0)="","",VLOOKUP(J$2,行为概览!$D$3:$J$33,7,0)) | ... AE17: =IF(VLOOKUP(AE$2,行为概览!$D$3:$J$33,7,0)="","",VLOOKUP(AE$2,行为概览!$D$3:$J$33,7,0)) | AF17: =IF(C17="","",ROUND(C17*玩法行为规划!B17,2)) -> 16.67 | AG17: =IF(D17="","",ROUND(D17*玩法行为规划!C17,2)) -> 0 | AH17: =IF(E17="","",ROUND(E17*玩法行为规划!D17,2)) -> 0 | AI17: =IF(F17="","",ROUND(F17*玩法行为规划!E17,2)) -> 0 | AJ17: =IF(G17="","",ROUND(G17*玩法行为规划!F17,2)) | AK17: =IF(H17="","",ROUND(H17*玩法行为规划!G17,2)) | AL17: =IF(I17="","",ROUND(I17*玩法行为规划!H17,2)) | AM17: =IF(J17="","",ROUND(J17*玩法行为规划!I17,2)) | ... BH17: =IF(AE17="","",ROUND(AE17*玩法行为规划!AD17,2)) | BI17: =SUM(AF17:BF17) -> 81.5 | BJ17: =B17*BI17 -> 489000 | BK17: =ROUND(B17*(4+MAX(A17-30,0)*0.6),-2) -> 24000 | BL17: =IF(--RIGHT(A17,1)=0,SUM(BK17:BK26),"") | BM17: =BK17/BN17 -> 1 | BN17: =INT(BJ17*升级节奏!G17+BK17) -> 24000 | BO17: =ROUND(B17/90,0) -> 67
A18: 16 | B18: =升级节奏!C18 -> 6400 | C18: =IF(VLOOKUP(C$2,行为概览!$D$3:$J$33,7,0)="","",VLOOKUP(C$2,行为概览!$D$3:$J$33,7,0)) -> 50 | D18: =IF(VLOOKUP(D$2,行为概览!$D$3:$J$33,7,0)="","",VLOOKUP(D$2,行为概览!$D$3:$J$33,7,0)) -> 3.3 | E18: =IF(VLOOKUP(E$2,行为概览!$D$3:$J$33,7,0)="","",VLOOKUP(E$2,行为概览!$D$3:$J$33,7,0)) -> 30 | F18: =IF(VLOOKUP(F$2,行为概览!$D$3:$J$33,7,0)="","",VLOOKUP(F$2,行为概览!$D$3:$J$33,7,0)) -> 15 | G18: =IF(VLOOKUP(G$2,行为概览!$D$3:$J$33,7,0)="","",VLOOKUP(G$2,行为概览!$D$3:$J$33,7,0)) | H18: =IF(VLOOKUP(H$2,行为概览!$D$3:$J$33,7,0)="","",VLOOKUP(H$2,行为概览!$D$3:$J$33,7,0)) | I18: =IF(VLOOKUP(I$2,行为概览!$D$3:$J$33,7,0)="","",VLOOKUP(I$2,行为概览!$D$3:$J$33,7,0)) | J18: =IF(VLOOKUP(J$2,行为概览!$D$3:$J$33,7,0)="","",VLOOKUP(J$2,行为概览!$D$3:$J$33,7,0)) | ... AE18: =IF(VLOOKUP(AE$2,行为概览!$D$3:$J$33,7,0)="","",VLOOKUP(AE$2,行为概览!$D$3:$J$33,7,0)) | AF18: =IF(C18="","",ROUND(C18*玩法行为规划!B18,2)) -> 16.67 | AG18: =IF(D18="","",ROUND(D18*玩法行为规划!C18,2)) -> 0 | AH18: =IF(E18="","",ROUND(E18*玩法行为规划!D18,2)) -> 0 | AI18: =IF(F18="","",ROUND(F18*玩法行为规划!E18,2)) -> 0 | AJ18: =IF(G18="","",ROUND(G18*玩法行为规划!F18,2)) | AK18: =IF(H18="","",ROUND(H18*玩法行为规划!G18,2)) | AL18: =IF(I18="","",ROUND(I18*玩法行为规划!H18,2)) | AM18: =IF(J18="","",ROUND(J18*玩法行为规划!I18,2)) | ... BH18: =IF(AE18="","",ROUND(AE18*玩法行为规划!AD18,2)) | BI18: =SUM(AF18:BF18) -> 81.5 | BJ18: =B18*BI18 -> 521600 | BK18: =ROUND(B18*(4+MAX(A18-30,0)*0.6),-2) -> 25600 | BL18: =IF(--RIGHT(A18,1)=0,SUM(BK18:BK27),"") | BM18: =BK18/BN18 -> 1 | BN18: =INT(BJ18*升级节奏!G18+BK18) -> 25600 | BO18: =ROUND(B18/90,0) -> 71
A19: 17 | B19: =升级节奏!C19 -> 6800 | C19: =IF(VLOOKUP(C$2,行为概览!$D$3:$J$33,7,0)="","",VLOOKUP(C$2,行为概览!$D$3:$J$33,7,0)) -> 50 | D19: =IF(VLOOKUP(D$2,行为概览!$D$3:$J$33,7,0)="","",VLOOKUP(D$2,行为概览!$D$3:$J$33,7,0)) -> 3.3 | E19: =IF(VLOOKUP(E$2,行为概览!$D$3:$J$33,7,0)="","",VLOOKUP(E$2,行为概览!$D$3:$J$33,7,0)) -> 30 | F19: =IF(VLOOKUP(F$2,行为概览!$D$3:$J$33,7,0)="","",VLOOKUP(F$2,行为概览!$D$3:$J$33,7,0)) -> 15 | G19: =IF(VLOOKUP(G$2,行为概览!$D$3:$J$33,7,0)="","",VLOOKUP(G$2,行为概览!$D$3:$J$33,7,0)) | H19: =IF(VLOOKUP(H$2,行为概览!$D$3:$J$33,7,0)="","",VLOOKUP(H$2,行为概览!$D$3:$J$33,7,0)) | I19: =IF(VLOOKUP(I$2,行为概览!$D$3:$J$33,7,0)="","",VLOOKUP(I$2,行为概览!$D$3:$J$33,7,0)) | J19: =IF(VLOOKUP(J$2,行为概览!$D$3:$J$33,7,0)="","",VLOOKUP(J$2,行为概览!$D$3:$J$33,7,0)) | ... AE19: =IF(VLOOKUP(AE$2,行为概览!$D$3:$J$33,7,0)="","",VLOOKUP(AE$2,行为概览!$D$3:$J$33,7,0)) | AF19: =IF(C19="","",ROUND(C19*玩法行为规划!B19,2)) -> 16.67 | AG19: =IF(D19="","",ROUND(D19*玩法行为规划!C19,2)) -> 0 | AH19: =IF(E19="","",ROUND(E19*玩法行为规划!D19,2)) -> 0 | AI19: =IF(F19="","",ROUND(F19*玩法行为规划!E19,2)) -> 0 | AJ19: =IF(G19="","",ROUND(G19*玩法行为规划!F19,2)) | AK19: =IF(H19="","",ROUND(H19*玩法行为规划!G19,2)) | AL19: =IF(I19="","",ROUND(I19*玩法行为规划!H19,2)) | AM19: =IF(J19="","",ROUND(J19*玩法行为规划!I19,2)) | ... BH19: =IF(AE19="","",ROUND(AE19*玩法行为规划!AD19,2)) | BI19: =SUM(AF19:BF19) -> 81.5 | BJ19: =B19*BI19 -> 554200 | BK19: =ROUND(B19*(4+MAX(A19-30,0)*0.6),-2) -> 27200 | BL19: =IF(--RIGHT(A19,1)=0,SUM(BK19:BK28),"") | BM19: =BK19/BN19 -> 1 | BN19: =INT(BJ19*升级节奏!G19+BK19) -> 27200 | BO19: =ROUND(B19/90,0) -> 76
A20: 18 | B20: =升级节奏!C20 -> 7200 | C20: =IF(VLOOKUP(C$2,行为概览!$D$3:$J$33,7,0)="","",VLOOKUP(C$2,行为概览!$D$3:$J$33,7,0)) -> 50 | D20: =IF(VLOOKUP(D$2,行为概览!$D$3:$J$33,7,0)="","",VLOOKUP(D$2,行为概览!$D$3:$J$33,7,0)) -> 3.3 | E20: =IF(VLOOKUP(E$2,行为概览!$D$3:$J$33,7,0)="","",VLOOKUP(E$2,行为概览!$D$3:$J$33,7,0)) -> 30 | F20: =IF(VLOOKUP(F$2,行为概览!$D$3:$J$33,7,0)="","",VLOOKUP(F$2,行为概览!$D$3:$J$33,7,0)) -> 15 | G20: =IF(VLOOKUP(G$2,行为概览!$D$3:$J$33,7,0)="","",VLOOKUP(G$2,行为概览!$D$3:$J$33,7,0)) | H20: =IF(VLOOKUP(H$2,行为概览!$D$3:$J$33,7,0)="","",VLOOKUP(H$2,行为概览!$D$3:$J$33,7,0)) | I20: =IF(VLOOKUP(I$2,行为概览!$D$3:$J$33,7,0)="","",VLOOKUP(I$2,行为概览!$D$3:$J$33,7,0)) | J20: =IF(VLOOKUP(J$2,行为概览!$D$3:$J$33,7,0)="","",VLOOKUP(J$2,行为概览!$D$3:$J$33,7,0)) | ... AE20: =IF(VLOOKUP(AE$2,行为概览!$D$3:$J$33,7,0)="","",VLOOKUP(AE$2,行为概览!$D$3:$J$33,7,0)) | AF20: =IF(C20="","",ROUND(C20*玩法行为规划!B20,2)) -> 16.67 | AG20: =IF(D20="","",ROUND(D20*玩法行为规划!C20,2)) -> 0 | AH20: =IF(E20="","",ROUND(E20*玩法行为规划!D20,2)) -> 0 | AI20: =IF(F20="","",ROUND(F20*玩法行为规划!E20,2)) -> 0 | AJ20: =IF(G20="","",ROUND(G20*玩法行为规划!F20,2)) | AK20: =IF(H20="","",ROUND(H20*玩法行为规划!G20,2)) | AL20: =IF(I20="","",ROUND(I20*玩法行为规划!H20,2)) | AM20: =IF(J20="","",ROUND(J20*玩法行为规划!I20,2)) | ... BH20: =IF(AE20="","",ROUND(AE20*玩法行为规划!AD20,2)) | BI20: =SUM(AF20:BF20) -> 81.5 | BJ20: =B20*BI20 -> 586800 | BK20: =ROUND(B20*(4+MAX(A20-30,0)*0.6),-2) -> 28800 | BL20: =IF(--RIGHT(A20,1)=0,SUM(BK20:BK29),"") | BM20: =BK20/BN20 -> 1 | BN20: =INT(BJ20*升级节奏!G20+BK20) -> 28800 | BO20: =ROUND(B20/90,0) -> 80
