Workbook

Sheet 任务经验
A1: ID | B1: 是否战斗 | C1: 战斗备注 | D1: ExpReward | E1: MoneyReward | F1: PetExpReward | G1: 宠物当前等级 | H1: 任务限制等级 | I1: 当前角色经验 | J1: 当前角色等级 | K1: 当前经验 | M1: 权重 | N1: 系数 | Q1: 等级段 | R1: 经验分配 | S1: 宠物经验 | T1: 银币 | U1: 实际经验 | V1: 任务数量 | W1: 总权重 | X1: 单份经验 | Y1: 单份宠物经验 | Z1: 单份银币 | AA1: 等级 | AB1: 任务数
A2: 180101 | B2: =(--INDEX(任务列表!A:B,MATCH(A2,任务列表!A:A,0),2)) -> 0 | D2: 350 | E2: 500 | F2: 0 | I2: =SUM($D$2:D2) -> 350 | J2: =INDEX(人物升级经验表!A:A,MATCH(任务经验!I2,人物升级经验表!C:C,1)+1,1) -> 1 | K2: =I2-INDEX(人物升级经验表!C:C,MATCH(任务经验!I2,人物升级经验表!C:C,1),1) -> 350 | M2: =IF((--B2)=0,1,IF((--B2)=-1,0,2)) -> 1 | Q2: 0 | R2: 72000 | S2: 48180 | T2: 45000 | U2: =SUM(D2:D35) -> 87100 | V2: =COUNTA(A2:A35) -> 34 | W2: =SUM(M2:M35) -> 39 | X2: =ROUND(R2/$W2,-2) -> 1800 | Y2: =ROUND(S2/$W2,-2) -> 1200 | Z2: =ROUND(T2/$W2,-2) -> 1200 | AA2: 1 | AB2: =COUNTIFS(J:J,AA2) -> 2
A3: 180103 | B3: =(--INDEX(任务列表!A:B,MATCH(A3,任务列表!A:A,0),2)) -> 0 | D3: 500 | E3: 500 | F3: 0 | I3: =SUM($D$2:D3) -> 850 | J3: =INDEX(人物升级经验表!A:A,MATCH(任务经验!I3,人物升级经验表!C:C,1)+1,1) -> 1 | K3: =I3-INDEX(人物升级经验表!C:C,MATCH(任务经验!I3,人物升级经验表!C:C,1),1) -> 850 | M3: =IF((--B2)=0,1,IF((--B2)=-1,0,2)) -> 1 | Q3: 10 | R3: 232000 | S3: 194450 | T3: 145000 | U3: =SUM(D36:D86) -> 206250 | V3: =COUNTA(A36:A86) -> 51 | W3: =SUM(M36:M86) -> 57 | X3: =ROUND(R3/$W3,-2) -> 4100 | Y3: =ROUND(S3/$W3,-2) -> 3400 | Z3: =ROUND(T3/$W3,-2) -> 2500 | AA3: 2 | AB3: =COUNTIFS(J:J,AA3) -> 3
A4: 180102 | B4: =(--INDEX(任务列表!A:B,MATCH(A4,任务列表!A:A,0),2)) -> 0 | D4: 950 | E4: 660 | F4: 0 | I4: =SUM($D$2:D4) -> 1800 | J4: =INDEX(人物升级经验表!A:A,MATCH(任务经验!I4,人物升级经验表!C:C,1)+1,1) -> 2 | K4: =I4-INDEX(人物升级经验表!C:C,MATCH(任务经验!I4,人物升级经验表!C:C,1),1) -> 200 | M4: =IF((--B4)=0,1,IF((--B4)=-1,0,2)) -> 1 | Q4: 20 | R4: 392000 | S4: 439450 | T4: 245000 | U4: =SUM(D87:D143) -> 394140 | V4: =COUNTA(A87:A143) -> 57 | W4: =SUM(M87:M143) -> 67 | X4: =ROUND(R4/$W4,-2) -> 5900 | Y4: =ROUND(S4/$W4,-2) -> 6600 | Z4: =ROUND(T4/$W4,-2) -> 3700 | AA4: 3 | AB4: =COUNTIFS(J:J,AA4) -> 3
A5: 180104 | B5: =(--INDEX(任务列表!A:B,MATCH(A5,任务列表!A:A,0),2)) -> 0 | D5: 950 | E5: 660 | F5: 0 | I5: =SUM($D$2:D5) -> 2750 | J5: =INDEX(人物升级经验表!A:A,MATCH(任务经验!I5,人物升级经验表!C:C,1)+1,1) -> 2 | K5: =I5-INDEX(人物升级经验表!C:C,MATCH(任务经验!I5,人物升级经验表!C:C,1),1) -> 1150 | M5: =IF((--B5)=0,1,IF((--B5)=-1,0,2)) -> 1 | Q5: 30 | R5: 944400 | S5: 1223900 | T5: 345000 | U5: =SUM(D144:D200) -> 928740 | V5: =COUNTA(A144:A200) -> 57 | W5: =SUM(M144:M200) -> 64 | X5: =ROUND(R5/$W5,-2) -> 14800 | Y5: =ROUND(S5/$W5,-2) -> 19100 | Z5: =ROUND(T5/$W5,-2) -> 5400 | AA5: 4 | AB5: =COUNTIFS(J:J,AA5) -> 3
A6: 180105 | B6: =(--INDEX(任务列表!A:B,MATCH(A6,任务列表!A:A,0),2)) -> 0 | D6: 1000 | E6: 660 | F6: 0 | I6: =SUM($D$2:D6) -> 3750 | J6: =INDEX(人物升级经验表!A:A,MATCH(任务经验!I6,人物升级经验表!C:C,1)+1,1) -> 2 | K6: =I6-INDEX(人物升级经验表!C:C,MATCH(任务经验!I6,人物升级经验表!C:C,1),1) -> 2150 | M6: =IF((--B6)=0,1,IF((--B6)=-1,0,2)) -> 1 | Q6: 40 | R6: 2280400 | S6: 2013900 | T6: 653500 | U6: =SUM(D201:D259) -> 2737100 | V6: =COUNTA(A201:A259) -> 59 | W6: =SUM(M201:M259) -> 70 | X6: =ROUND(R6/$W6,-2) -> 32600 | Y6: =ROUND(S6/$W6,-2) -> 28800 | Z6: =ROUND(T6/$W6,-2) -> 9300 | AA6: 5 | AB6: =COUNTIFS(J:J,AA6) -> 3
A7: 180130 | B7: =(--INDEX(任务列表!A:B,MATCH(A7,任务列表!A:A,0),2)) -> 0 | D7: 1500 | E7: 1000 | F7: 0 | I7: =SUM($D$2:D7) -> 5250 | J7: =INDEX(人物升级经验表!A:A,MATCH(任务经验!I7,人物升级经验表!C:C,1)+1,1) -> 3 | K7: =I7-INDEX(人物升级经验表!C:C,MATCH(任务经验!I7,人物升级经验表!C:C,1),1) -> 450 | M7: =IF((--B7)=0,1,IF((--B7)=-1,0,2)) -> 1 | Q7: 50 | R7: 3878400 | S7: 3003900 | T7: 2233500 | W7: 65 | X7: =ROUND(R7/$W7,-2) -> 59700 | Y7: =ROUND(S7/$W7,-2) -> 46200 | Z7: =ROUND(T7/$W7,-2) -> 34400 | AA7: 6 | AB7: =COUNTIFS(J:J,AA7) -> 4
A8: 180131 | B8: =(--INDEX(任务列表!A:B,MATCH(A8,任务列表!A:A,0),2)) -> 0 | D8: 1500 | E8: 1000 | F8: 0 | I8: =SUM($D$2:D8) -> 6750 | J8: =INDEX(人物升级经验表!A:A,MATCH(任务经验!I8,人物升级经验表!C:C,1)+1,1) -> 3 | K8: =I8-INDEX(人物升级经验表!C:C,MATCH(任务经验!I8,人物升级经验表!C:C,1),1) -> 1950 | M8: =IF((--B8)=0,1,IF((--B8)=-1,0,2)) -> 1 | Q8: 60 | R8: 10224000 | S8: 4193900 | T8: 3323500 | W8: 65 | X8: =ROUND(R8/$W8,-2) -> 157300 | Y8: =ROUND(S8/$W8,-2) -> 64500 | Z8: =ROUND(T8/$W8,-2) -> 51100 | AA8: 7 | AB8: =COUNTIFS(J:J,AA8) -> 4
A9: 180132 | B9: =(--INDEX(任务列表!A:B,MATCH(A9,任务列表!A:A,0),2)) -> 0 | D9: 1500 | E9: 1000 | F9: 0 | I9: =SUM($D$2:D9) -> 8250 | J9: =INDEX(人物升级经验表!A:A,MATCH(任务经验!I9,人物升级经验表!C:C,1)+1,1) -> 3 | K9: =I9-INDEX(人物升级经验表!C:C,MATCH(任务经验!I9,人物升级经验表!C:C,1),1) -> 3450 | M9: =IF((--B9)=0,1,IF((--B9)=-1,0,2)) -> 1 | Q9: 70 | R9: 16411400 | S9: 5583900 | T9: 4613500 | W9: 65 | X9: =ROUND(R9/$W9,-2) -> 252500 | Y9: =ROUND(S9/$W9,-2) -> 85900 | Z9: =ROUND(T9/$W9,-2) -> 71000 | AA9: 8 | AB9: =COUNTIFS(J:J,AA9) -> 3
A10: 180133 | B10: =(--INDEX(任务列表!A:B,MATCH(A10,任务列表!A:A,0),2)) -> 0 | D10: 1600 | E10: 1330 | F10: 0 | G10: =VLOOKUP(VLOOKUP($J$10+4-1,宠物升级表!$A:$C,3,FALSE)+SUM($F$10:F10),宠物升级表!C:D,2,TRUE)+1 -> 8 | I10: =SUM($D$2:D10) -> 9850 | J10: =INDEX(人物升级经验表!A:A,MATCH(任务经验!I10,人物升级经验表!C:C,1)+1,1) -> 4 | K10: =I10-INDEX(人物升级经验表!C:C,MATCH(任务经验!I10,人物升级经验表!C:C,1),1) -> 250 | M10: =IF((--B10)=0,1,IF((--B10)=-1,0,2)) -> 1 | O10: =IF((G10-J10)>4,1,"") | AA10: 9 | AB10: =COUNTIFS(J:J,AA10) -> 4
A11: 180134 | B11: =(--INDEX(任务列表!A:B,MATCH(A11,任务列表!A:A,0),2)) -> 8502 | C11: 暗夜男 | D11: 3200 | E11: 1330 | F11: 1350 | G11: =VLOOKUP(VLOOKUP($J$10+4-1,宠物升级表!$A:$C,3,FALSE)+SUM($F$10:F11),宠物升级表!C:D,2,TRUE)+1 -> 8 | I11: =SUM($D$2:D11) -> 13050 | J11: =INDEX(人物升级经验表!A:A,MATCH(任务经验!I11,人物升级经验表!C:C,1)+1,1) -> 4 | K11: =I11-INDEX(人物升级经验表!C:C,MATCH(任务经验!I11,人物升级经验表!C:C,1),1) -> 3450 | L11: `+200 | M11: =IF((--B11)=0,1,IF((--B11)=-1,0,2)) -> 2 | O11: =IF((G11-J11)>4,1,"") | AA11: 10 | AB11: =COUNTIFS(J:J,AA11) -> 5
A12: 180135 | B12: =(--INDEX(任务列表!A:B,MATCH(A12,任务列表!A:A,0),2)) -> 0 | D12: 1600 | E12: 1330 | F12: 1350 | G12: =VLOOKUP(VLOOKUP($J$10+4-1,宠物升级表!$A:$C,3,FALSE)+SUM($F$10:F12),宠物升级表!C:D,2,TRUE)+1 -> 8 | I12: =SUM($D$2:D12) -> 14650 | J12: =INDEX(人物升级经验表!A:A,MATCH(任务经验!I12,人物升级经验表!C:C,1)+1,1) -> 4 | K12: =I12-INDEX(人物升级经验表!C:C,MATCH(任务经验!I12,人物升级经验表!C:C,1),1) -> 5050 | M12: =IF((--B12)=0,1,IF((--B12)=-1,0,2)) -> 1 | O12: =IF((G12-J12)>4,1,"") | AA12: 11 | AB12: =COUNTIFS(J:J,AA12) -> 5
A13: 180136 | B13: =(--INDEX(任务列表!A:B,MATCH(A13,任务列表!A:A,0),2)) -> 0 | D13: 2200 | E13: 1660 | F13: 1660 | G13: =VLOOKUP(VLOOKUP($J$10+4-1,宠物升级表!$A:$C,3,FALSE)+SUM($F$10:F13),宠物升级表!C:D,2,TRUE)+1 -> 9 | I13: =SUM($D$2:D13) -> 16850 | J13: =INDEX(人物升级经验表!A:A,MATCH(任务经验!I13,人物升级经验表!C:C,1)+1,1) -> 5 | K13: =I13-INDEX(人物升级经验表!C:C,MATCH(任务经验!I13,人物升级经验表!C:C,1),1) -> 850 | M13: =IF((--B12)=0,1,IF((--B12)=-1,0,2)) -> 1 | O13: =IF((G13-J13)>4,1,"") | AA13: 12 | AB13: =COUNTIFS(J:J,AA13) -> 6
A14: 180137 | B14: =(--INDEX(任务列表!A:B,MATCH(A14,任务列表!A:A,0),2)) -> 0 | D14: 2200 | E14: 1660 | F14: 1660 | G14: =VLOOKUP(VLOOKUP($J$10+4-1,宠物升级表!$A:$C,3,FALSE)+SUM($F$10:F14),宠物升级表!C:D,2,TRUE)+1 -> 9 | I14: =SUM($D$2:D14) -> 19050 | J14: =INDEX(人物升级经验表!A:A,MATCH(任务经验!I14,人物升级经验表!C:C,1)+1,1) -> 5 | K14: =I14-INDEX(人物升级经验表!C:C,MATCH(任务经验!I14,人物升级经验表!C:C,1),1) -> 3050 | M14: =IF((--B14)=0,1,IF((--B14)=-1,0,2)) -> 1 | O14: =IF((G14-J14)>4,1,"") | AA14: 13 | AB14: =COUNTIFS(J:J,AA14) -> 6
A15: 189901 | B15: =(--INDEX(任务列表!A:B,MATCH(A15,任务列表!A:A,0),2)) -> 0 | D15: 2400 | E15: 1660 | F15: 1660 | G15: =VLOOKUP(VLOOKUP($J$10+4-1,宠物升级表!$A:$C,3,FALSE)+SUM($F$10:F15),宠物升级表!C:D,2,TRUE)+1 -> 10 | I15: =SUM($D$2:D15) -> 21450 | J15: =INDEX(人物升级经验表!A:A,MATCH(任务经验!I15,人物升级经验表!C:C,1)+1,1) -> 5 | K15: =I15-INDEX(人物升级经验表!C:C,MATCH(任务经验!I15,人物升级经验表!C:C,1),1) -> 5450 | M15: =IF((--B15)=0,1,IF((--B15)=-1,0,2)) -> 1 | O15: =IF((G15-J15)>4,1,"") -> 1 | AA15: 14 | AB15: =COUNTIFS(J:J,AA15) -> 6
A16: 180138 | B16: =(--INDEX(任务列表!A:B,MATCH(A16,任务列表!A:A,0),2)) -> 8503 | C16: 天灾爪牙 | D16: 4800 | E16: 1500 | F16: 1500 | G16: =VLOOKUP(VLOOKUP($J$10+4-1,宠物升级表!$A:$C,3,FALSE)+SUM($F$10:F16),宠物升级表!C:D,2,TRUE)+1 -> 10 | I16: =SUM($D$2:D16) -> 26250 | J16: =INDEX(人物升级经验表!A:A,MATCH(任务经验!I16,人物升级经验表!C:C,1)+1,1) -> 6 | K16: =I16-INDEX(人物升级经验表!C:C,MATCH(任务经验!I16,人物升级经验表!C:C,1),1) -> 2250 | M16: =IF((--B16)=0,1,IF((--B16)=-1,0,2)) -> 2 | O16: =IF((G16-J16)>4,1,"") | AA16: 15 | AB16: =COUNTIFS(J:J,AA16) -> 5
A17: 180139 | B17: =(--INDEX(任务列表!A:B,MATCH(A17,任务列表!A:A,0),2)) -> 0 | D17: 2400 | E17: 1500 | F17: 1500 | G17: =VLOOKUP(VLOOKUP($J$10+4-1,宠物升级表!$A:$C,3,FALSE)+SUM($F$10:F17),宠物升级表!C:D,2,TRUE)+1 -> 10 | I17: =SUM($D$2:D17) -> 28650 | J17: =INDEX(人物升级经验表!A:A,MATCH(任务经验!I17,人物升级经验表!C:C,1)+1,1) -> 6 | K17: =I17-INDEX(人物升级经验表!C:C,MATCH(任务经验!I17,人物升级经验表!C:C,1),1) -> 4650 | M17: =IF((--B17)=0,1,IF((--B17)=-1,0,2)) -> 1 | O17: =IF((G17-J17)>4,1,"") | AA17: 16 | AB17: =COUNTIFS(J:J,AA17) -> 5
A18: 180140 | B18: =(--INDEX(任务列表!A:B,MATCH(A18,任务列表!A:A,0),2)) -> 0 | D18: 2400 | E18: 1500 | F18: 1500 | G18: =VLOOKUP(VLOOKUP($J$10+4-1,宠物升级表!$A:$C,3,FALSE)+SUM($F$10:F18),宠物升级表!C:D,2,TRUE)+1 -> 10 | I18: =SUM($D$2:D18) -> 31050 | J18: =INDEX(人物升级经验表!A:A,MATCH(任务经验!I18,人物升级经验表!C:C,1)+1,1) -> 6 | K18: =I18-INDEX(人物升级经验表!C:C,MATCH(任务经验!I18,人物升级经验表!C:C,1),1) -> 7050 | M18: =IF((--B18)=0,1,IF((--B18)=-1,0,2)) -> 1 | O18: =IF((G18-J18)>4,1,"") | AA18: 17 | AB18: =COUNTIFS(J:J,AA18) -> 7
A19: 180141 | B19: =(--INDEX(任务列表!A:B,MATCH(A19,任务列表!A:A,0),2)) -> 0 | D19: 2400 | E19: 1500 | F19: 1500 | G19: =VLOOKUP(VLOOKUP($J$10+4-1,宠物升级表!$A:$C,3,FALSE)+SUM($F$10:F19),宠物升级表!C:D,2,TRUE)+1 -> 11 | I19: =SUM($D$2:D19) -> 33450 | J19: =INDEX(人物升级经验表!A:A,MATCH(任务经验!I19,人物升级经验表!C:C,1)+1,1) -> 6 | K19: =I19-INDEX(人物升级经验表!C:C,MATCH(任务经验!I19,人物升级经验表!C:C,1),1) -> 9450 | L19: 升级！！ | M19: =IF((--B19)=0,1,IF((--B19)=-1,0,2)) -> 1 | O19: =IF((G19-J19)>4,1,"") -> 1 | AA19: 18 | AB19: =COUNTIFS(J:J,AA19) -> 6
A20: 180142 | B20: =(--INDEX(任务列表!A:B,MATCH(A20,任务列表!A:A,0),2)) -> 0 | D20: 2800 | E20: 1750 | F20: 1550 | G20: =VLOOKUP(VLOOKUP($J$10+4-1,宠物升级表!$A:$C,3,FALSE)+SUM($F$10:F20),宠物升级表!C:D,2,TRUE)+1 -> 11 | I20: =SUM($D$2:D20) -> 36250 | J20: =INDEX(人物升级经验表!A:A,MATCH(任务经验!I20,人物升级经验表!C:C,1)+1,1) -> 7 | K20: =I20-INDEX(人物升级经验表!C:C,MATCH(任务经验!I20,人物升级经验表!C:C,1),1) -> 2650 | M20: =IF((--B20)=0,1,IF((--B20)=-1,0,2)) -> 1 | O20: =IF((G20-J20)>4,1,"") | AA20: 19 | AB20: =COUNTIFS(J:J,AA20) -> 7
A21: 180143 | B21: =(--INDEX(任务列表!A:B,MATCH(A21,任务列表!A:A,0),2)) -> 0 | D21: 2800 | E21: 1750 | F21: 1550 | G21: =VLOOKUP(VLOOKUP($J$10+4-1,宠物升级表!$A:$C,3,FALSE)+SUM($F$10:F21),宠物升级表!C:D,2,TRUE)+1 -> 11 | I21: =SUM($D$2:D21) -> 39050 | J21: =INDEX(人物升级经验表!A:A,MATCH(任务经验!I21,人物升级经验表!C:C,1)+1,1) -> 7 | K21: =I21-INDEX(人物升级经验表!C:C,MATCH(任务经验!I21,人物升级经验表!C:C,1),1) -> 5450 | M21: =IF((--B21)=0,1,IF((--B21)=-1,0,2)) -> 1 | O21: =IF((G21-J21)>4,1,"") | AA21: 20 | AB21: =COUNTIFS(J:J,AA21) -> 6
A22: 180144 | B22: =(--INDEX(任务列表!A:B,MATCH(A22,任务列表!A:A,0),2)) -> 0 | D22: 2800 | E22: 1750 | F22: 1550 | G22: =VLOOKUP(VLOOKUP($J$10+4-1,宠物升级表!$A:$C,3,FALSE)+SUM($F$10:F22),宠物升级表!C:D,2,TRUE)+1 -> 11 | I22: =SUM($D$2:D22) -> 41850 | J22: =INDEX(人物升级经验表!A:A,MATCH(任务经验!I22,人物升级经验表!C:C,1)+1,1) -> 7 | K22: =I22-INDEX(人物升级经验表!C:C,MATCH(任务经验!I22,人物升级经验表!C:C,1),1) -> 8250 | M22: =IF((--B22)=0,1,IF((--B22)=-1,0,2)) -> 1 | O22: =IF((G22-J22)>4,1,"")
A23: 180145 | B23: =(--INDEX(任务列表!A:B,MATCH(A23,任务列表!A:A,0),2)) -> 0 | D23: 2800 | E23: 1750 | F23: 1550 | G23: =VLOOKUP(VLOOKUP($J$10+4-1,宠物升级表!$A:$C,3,FALSE)+SUM($F$10:F23),宠物升级表!C:D,2,TRUE)+1 -> 12 | I23: =SUM($D$2:D23) -> 44650 | J23: =INDEX(人物升级经验表!A:A,MATCH(任务经验!I23,人物升级经验表!C:C,1)+1,1) -> 7 | K23: =I23-INDEX(人物升级经验表!C:C,MATCH(任务经验!I23,人物升级经验表!C:C,1),1) -> 11050 | L23: 升级！！ | M23: =IF((--B22)=0,1,IF((--B22)=-1,0,2)) -> 1 | O23: =IF((G23-J23)>4,1,"") -> 1 | R23: 等级段 | S23: 经验 | T23: 银币 | U23: 宠物经验 | V23: 任务数量 | W23: 单任务经验 | X23: 银币分摊 | Y23: 宠物经验分摊
A24: 180146 | B24: =(--INDEX(任务列表!A:B,MATCH(A24,任务列表!A:A,0),2)) -> 0 | D24: 2800 | E24: 2000 | F24: 2110 | G24: =VLOOKUP(VLOOKUP($J$10+4-1,宠物升级表!$A:$C,3,FALSE)+SUM($F$10:F24),宠物升级表!C:D,2,TRUE)+1 -> 12 | I24: =SUM($D$2:D24) -> 47450 | J24: =INDEX(人物升级经验表!A:A,MATCH(任务经验!I24,人物升级经验表!C:C,1)+1,1) -> 8 | K24: =I24-INDEX(人物升级经验表!C:C,MATCH(任务经验!I24,人物升级经验表!C:C,1),1) -> 2650 | M24: =IF((--B24)=0,1,IF((--B24)=-1,0,2)) -> 1 | O24: =IF((G24-J24)>4,1,"") | R24: 1 | S24: 1600 | T24: 1000 | V24: 2 | W24: =S24/V24 -> 800 | X24: =T24/V24 -> 500
A25: 180147 | B25: =(--INDEX(任务列表!A:B,MATCH(A25,任务列表!A:A,0),2)) -> 8510 | C25: 魔狼沃根 | D25: 5400 | E25: 2000 | F25: 2110 | G25: =VLOOKUP(VLOOKUP($J$10+4-1,宠物升级表!$A:$C,3,FALSE)+SUM($F$10:F25),宠物升级表!C:D,2,TRUE)+1 -> 12 | I25: =SUM($D$2:D25) -> 52850 | J25: =INDEX(人物升级经验表!A:A,MATCH(任务经验!I25,人物升级经验表!C:C,1)+1,1) -> 8 | K25: =I25-INDEX(人物升级经验表!C:C,MATCH(任务经验!I25,人物升级经验表!C:C,1),1) -> 8050 | M25: =IF((--B25)=0,1,IF((--B25)=-1,0,2)) -> 2 | O25: =IF((G25-J25)>4,1,"") | R25: 2 | S25: 3200 | T25: 2000 | V25: 3 | W25: =S25/V25 -> 1066.6667 | X25: =T25/V25 -> 666.66667
A26: 180148 | B26: =(--INDEX(任务列表!A:B,MATCH(A26,任务列表!A:A,0),2)) -> 0 | D26: 2800 | E26: 2000 | F26: 2110 | G26: =VLOOKUP(VLOOKUP($J$10+4-1,宠物升级表!$A:$C,3,FALSE)+SUM($F$10:F26),宠物升级表!C:D,2,TRUE)+1 -> 13 | I26: =SUM($D$2:D26) -> 55650 | J26: =INDEX(人物升级经验表!A:A,MATCH(任务经验!I26,人物升级经验表!C:C,1)+1,1) -> 8 | K26: =I26-INDEX(人物升级经验表!C:C,MATCH(任务经验!I26,人物升级经验表!C:C,1),1) -> 10850 | M26: =IF((--B26)=0,1,IF((--B26)=-1,0,2)) -> 1 | O26: =IF((G26-J26)>4,1,"") -> 1 | R26: 3 | S26: 4800 | T26: 3000 | V26: 3 | W26: =S26/V26 -> 1600 | X26: =T26/V26 -> 1000
A27: 180149 | B27: =(--INDEX(任务列表!A:B,MATCH(A27,任务列表!A:A,0),2)) -> 8504 | C27: 大小姐 | D27: 5400 | E27: 2000 | F27: 2110 | G27: =VLOOKUP(VLOOKUP($J$10+4-1,宠物升级表!$A:$C,3,FALSE)+SUM($F$10:F27),宠物升级表!C:D,2,TRUE)+1 -> 13 | I27: =SUM($D$2:D27) -> 61050 | J27: =INDEX(人物升级经验表!A:A,MATCH(任务经验!I27,人物升级经验表!C:C,1)+1,1) -> 9 | K27: =I27-INDEX(人物升级经验表!C:C,MATCH(任务经验!I27,人物升级经验表!C:C,1),1) -> 3450 | M27: =IF((--B27)=0,1,IF((--B27)=-1,0,2)) -> 2 | O27: =IF((G27-J27)>4,1,"") | R27: 4 | S27: 6400 | T27: 4000 | U27: 4070 | V27: 3 | W27: =S27/V27 -> 2133.3333 | X27: =T27/V27 -> 1333.3333 | Y27: =U27/V27 -> 1356.6667
A28: 180150 | B28: =(--INDEX(任务列表!A:B,MATCH(A28,任务列表!A:A,0),2)) -> 0 | D28: 2800 | E28: 2250 | F28: 1600 | G28: =VLOOKUP(VLOOKUP($J$10+4-1,宠物升级表!$A:$C,3,FALSE)+SUM($F$10:F28),宠物升级表!C:D,2,TRUE)+1 -> 13 | I28: =SUM($D$2:D28) -> 63850 | J28: =INDEX(人物升级经验表!A:A,MATCH(任务经验!I28,人物升级经验表!C:C,1)+1,1) -> 9 | K28: =I28-INDEX(人物升级经验表!C:C,MATCH(任务经验!I28,人物升级经验表!C:C,1),1) -> 6250 | M28: =IF((--B28)=0,1,IF((--B28)=-1,0,2)) -> 1 | O28: =IF((G28-J28)>4,1,"") | R28: 5 | S28: 8000 | T28: 5000 | U28: 5020 | V28: 3 | W28: =S28/V28 -> 2666.6667 | X28: =T28/V28 -> 1666.6667 | Y28: =U28/V28 -> 1673.3333
A29: 180151 | B29: =(--INDEX(任务列表!A:B,MATCH(A29,任务列表!A:A,0),2)) -> 0 | D29: 2800 | E29: 2250 | F29: 1600 | G29: =VLOOKUP(VLOOKUP($J$10+4-1,宠物升级表!$A:$C,3,FALSE)+SUM($F$10:F29),宠物升级表!C:D,2,TRUE)+1 -> 13 | I29: =SUM($D$2:D29) -> 66650 | J29: =INDEX(人物升级经验表!A:A,MATCH(任务经验!I29,人物升级经验表!C:C,1)+1,1) -> 9 | K29: =I29-INDEX(人物升级经验表!C:C,MATCH(任务经验!I29,人物升级经验表!C:C,1),1) -> 9050 | M29: =IF((--B29)=0,1,IF((--B29)=-1,0,2)) -> 1 | O29: =IF((G29-J29)>4,1,"") | R29: 6 | S29: 9600 | T29: 6000 | U29: 6070 | V29: 4 | W29: =S29/V29 -> 2400 | X29: =T29/V29 -> 1500 | Y29: =U29/V29 -> 1517.5
A30: 180152 | B30: =(--INDEX(任务列表!A:B,MATCH(A30,任务列表!A:A,0),2)) -> 0 | D30: 2800 | E30: 2250 | F30: 1600 | G30: =VLOOKUP(VLOOKUP($J$10+4-1,宠物升级表!$A:$C,3,FALSE)+SUM($F$10:F30),宠物升级表!C:D,2,TRUE)+1 -> 13 | I30: =SUM($D$2:D30) -> 69450 | J30: =INDEX(人物升级经验表!A:A,MATCH(任务经验!I30,人物升级经验表!C:C,1)+1,1) -> 9 | K30: =I30-INDEX(人物升级经验表!C:C,MATCH(任务经验!I30,人物升级经验表!C:C,1),1) -> 11850 | M30: =IF((--B20)=0,1,IF((--B20)=-1,0,2)) -> 1 | O30: =IF((G30-J30)>4,1,"") | R30: 7 | S30: 11200 | T30: 7000 | U30: 7220 | V30: 4 | W30: =S30/V30 -> 2800 | X30: =T30/V30 -> 1750 | Y30: =U30/V30 -> 1805
A31: 180153 | B31: =(--INDEX(任务列表!A:B,MATCH(A31,任务列表!A:A,0),2)) -> 0 | D31: 2800 | E31: 2250 | F31: 1600 | G31: =VLOOKUP(VLOOKUP($J$10+4-1,宠物升级表!$A:$C,3,FALSE)+SUM($F$10:F31),宠物升级表!C:D,2,TRUE)+1 -> 14 | I31: =SUM($D$2:D31) -> 72250 | J31: =INDEX(人物升级经验表!A:A,MATCH(任务经验!I31,人物升级经验表!C:C,1)+1,1) -> 10 | K31: =I31-INDEX(人物升级经验表!C:C,MATCH(任务经验!I31,人物升级经验表!C:C,1),1) -> 250 | M31: =IF((--B21)=0,1,IF((--B21)=-1,0,2)) -> 1 | O31: =IF((G31-J31)>4,1,"") | R31: 8 | S31: 12800 | T31: 8000 | U31: 8470 | V31: 4 | W31: =S31/V31 -> 3200 | X31: =T31/V31 -> 2000 | Y31: =U31/V31 -> 2117.5
A32: 180154 | B32: =(--INDEX(任务列表!A:B,MATCH(A32,任务列表!A:A,0),2)) -> 0 | D32: 2950 | E32: 2500 | F32: 2260 | G32: =VLOOKUP(VLOOKUP($J$10+4-1,宠物升级表!$A:$C,3,FALSE)+SUM($F$10:F32),宠物升级表!C:D,2,TRUE)+1 -> 14 | I32: =SUM($D$2:D32) -> 75200 | J32: =INDEX(人物升级经验表!A:A,MATCH(任务经验!I32,人物升级经验表!C:C,1)+1,1) -> 10 | K32: =I32-INDEX(人物升级经验表!C:C,MATCH(任务经验!I32,人物升级经验表!C:C,1),1) -> 3200 | M32: =IF((--B22)=0,1,IF((--B22)=-1,0,2)) -> 1 | O32: =IF((G32-J32)>4,1,"") | R32: 9 | S32: 14400 | T32: 9000 | U32: 9820 | V32: 4 | W32: =S32/V32 -> 3600 | X32: =T32/V32 -> 2250 | Y32: =U32/V32 -> 2455
A33: 180155 | B33: =(--INDEX(任务列表!A:B,MATCH(A33,任务列表!A:A,0),2)) -> 0 | D33: 2950 | E33: 2500 | F33: 2260 | G33: =VLOOKUP(VLOOKUP($J$10+4-1,宠物升级表!$A:$C,3,FALSE)+SUM($F$10:F33),宠物升级表!C:D,2,TRUE)+1 -> 14 | I33: =SUM($D$2:D33) -> 78150 | J33: =INDEX(人物升级经验表!A:A,MATCH(任务经验!I33,人物升级经验表!C:C,1)+1,1) -> 10 | K33: =I33-INDEX(人物升级经验表!C:C,MATCH(任务经验!I33,人物升级经验表!C:C,1),1) -> 6150 | M33: =IF((--B22)=0,1,IF((--B22)=-1,0,2)) -> 1 | O33: =IF((G33-J33)>4,1,"") | R33: 10 | S33: 16000 | T33: 10000 | U33: 11270 | V33: 4 | W33: =S33/V33 -> 4000 | X33: =T33/V33 -> 2500 | Y33: =U33/V33 -> 2817.5
A34: 180156 | B34: =(--INDEX(任务列表!A:B,MATCH(A34,任务列表!A:A,0),2)) -> 0 | D34: 2950 | E34: 2500 | F34: 2260 | G34: =VLOOKUP(VLOOKUP($J$10+4-1,宠物升级表!$A:$C,3,FALSE)+SUM($F$10:F34),宠物升级表!C:D,2,TRUE)+1 -> 14 | I34: =SUM($D$2:D34) -> 81100 | J34: =INDEX(人物升级经验表!A:A,MATCH(任务经验!I34,人物升级经验表!C:C,1)+1,1) -> 10 | K34: =I34-INDEX(人物升级经验表!C:C,MATCH(任务经验!I34,人物升级经验表!C:C,1),1) -> 9100 | M34: =IF((--B24)=0,1,IF((--B24)=-1,0,2)) -> 1 | O34: =IF((G34-J34)>4,1,"") | T34: =SUM(V24:V33) -> 34
A35: 180157 | B35: =(--INDEX(任务列表!A:B,MATCH(A35,任务列表!A:A,0),2)) -> 8505 | C35: 耐奥祖 | D35: 6000 | E35: 2500 | F35: 2800 | G35: =VLOOKUP(VLOOKUP($J$10+4-1,宠物升级表!$A:$C,3,FALSE)+SUM($F$10:F35),宠物升级表!C:D,2,TRUE)+1 -> 15 | H35: 10 | I35: =SUM($D$2:D35) -> 87100 | J35: =INDEX(人物升级经验表!A:A,MATCH(任务经验!I35,人物升级经验表!C:C,1)+1,1) -> 10 | K35: =I35-INDEX(人物升级经验表!C:C,MATCH(任务经验!I35,人物升级经验表!C:C,1),1) -> 15100 | M35: =IF((--B25)=0,1,IF((--B25)=-1,0,2)) -> 2 | O35: =IF((G35-J35)>4,1,"") -> 1
A36: 180158 | B36: =(--INDEX(任务列表!A:B,MATCH(A36,任务列表!A:A,0),2)) -> 0 | D36: 3200 | E36: 2200 | F36: 2200 | G36: =VLOOKUP(VLOOKUP($J$10+4-1,宠物升级表!$A:$C,3,FALSE)+SUM($F$10:F36),宠物升级表!C:D,2,TRUE)+1 -> 15 | I36: =SUM($D$2:D36) -> 90300 | J36: =INDEX(人物升级经验表!A:A,MATCH(任务经验!I36,人物升级经验表!C:C,1)+1,1) -> 11 | K36: =I36-INDEX(人物升级经验表!C:C,MATCH(任务经验!I36,人物升级经验表!C:C,1),1) -> 2300 | M36: =IF((--B26)=0,1,IF((--B26)=-1,0,2)) -> 1 | O36: =IF((G36-J36)>4,1,"")
A37: 180159 | B37: =(--INDEX(任务列表!A:B,MATCH(A37,任务列表!A:A,0),2)) -> 0 | D37: 3200 | E37: 2200 | F37: 2200 | G37: =VLOOKUP(VLOOKUP($J$10+4-1,宠物升级表!$A:$C,3,FALSE)+SUM($F$10:F37),宠物升级表!C:D,2,TRUE)+1 -> 15 | I37: =SUM($D$2:D37) -> 93500 | J37: =INDEX(人物升级经验表!A:A,MATCH(任务经验!I37,人物升级经验表!C:C,1)+1,1) -> 11 | K37: =I37-INDEX(人物升级经验表!C:C,MATCH(任务经验!I37,人物升级经验表!C:C,1),1) -> 5500 | M37: =IF((--B27)=0,1,IF((--B27)=-1,0,2)) -> 2 | O37: =IF((G37-J37)>4,1,"") | R37: 等级段 | S37: 经验 | T37: 银币 | U37: 宠物经验 | V37: 任务数量 | W37: 单任务经验 | X37: 银币分摊 | Y37: 宠物经验分摊
A38: 180160 | B38: =(--INDEX(任务列表!A:B,MATCH(A38,任务列表!A:A,0),2)) -> 0 | D38: 3200 | E38: 2200 | F38: 2200 | G38: =VLOOKUP(VLOOKUP($J$10+4-1,宠物升级表!$A:$C,3,FALSE)+SUM($F$10:F38),宠物升级表!C:D,2,TRUE)+1 -> 15 | I38: =SUM($D$2:D38) -> 96700 | J38: =INDEX(人物升级经验表!A:A,MATCH(任务经验!I38,人物升级经验表!C:C,1)+1,1) -> 11 | K38: =I38-INDEX(人物升级经验表!C:C,MATCH(任务经验!I38,人物升级经验表!C:C,1),1) -> 8700 | M38: =IF((--B28)=0,1,IF((--B28)=-1,0,2)) -> 1 | O38: =IF((G38-J38)>4,1,"") | R38: 11 | S38: 17600 | T38: 11000 | U38: 12820 | V38: 5 | W38: =S38/V38 -> 3520 | X38: =T38/V38 -> 2200 | Y38: =U38/V38 -> 2564
A39: 180161 | B39: =(--INDEX(任务列表!A:B,MATCH(A39,任务列表!A:A,0),2)) -> 0 | D39: 3200 | E39: 2200 | F39: 2200 | G39: =VLOOKUP(VLOOKUP($J$10+4-1,宠物升级表!$A:$C,3,FALSE)+SUM($F$10:F39),宠物升级表!C:D,2,TRUE)+1 -> 15 | I39: =SUM($D$2:D39) -> 99900 | J39: =INDEX(人物升级经验表!A:A,MATCH(任务经验!I39,人物升级经验表!C:C,1)+1,1) -> 11 | K39: =I39-INDEX(人物升级经验表!C:C,MATCH(任务经验!I39,人物升级经验表!C:C,1),1) -> 11900 | M39: =IF((--B29)=0,1,IF((--B29)=-1,0,2)) -> 1 | O39: =IF((G39-J39)>4,1,"") | R39: 12 | S39: 19200 | T39: 12000 | U39: 14470 | V39: 5 | W39: =S39/V39 -> 3840 | X39: =T39/V39 -> 2400 | Y39: =U39/V39 -> 2894
A40: 180106 | B40: =(--INDEX(任务列表!A:B,MATCH(A40,任务列表!A:A,0),2)) -> 0 | D40: 3200 | E40: 2200 | F40: 2200 | G40: =VLOOKUP(VLOOKUP($J$10+4-1,宠物升级表!$A:$C,3,FALSE)+SUM($F$10:F40),宠物升级表!C:D,2,TRUE)+1 -> 16 | I40: =SUM($D$2:D40) -> 103100 | J40: =INDEX(人物升级经验表!A:A,MATCH(任务经验!I40,人物升级经验表!C:C,1)+1,1) -> 11 | K40: =I40-INDEX(人物升级经验表!C:C,MATCH(任务经验!I40,人物升级经验表!C:C,1),1) -> 15100 | M40: =IF((--B40)=0,1,IF((--B40)=-1,0,2)) -> 1 | O40: =IF((G40-J40)>4,1,"") -> 1 | R40: 13 | S40: 20800 | T40: 13000 | U40: 16220 | V40: 5 | W40: =S40/V40 -> 4160 | X40: =T40/V40 -> 2600 | Y40: =U40/V40 -> 3244
...

Sheet 人物升级经验表
A1: 当前等级 | B1: 升级经验 | C1: 当前等级所需经验
A2: 0 | B2: 0 | C2: 0
A3: 1 | B3: 1600 | C3: 1600
A4: 2 | B4: 3200 | C4: 4800
A5: 3 | B5: 4800 | C5: 9600
A6: 4 | B6: 6400 | C6: 16000
A7: 5 | B7: 8000 | C7: 24000
A8: 6 | B8: 9600 | C8: 33600
A9: 7 | B9: 11200 | C9: 44800
A10: 8 | B10: 12800 | C10: 57600
A11: 9 | B11: 14400 | C11: 72000
A12: 10 | B12: 16000 | C12: 88000
A13: 11 | B13: 17600 | C13: 105600
... A152: 150 | B152: 529301530 | C152: 19532492643

Sheet 任务列表
A1: 180101 | B1: 0
A2: 180201 | B2: 0
A3: 180301 | B3: 0
A4: 180401 | B4: 0
A5: 180501 | B5: 0
A6: 180601 | B6: 0
A7: 180701 | B7: 0
A8: 180801 | B8: 0
A9: 180901 | B9: 0
A10: 180102 | B10: 0
A11: 180202 | B11: 0
A12: 180302 | B12: 0
... A262: 182181 | B262: 8546
A263: 182182
A264: 182183 | B264: 0
A265: 182184 | B265: 0
A266: 182185 | B266: 0
A267: 182186 | B267: 8547
A268: 182187 | B268: 8548
A269: 182188 | B269: 0
A270: 182189 | B270: 0
A271: 182190 | B271: 0
A272: 182191 | B272: 0
A273: 182192 | B273: 0
A274: 182193 | B274: 0
A275: 182194 | B275: 8549
... A373: 189901 | B373: 0
A374: 189902 | B374: 0
A375: 189903 | B375: 0
A376: 189904 | B376: 0
A377: 189905 | B377: 0
A378: 189906 | B378: 0
A379: 189907 | B379: 0
A380: 189908 | B380: 0
A381: 189909 | B381: 0
A382: 189910 | B382: 0
A383: 189911 | B383: 0
A384: 189912 | B384: 0
A385: 189913 | B385: 0
A386: 189914 | B386: 0
...

Sheet 宠物升级表
A1: 等级 | B1: 所需经验 | C1: 总经验值
A2: 0 | B2: 20 | C2: =SUM($B$2:B2) -> 20 | D2: 0
A3: 1 | B3: 70 | C3: =SUM($B$2:B3) -> 90 | D3: 1
A4: 2 | B4: 220 | C4: =SUM($B$2:B4) -> 310 | D4: 2
A5: 3 | B5: 470 | C5: =SUM($B$2:B5) -> 780 | D5: 3
A6: 4 | B6: 820 | C6: =SUM($B$2:B6) -> 1600 | D6: 4
A7: 5 | B7: 1270 | C7: =SUM($B$2:B7) -> 2870 | D7: 5
A8: 6 | B8: 1820 | C8: =SUM($B$2:B8) -> 4690 | D8: 6 | J8: 7160
A9: 7 | B9: 2470 | C9: =SUM($B$2:B9) -> 7160 | D9: 7 | H9: 44150 | J9: 67300
A10: 8 | B10: 3220 | C10: =SUM($B$2:B10) -> 10380 | D10: 8 | J10: =J8+J9 -> 74460
A11: 9 | B11: 4070 | C11: =SUM($B$2:B11) -> 14450 | D11: 9
A12: 10 | B12: 5020 | C12: =SUM($B$2:B12) -> 19470 | D12: 10
A13: 11 | B13: 6070 | C13: =SUM($B$2:B13) -> 25540 | D13: 11
A14: 12 | B14: 7220 | C14: =SUM($B$2:B14) -> 32760 | D14: 12
A15: 13 | B15: 8470 | C15: =SUM($B$2:B15) -> 41230 | D15: 13
A16: 14 | B16: 9820 | C16: =SUM($B$2:B16) -> 51050 | D16: 14
A17: 15 | B17: 11270 | C17: =SUM($B$2:B17) -> 62320 | D17: 15
A18: 16 | B18: 12820 | C18: =SUM($B$2:B18) -> 75140 | D18: 16
A19: 17 | B19: 14470 | C19: =SUM($B$2:B19) -> 89610 | D19: 17
A20: 18 | B20: 16220 | C20: =SUM($B$2:B20) -> 105830 | D20: 18
A21: 19 | B21: 18070 | C21: =SUM($B$2:B21) -> 123900 | D21: 19
A22: 20 | B22: 20020 | C22: =SUM($B$2:B22) -> 143920 | D22: 20
... A151: 149 | B151: 1110070 | C151: =SUM($B$2:B151) -> 55691750 | D151: 149
B152: 1125020

Sheet Sheet1
A1: 150 | B1: 529301530
A2: 149 | B2: 518860046 | N2: 34个任务
A3: 148 | B3: 508556965
A4: 147 | B4: 498391164 | K4: 1 | L4: 300 | M4: 2
A5: 146 | B5: 488361720 | K5: 2 | L5: 1000 | M5: 3
A6: 145 | B6: 478467912 | K6: 3 | L6: 2300 | M6: 3
A7: 144 | B7: 468708618 | K7: 4 | L7: 4000 | M7: 4
A8: 143 | B8: 459083115 | K8: 5 | L8: 6300 | M8: 5
A9: 142 | B9: 449590281 | K9: 6 | L9: 9000 | M9: 6
A10: 141 | B10: 440229194 | K10: 7 | L10: 12300 | M10: 6
A11: 140 | B11: 430999132 | K11: 8 | L11: 16000 | M11: 6
A12: 139 | B12: 421898973 | K12: 9 | L12: 20300 | M12: 7
A13: 138 | B13: 412927994
A14: 137 | B14: 404085074
A15: 136 | B15: 395369289
A16: 135 | B16: 386779919
A17: 134 | B17: 378315841
A18: 133 | B18: 369976332
A19: 132 | B19: 361760271
A20: 131 | B20: 353666735
A21: 130 | B21: 345695003
A22: 129 | B22: 337843951 | L22: 4
A23: 128 | B23: 330112859
A24: 127 | B24: 322500603
A25: 126 | B25: 315006262
A26: 125 | B26: 307629113
A27: 124 | B27: 300368034
A28: 123 | B28: 293222304
A29: 122 | B29: 286190799
A30: 121 | B30: 279272599
A31: 120 | B31: 272466980
A32: 119 | B32: 265772820
A33: 118 | B33: 259189397
A34: 117 | B34: 252715590
... A150: 1 | B150: 1600

Sheet Sheet2
