Workbook

Sheet 战斗计算流程
B1: 基础属性 | G1: 技能执行
B2: 10 | C2: 体质 | D2: 10 | E2: cons_value | H2: //该次技能内部参数
B3: 20 | C3: 智力 | D3: 20 | E3: iq_value | G3: 判断技能是否能释放 | H3: 技能释放属性状态过滤 | I3: 技能释放属性状态条件
B4: 30 | C4: 力量 | D4: 30 | E4: str_value | H4: 技能释放buff状态过滤 | I4: 技能释放buff状态条件
B5: 40 | C5: 耐力 | D5: 40 | E5: endu_value | H5: 技能释放消耗生命 | I5: 技能释放消耗魔法 | J5: 技能释放消耗怒气
B6: 50 | C6: 敏捷 | D6: 50 | E6: agi_value | H6: 选择目标类型 | I6: 玩家操作选择的目标
B7: 60 | C7: 生命 | D7: 60 | E7: maxhp_value | H7: buff0类型id | I7: buff0释放属性状态过滤 | J7: buff0释放属性状态条件 | K7: buff0释放buff状态过滤 | L7: buff0释放buff状态条件 | M7: buff0触发几率 | N7: buff0命中 | O7: buff0目标类型 | P7: buff0目标个数 | Q7: buff0排序变量 | R7: buff0持续回合 | S7: buff0效果
B8: 70 | C8: 当前生命上限 | D8: 70 | E8: uplimithp_value | H8: buff1类型id | I8: buff1释放属性状态过滤 | J8: buff1释放属性状态条件 | K8: buff1释放buff状态过滤 | L8: buff1释放buff状态条件 | M8: buff1触发几率 | N8: buff1命中 | O8: buff1目标类型 | P8: buff1目标个数 | Q8: buff1排序变量 | R8: buff1持续回合 | S8: buff1效果
B9: 80 | C9: 生命值 | D9: 80 | E9: curhp_value | H9: buff2类型id | I9: buff2释放属性状态过滤 | J9: buff2释放属性状态条件 | K9: buff2释放buff状态过滤 | L9: buff2释放buff状态条件 | M9: buff2触发几率 | N9: buff2命中 | O9: buff2目标类型 | P9: buff2目标个数 | Q9: buff2排序变量 | R9: buff2持续回合 | S9: buff2效果
B10: 90 | C10: 魔法 | D10: 90 | E10: maxmp_value | H10: buff3类型id | I10: buff3释放属性状态过滤 | J10: buff3释放属性状态条件 | K10: buff3释放buff状态过滤 | L10: buff3释放buff状态条件 | M10: buff3触发几率 | N10: buff3命中 | O10: buff3目标类型 | P10: buff3目标个数 | Q10: buff3排序变量 | R10: buff3持续回合 | S10: buff3效果
B11: 100 | C11: 魔法值 | D11: 100 | E11: curmp_value | H11: buff4类型id | I11: buff4释放属性状态过滤 | J11: buff4释放属性状态条件 | K11: buff4释放buff状态过滤 | L11: buff4释放buff状态条件 | M11: buff4触发几率 | N11: buff4命中 | O11: buff4目标类型 | P11: buff4目标个数 | Q11: buff4排序变量 | R11: buff4持续回合 | S11: buff4效果
B12: 110 | C12: 怒气 | D12: 110 | E12: maxsp_value | H12: buff5类型id | I12: buff5释放属性状态过滤 | J12: buff5释放属性状态条件 | K12: buff5释放buff状态过滤 | L12: buff5释放buff状态条件 | M12: buff5触发几率 | N12: buff5命中 | O12: buff5目标类型 | P12: buff5目标个数 | Q12: buff5排序变量 | R12: buff5持续回合 | S12: buff5效果
B13: 120 | C13: 怒气值 | D13: 120 | E13: cursp_value | H13: buff6类型id | I13: buff6释放属性状态过滤 | J13: buff6释放属性状态条件 | K13: buff6释放buff状态过滤 | L13: buff6释放buff状态条件 | M13: buff6触发几率 | N13: buff6命中 | O13: buff6目标类型 | P13: buff6目标个数 | Q13: buff6排序变量 | R13: buff6持续回合 | S13: buff6效果
B14: 130 | C14: 物理攻击 | D14: 130 | E14: phyattack_value | H14: buff7类型id | I14: buff7释放属性状态过滤 | J14: buff7释放属性状态条件 | K14: buff7释放buff状态过滤 | L14: buff7释放buff状态条件 | M14: buff7触发几率 | N14: buff7命中 | O14: buff7目标类型 | P14: buff7目标个数 | Q14: buff7排序变量 | R14: buff7持续回合 | S14: buff7效果
B15: 140 | C15: 物理防御 | D15: 140 | E15: defend_value | H15: buff8类型id | I15: buff8释放属性状态过滤 | J15: buff8释放属性状态条件 | K15: buff8释放buff状态过滤 | L15: buff8释放buff状态条件 | M15: buff8触发几率 | N15: buff8命中 | O15: buff8目标类型 | P15: buff8目标个数 | Q15: buff8排序变量 | R15: buff8持续回合 | S15: buff8效果
B16: 150 | C16: 法术攻击 | D16: 150 | E16: magicattack_value | H16: buff9类型id | I16: buff9释放属性状态过滤 | J16: buff9释放属性状态条件 | K16: buff9释放buff状态过滤 | L16: buff9释放buff状态条件 | M16: buff9触发几率 | N16: buff9命中 | O16: buff9目标类型 | P16: buff9目标个数 | Q16: buff9排序变量 | R16: buff9持续回合 | S16: buff9效果
B17: 160 | C17: 法术防御 | D17: 160 | E17: magicdef_value | H17: buff10类型id | I17: buff10释放属性状态过滤 | J17: buff10释放属性状态条件 | K17: buff10释放buff状态过滤 | L17: buff10释放buff状态条件 | M17: buff10触发几率 | N17: buff10命中 | O17: buff10目标类型 | P17: buff10目标个数 | Q17: buff10排序变量 | R17: buff10持续回合 | S17: buff10效果
B18: 170 | C18: 治疗强度 | D18: 170 | E18: medical_value | H18: buff11类型id | I18: buff11释放属性状态过滤 | J18: buff11释放属性状态条件 | K18: buff11释放buff状态过滤 | L18: buff11释放buff状态条件 | M18: buff11触发几率 | N18: buff11命中 | O18: buff11目标类型 | P18: buff11目标个数 | Q18: buff11排序变量 | R18: buff11持续回合 | S18: buff11效果
B19: 180 | C19: 控制命中 | D19: 180 | E19: sealhit_value | H19: buff12类型id | I19: buff12释放属性状态过滤 | J19: buff12释放属性状态条件 | K19: buff12释放buff状态过滤 | L19: buff12释放buff状态条件 | M19: buff12触发几率 | N19: buff12命中 | O19: buff12目标类型 | P19: buff12目标个数 | Q19: buff12排序变量 | R19: buff12持续回合 | S19: buff12效果
B20: 190 | C20: 控制抗性 | D20: 190 | E20: unseal_value
B21: 200 | C21: 速度 | D21: 200 | E21: speed_value | G21: 取出属性 | H21: 所有战斗属性
B22: 210 | C22: 命中 | D22: 210 | E22: hit_value | H22: 插入对应的技能脚本修正参数
B23: 220 | C23: 闪避 | D23: 220 | E23: dodge_value
B24: 230 | C24: 物理暴击 | D24: 230 | E24: phycruellv_value | G24: 按技能阶段包含的效果buff一个阶段一个阶段执行
B25: 240 | C25: 物理抗暴 | D25: 240 | E25: resistcruel_value | G25: 该阶段buff全部不能释放则跳过该阶段，该阶段buff全部闪避则客户端播放闪避动作
B26: 250 | C26: 物理暴伤 | D26: 250 | E26: phycrueldegree_value | G26: 每个buff的执行流程 | H26: //该次buff内部参数
B27: 260 | C27: 法术暴击 | D27: 260 | E27: magiccruellv_value | H27: 该效果buff释放条件
B28: 270 | C28: 法术抗暴 | D28: 270 | E28: resistmagiccrule_value | H28: 物理攻击 | I28: 物理防御
B29: 280 | C29: 法术暴伤 | D29: 280 | E29: magiccrueldegree_value | H29: 物理伤害效果修正 | I29: 被物理伤害修正
B30: 290 | C30: 治疗暴击 | D30: 290 | E30: heallv_value | H30: 物理穿透 | I30: 物理抵抗
B31: 300 | C31: 治疗暴击量 | D31: 300 | E31: healdegree_value | H31: 最低物理伤害 | I31: 伤害浮动值
B32: 310 | C32: 忽视物理防御几率 | D32: 310 | E32: phynodefrate_value | H32: 忽视物理防御率=忽视物理防御几率 | I32: 忽视物理防御系数=忽视物理防御系数
B33: 320 | C33: 忽视物理防御系数 | D33: 320 | E33: phynodefdegree_value | H33: 物理暴击率=（物理暴击/1000-物理抗暴/1000）+(物理暴击几率修正-被物理暴击几率修正）
B34: 330 | C34: 忽视法术防御几率 | D34: 330 | E34: magicnodefrate_value | H34: 物理暴伤=物理暴伤
B35: 340 | C35: 忽视法术防御系数 | D35: 340 | E35: magicnodefdegree_value | H35: 是否防御=靠客户端给 | I35: 防御减免伤害系数=防御减免伤害系数
B36: 350 | C36: 吸血几率 | D36: 350 | E36: xixuerate_value | H36: 格挡率=格挡几率-攻击时被格挡几率修正 | I36: 格挡减免伤害系数=格挡减免伤害系数
B37: 360 | C37: 吸血系数 | D37: 360 | E37: xixuedegree_value | H37: 是否主动保护=靠客户端给
B38: 370 | C38: 打蓝几率 | D38: 370 | E38: dalanrate_value | H38: 每个组合被动保护概率=默认自动保护率+好友度加成自动保护率 | I38: 保护分担伤害系数=保护分担伤害系数
B39: 380 | C39: 打蓝系数（原吸蓝比例改成打蓝比例） | D39: 380 | E39: xilandegree_value | H39: 打蓝率=打蓝几率 | I39: 打蓝系数=打蓝系数
B40: 390 | C40: 上毒几率 | D40: 390 | E40: poisonrate_value | H40: 吸血率=吸血几率 | I40: 吸血系数=吸血系数
...

Sheet 属性投放
C2: 属性投放标准模板 | D2: 生命 | E2: 魔法 | F2: 物攻 | G2: 物防 | H2: 法攻 | I2: 法防 | J2: 速度 | K2: 治疗强度 | L2: 控制命中 | M2: 控制抗性 | N2: 标准角色物攻回合数 | O2: 标准角色法攻回合数 | P2: 标准角色治疗平均回合数
D3: =ROUND(SUM(E36:E53),2) -> 57.4 | E3: =ROUND(SUM(F36:F53),2) -> 48.2 | F3: =ROUND(SUM(G36:G53),2) -> 19.3 | G3: =ROUND(SUM(H36:H53),2) -> 9.7 | H3: =ROUND(SUM(I36:I53),2) -> 14.3 | I3: =ROUND(SUM(J36:J53),2) -> 10.9 | J3: =ROUND(SUM(K36:K53),2) -> 7.25 | K3: =ROUND(SUM(L36:L53),2) -> 5.1 | ... M3: =ROUND(SUM(N36:N53),2) -> 11.1 | N3: =D3/((F3*(1+E8)-G3+F8)*(1+G8)*(1+H8))/I8 -> 4.0901836 | O3: =D3/((H3*(1+E9)-I3+F9)*(1+G9)*(1+H9))/I9 -> 8.1673307 | P3: =D3/((K3*(1+E10)+F10)*(1+G10)*(1+H10))/I10 -> 6.6853017
C4: 主角初始属性 | D4: 200 | E4: 200 | F4: 100 | G4: 50 | H4: 80 | I4: 40 | J4: 30 | K4: 20 | L4: 0 | M4: 0
O6: =3700/O3 -> 453.02439 | P6: =3700/P3 -> 553.45296
E7: 技能附加百分比系数 | F7: 技能附加点数系数 | G7: 平均阵法加成 | H7: 修炼平均加强系数 | I7: 单位数衰减
D8: 物攻 | E8: 0.1 | F8: 1 | G8: 0.12 | H8: 0 | I8: 1
D9: 法攻 | E9: 0.5 | F9: 2 | G9: 0.12 | H9: 0 | I9: 0.5
D10: 治疗 | E10: 0 | F10: 3 | G10: 0 | H10: 0.06 | I10: 1
D13: 角色属性标准投放-模块投放比重 | E13: 生命 | F13: 魔法 | G13: 物攻 | H13: 物防 | I13: 法攻 | J13: 法防 | K13: 速度 | L13: 治疗强度 | M13: 控制命中 | N13: 控制抗性
C14: 固定属性 | D14: 装备白属性 | E14: =ROUND(E36/D$3,3) -> 0.286 | F14: =ROUND(F36/E$3,3) -> 0.17 | G14: =ROUND(G36/F$3,3) -> 0.425 | H14: =ROUND(H36/G$3,3) -> 0.423 | I14: =ROUND(I36/H$3,3) -> 0.287 | J14: =ROUND(J36/I$3,3) -> 0.22 | K14: =ROUND(K36/J$3,3) -> 0.179 | L14: =ROUND(L36/K$3,3) -> 0.588 | ... N14: =ROUND(N36/M$3,3) -> 0
D15: 公会技能 | E15: =ROUND(E37/D$3,3) -> 0.174 | F15: =ROUND(F37/E$3,3) -> 0.207 | G15: =ROUND(G37/F$3,3) -> 0 | H15: =ROUND(H37/G$3,3) -> 0 | I15: =ROUND(I37/H$3,3) -> 0 | J15: =ROUND(J37/I$3,3) -> 0 | K15: =ROUND(K37/J$3,3) -> 0 | L15: =ROUND(L37/K$3,3) -> 0 | ... N15: =ROUND(N37/M$3,3) -> 0
D16: 装备打符 | E16: =ROUND(E38/D$3,3) -> 0.087 | F16: =ROUND(F38/E$3,3) -> 0 | G16: =ROUND(G38/F$3,3) -> 0.052 | H16: =ROUND(H38/G$3,3) -> 0.103 | I16: =ROUND(I38/H$3,3) -> 0.07 | J16: =ROUND(J38/I$3,3) -> 0.092 | K16: =ROUND(K38/J$3,3) -> 0.069 | L16: =ROUND(L38/K$3,3) -> 0.098 | ... N16: =ROUND(N38/M$3,3) -> 0.027
E17: =ROUND(E39/D$3,3) -> 0 | F17: =ROUND(F39/E$3,3) -> 0 | G17: =ROUND(G39/F$3,3) -> 0 | H17: =ROUND(H39/G$3,3) -> 0 | I17: =ROUND(I39/H$3,3) -> 0 | J17: =ROUND(J39/I$3,3) -> 0 | K17: =ROUND(K39/J$3,3) -> 0 | L17: =ROUND(L39/K$3,3) -> 0 | ... N17: =ROUND(N39/M$3,3) -> 0
E18: =ROUND(E40/D$3,3) -> 0 | F18: =ROUND(F40/E$3,3) -> 0 | G18: =ROUND(G40/F$3,3) -> 0 | H18: =ROUND(H40/G$3,3) -> 0 | I18: =ROUND(I40/H$3,3) -> 0 | J18: =ROUND(J40/I$3,3) -> 0 | K18: =ROUND(K40/J$3,3) -> 0 | L18: =ROUND(L40/K$3,3) -> 0 | ... N18: =ROUND(N40/M$3,3) -> 0
E19: =ROUND(E41/D$3,3) -> 0 | F19: =ROUND(F41/E$3,3) -> 0 | G19: =ROUND(G41/F$3,3) -> 0 | H19: =ROUND(H41/G$3,3) -> 0 | I19: =ROUND(I41/H$3,3) -> 0 | J19: =ROUND(J41/I$3,3) -> 0 | K19: =ROUND(K41/J$3,3) -> 0 | L19: =ROUND(L41/K$3,3) -> 0 | ... N19: =ROUND(N41/M$3,3) -> 0
E20: =ROUND(E42/D$3,3) -> 0 | F20: =ROUND(F42/E$3,3) -> 0 | G20: =ROUND(G42/F$3,3) -> 0 | H20: =ROUND(H42/G$3,3) -> 0 | I20: =ROUND(I42/H$3,3) -> 0 | J20: =ROUND(J42/I$3,3) -> 0 | K20: =ROUND(K42/J$3,3) -> 0 | L20: =ROUND(L42/K$3,3) -> 0 | ... N20: =ROUND(N42/M$3,3) -> 0
E21: =ROUND(E43/D$3,3) -> 0 | F21: =ROUND(F43/E$3,3) -> 0 | G21: =ROUND(G43/F$3,3) -> 0 | H21: =ROUND(H43/G$3,3) -> 0 | I21: =ROUND(I43/H$3,3) -> 0 | J21: =ROUND(J43/I$3,3) -> 0 | K21: =ROUND(K43/J$3,3) -> 0 | L21: =ROUND(L43/K$3,3) -> 0 | ... N21: =ROUND(N43/M$3,3) -> 0
E22: =ROUND(E44/D$3,3) -> 0 | F22: =ROUND(F44/E$3,3) -> 0 | G22: =ROUND(G44/F$3,3) -> 0 | H22: =ROUND(H44/G$3,3) -> 0 | I22: =ROUND(I44/H$3,3) -> 0 | J22: =ROUND(J44/I$3,3) -> 0 | K22: =ROUND(K44/J$3,3) -> 0 | L22: =ROUND(L44/K$3,3) -> 0 | ... N22: =ROUND(N44/M$3,3) -> 0
C23: 加点层面选择属性 | D23: 自然成长 | E23: =ROUND(E45/D$3,3) -> 0.139 | F23: =ROUND(F45/E$3,3) -> 0.104 | G23: =ROUND(G45/F$3,3) -> 0.052 | H23: =ROUND(H45/G$3,3) -> 0.227 | I23: =ROUND(I45/H$3,3) -> 0.07 | J23: =ROUND(J45/I$3,3) -> 0.22 | K23: =ROUND(K45/J$3,3) -> 0.29 | L23: =ROUND(L45/K$3,3) -> 0 | ... N23: =ROUND(N45/M$3,3) -> 0
D24: 手动加点 | E24: =ROUND(E46/D$3,3) -> 0.139 | F24: =ROUND(F46/E$3,3) -> 0.415 | G24: =ROUND(G46/F$3,3) -> 0.207 | H24: =ROUND(H46/G$3,3) -> 0 | I24: =ROUND(I46/H$3,3) -> 0.28 | J24: =ROUND(J46/I$3,3) -> 0.257 | K24: =ROUND(K46/J$3,3) -> 0.138 | L24: =ROUND(L46/K$3,3) -> 0 | ... N24: =ROUND(N46/M$3,3) -> 0
D25: 装备附加 | E25: =ROUND(E47/D$3,3) -> 0.035 | F25: =ROUND(F47/E$3,3) -> 0.104 | G25: =ROUND(G47/F$3,3) -> 0.052 | H25: =ROUND(H47/G$3,3) -> 0 | I25: =ROUND(I47/H$3,3) -> 0.07 | J25: =ROUND(J47/I$3,3) -> 0.064 | K25: =ROUND(K47/J$3,3) -> 0.034 | L25: =ROUND(L47/K$3,3) -> 0 | ... N25: =ROUND(N47/M$3,3) -> 0
E26: =ROUND(E48/D$3,3) -> 0 | F26: =ROUND(F48/E$3,3) -> 0 | G26: =ROUND(G48/F$3,3) -> 0 | H26: =ROUND(H48/G$3,3) -> 0 | I26: =ROUND(I48/H$3,3) -> 0 | J26: =ROUND(J48/I$3,3) -> 0 | K26: =ROUND(K48/J$3,3) -> 0 | L26: =ROUND(L48/K$3,3) -> 0 | ... N26: =ROUND(N48/M$3,3) -> 0
E27: =ROUND(E49/D$3,3) -> 0 | F27: =ROUND(F49/E$3,3) -> 0 | G27: =ROUND(G49/F$3,3) -> 0 | H27: =ROUND(H49/G$3,3) -> 0 | I27: =ROUND(I49/H$3,3) -> 0 | J27: =ROUND(J49/I$3,3) -> 0 | K27: =ROUND(K49/J$3,3) -> 0 | L27: =ROUND(L49/K$3,3) -> 0 | ... N27: =ROUND(N49/M$3,3) -> 0
C28: 职业层面选择属性 | D28: 宝石1 | E28: =ROUND(E50/D$3,3) -> 0.07 | F28: =ROUND(F50/E$3,3) -> 0 | G28: =ROUND(G50/F$3,3) -> 0.041 | H28: =ROUND(H50/G$3,3) -> 0.124 | I28: =ROUND(I50/H$3,3) -> 0.042 | J28: =ROUND(J50/I$3,3) -> 0.073 | K28: =ROUND(K50/J$3,3) -> 0.11 | L28: =ROUND(L50/K$3,3) -> 0.157 | ... N28: =ROUND(N50/M$3,3) -> 0.036
D29: 宝石2 | E29: =ROUND(E51/D$3,3) -> 0.07 | F29: =ROUND(F51/E$3,3) -> 0 | G29: =ROUND(G51/F$3,3) -> 0.041 | H29: =ROUND(H51/G$3,3) -> 0.124 | I29: =ROUND(I51/H$3,3) -> 0.042 | J29: =ROUND(J51/I$3,3) -> 0.073 | K29: =ROUND(K51/J$3,3) -> 0.11 | L29: =ROUND(L51/K$3,3) -> 0.157 | ... N29: =ROUND(N51/M$3,3) -> 0.036
D30: 职业技能被动 | E30: =ROUND(E52/D$3,3) -> 0 | F30: =ROUND(F52/E$3,3) -> 0 | G30: =ROUND(G52/F$3,3) -> 0.13 | H30: =ROUND(H52/G$3,3) -> 0 | I30: =ROUND(I52/H$3,3) -> 0.14 | J30: =ROUND(J52/I$3,3) -> 0 | K30: =ROUND(K52/J$3,3) -> 0.069 | L30: =ROUND(L52/K$3,3) -> 0 | ... N30: =ROUND(N52/M$3,3) -> 0.901
E31: =ROUND(E53/D$3,3) -> 0 | F31: =ROUND(F53/E$3,3) -> 0 | G31: =ROUND(G53/F$3,3) -> 0 | H31: =ROUND(H53/G$3,3) -> 0 | I31: =ROUND(I53/H$3,3) -> 0 | J31: =ROUND(J53/I$3,3) -> 0 | K31: =ROUND(K53/J$3,3) -> 0 | L31: =ROUND(L53/K$3,3) -> 0 | ... N31: =ROUND(N53/M$3,3) -> 0
D32: 合计 | E32: =SUM(E14:E31) -> 1 | F32: =SUM(F14:F31) -> 1 | G32: =SUM(G14:G31) -> 1 | H32: =SUM(H14:H31) -> 1.001 | I32: =SUM(I14:I31) -> 1.001 | J32: =SUM(J14:J31) -> 0.999 | K32: =SUM(K14:K31) -> 0.999 | L32: =SUM(L14:L31) -> 1 | ... N32: =SUM(N14:N31) -> 1
D33: 固定部分比重 | E33: =SUM(E14:E16) -> 0.547 | F33: =SUM(F14:F16) -> 0.377 | G33: =SUM(G14:G16) -> 0.477 | H33: =SUM(H14:H16) -> 0.526 | I33: =SUM(I14:I16) -> 0.357 | J33: =SUM(J14:J16) -> 0.312 | K33: =SUM(K14:K16) -> 0.248 | L33: =SUM(L14:L16) -> 0.686 | ... N33: =SUM(N14:N16) -> 0.027
D35: 属性成长标准投放-模块投放量 | E35: 生命 | F35: 魔法 | G35: 物攻 | H35: 物防 | I35: 法攻 | J35: 法防 | K35: 速度 | L35: 治疗强度 | M35: 控制命中 | N35: 控制抗性
C36: 固定属性 | D36: 装备白属性 | E36: 16.4 | F36: 8.2 | G36: 8.2 | H36: 4.1 | I36: 4.1 | J36: 2.4 | K36: 1.3 | L36: 3 | M36: 0 | N36: 0 | O36: 16.4 | P36: 8.2 | Q36: 8.2 | R36: 4.1 | S36: 4.1 | T36: 2.4 | U36: 1.3 | V36: 3 | W36: 0 | X36: 0
D37: 公会技能 | E37: 10 | F37: 10 | G37: 0 | H37: 0 | I37: 0 | J37: 0 | K37: 0 | L37: 0 | M37: 0 | N37: 0 | O37: 10 | P37: 10 | Q37: 0 | R37: 0 | S37: 0 | T37: 0 | U37: 0 | V37: 0 | W37: 0 | X37: 0
D38: 装备附魔 | E38: 5 | F38: 0 | G38: 1 | H38: 1 | I38: 1 | J38: 1 | K38: 0.5 | L38: 0.5 | M38: 0.3 | N38: 0.3 | O38: 5 | P38: 0 | Q38: 1 | R38: 1 | S38: 1 | T38: 1 | U38: 0.5 | V38: 0.5 | W38: 0.3 | X38: 0.3
E39: 0 | F39: 0 | G39: 0 | H39: 0 | I39: 0 | J39: 0 | K39: 0 | L39: 0 | M39: 0 | N39: 0 | O39: 0 | P39: 0 | Q39: 0 | R39: 0 | S39: 0 | T39: 0 | U39: 0 | V39: 0 | W39: 0 | X39: 0
E40: 0 | F40: 0 | G40: 0 | H40: 0 | I40: 0 | J40: 0 | K40: 0 | L40: 0 | M40: 0 | N40: 0 | O40: 0 | P40: 0 | Q40: 0 | R40: 0 | S40: 0 | T40: 0 | U40: 0 | V40: 0 | W40: 0 | X40: 0
E41: 0 | F41: 0 | G41: 0 | H41: 0 | I41: 0 | J41: 0 | K41: 0 | L41: 0 | M41: 0 | N41: 0 | O41: 0 | P41: 0 | Q41: 0 | R41: 0 | S41: 0 | T41: 0 | U41: 0 | V41: 0 | W41: 0 | X41: 0
E42: 0 | F42: 0 | G42: 0 | H42: 0 | I42: 0 | J42: 0 | K42: 0 | L42: 0 | M42: 0 | N42: 0 | O42: 0 | P42: 0 | Q42: 0 | R42: 0 | S42: 0 | T42: 0 | U42: 0 | V42: 0 | W42: 0 | X42: 0
E43: 0 | F43: 0 | G43: 0 | H43: 0 | I43: 0 | J43: 0 | K43: 0 | L43: 0 | M43: 0 | N43: 0 | O43: 0 | P43: 0 | Q43: 0 | R43: 0 | S43: 0 | T43: 0 | U43: 0 | V43: 0 | W43: 0 | X43: 0
E44: 0 | F44: 0 | G44: 0 | H44: 0 | I44: 0 | J44: 0 | K44: 0 | L44: 0 | M44: 0 | N44: 0 | O44: 0 | P44: 0 | Q44: 0 | R44: 0 | S44: 0 | T44: 0 | U44: 0 | V44: 0 | W44: 0 | X44: 0
C45: 加点层面选择属性 | D45: 自然成长 | E45: 8 | F45: 5 | G45: 1 | H45: 2.2 | I45: 1 | J45: 2.4 | K45: 2.1 | L45: 0 | M45: 0 | N45: 0 | O45: 8 | P45: 5 | Q45: 1 | R45: 2.2 | S45: 1 | T45: 2.4 | U45: 2.1 | V45: 0 | W45: 0 | X45: 0
...

Sheet 一级属性
E2: 该模块标准属性 | G2: 生命 | H2: 魔法 | I2: 物攻 | J2: 物防 | K2: 法攻 | L2: 法防 | M2: 速度 | N2: 治疗强度 | O2: 控制命中 | P2: 控制抗性
F3: 一级点数标准投放（自然成长、加点、装备附加） | G3: =SUM(属性投放!E45:E47) -> 18 | H3: =SUM(属性投放!F45:F47) -> 30 | I3: =SUM(属性投放!G45:G47) -> 6 | J3: =SUM(属性投放!H45:H47) -> 2.2 | K3: =SUM(属性投放!I45:I47) -> 6 | L3: =SUM(属性投放!J45:J47) -> 5.9 | M3: =SUM(属性投放!K45:K47) -> 3.35 | N3: =SUM(属性投放!L45:L47) -> 0 | ... P3: =SUM(属性投放!N45:N47) -> 0
F4: 二级属性能力评分 | G4: =属性价值和能力评分!F6 -> 0.34 | H4: =属性价值和能力评分!G6 -> 0.4 | I4: =属性价值和能力评分!H6 -> 1 | J4: =属性价值和能力评分!I6 -> 2 | K4: =属性价值和能力评分!J6 -> 1.35 | L4: =属性价值和能力评分!K6 -> 1.7 | M4: =属性价值和能力评分!L6 -> 2.5 | N4: =属性价值和能力评分!M6 -> 4 | ... P4: =属性价值和能力评分!O6 -> 1.7
F6: 自然成长加点 | G6: 1 | H6: 1 | I6: 1 | J6: 1 | K6: 1
F7: 职业标准加点 | G7: 体质 | H7: 智力 | I7: 力量 | J7: 耐力 | K7: 敏捷
F8: 战士 | G8: 1 | H8: 0 | I8: 4 | J8: 0 | K8: 0
F9: 圣骑 | G9: 1 | H9: 3 | I9: 0 | J9: 0 | K9: 1
F10: 猎人 | G10: 1 | H10: 0 | I10: 4 | J10: 0 | K10: 0
F11: 德鲁伊 | G11: 1 | H11: 0 | I11: 3 | J11: 1 | K11: 0
F12: 法师 | G12: 1 | H12: 4 | I12: 0 | J12: 0 | K12: 0
F13: 牧师 | G13: 1 | H13: 3 | I13: 0 | J13: 0 | K13: 1
F14: 萨满 | G14: 1 | H14: 4 | I14: 0 | J14: 0 | K14: 0
F15: 盗贼 | G15: 1 | H15: 0 | I15: 4 | J15: 0 | K15: 0
F16: 术士 | G16: 1 | H16: 3 | I16: 0 | J16: 0 | K16: 1
F17: 装备附加点数 | G17: 延续手动比例装备1级点数 | H17: 1.25 | I17: 点
E20: 加点选择层面能力系数
G21: 生命 | H21: 魔法 | I21: 物攻 | J21: 物防 | K21: 法攻 | L21: 法防 | M21: 速度
F22: 体质 | G22: 1 | H22: 0 | I22: 0 | J22: 0 | K22: 0 | L22: 0.4 | M22: 0.13
F23: 智力 | G23: 0 | H23: 1 | I23: 0 | J23: 0 | K23: 1 | L23: 1 | M23: 0
F24: 力量 | G24: 0 | H24: 0 | I24: 1 | J24: 0 | K24: 0 | L24: 0.6 | M24: 0.13
F25: 耐力 | G25: 0 | H25: 0 | I25: 0 | J25: 1 | K25: 0 | L25: 0.4 | M25: 0.13
F26: 敏捷 | G26: 0 | H26: 0 | I26: 0 | J26: 0 | K26: 0 | L26: 0 | M26: 1
E29: 一级属性转换（用来投放二级属性）
G31: 生命 | H31: 魔法 | I31: 物攻 | J31: 物防 | K31: 法攻 | L31: 法防 | M31: 速度 | N31: 加点能力价值
E32: 10 | F32: 体质 | G32: =ROUND(G$3/((VLOOKUP(VLOOKUP(1,属性投放!D$56:$N$65,COLUMNS(属性投放!D$56:$N$65),0),$F$8:$K$16,2,0)*G$22+VLOOKUP(VLOOKUP(1,属性投放!D$56:$N$65,COLUMNS(属性投放!D$56:$N$65),0),$F$8:$K$16,3,0)*G$23+VLOOKUP(VLOOKUP(1,属性投放!D$56:$N$65,COLUMNS(属性投放!D$56:$N$65),0),$F$8:$K$16,4,0)*G$24+VLOOKUP(VLOOKUP(1,属性投放!D$56:$N$65,COLUMNS(属性投放!D$56:$N$65),0),$F$8:$K$16,5,0)*G$25+VLOOKUP(VLOOKUP(1,属性投放!D$56:$N$65,COLUMNS(属性投放!D$56:$N$65),0),$F$8:$K$16,6,0)*G$26)*(5+$H$17)/5+1*SUM(G$22:G$26))*G22,1) -> 8 | H32: =ROUND(H$3/((VLOOKUP(VLOOKUP(1,属性投放!E$56:$N$65,COLUMNS(属性投放!E$56:$N$65),0),$F$8:$K$16,2,0)*H$22+VLOOKUP(VLOOKUP(1,属性投放!E$56:$N$65,COLUMNS(属性投放!E$56:$N$65),0),$F$8:$K$16,3,0)*H$23+VLOOKUP(VLOOKUP(1,属性投放!E$56:$N$65,COLUMNS(属性投放!E$56:$N$65),0),$F$8:$K$16,4,0)*H$24+VLOOKUP(VLOOKUP(1,属性投放!E$56:$N$65,COLUMNS(属性投放!E$56:$N$65),0),$F$8:$K$16,5,0)*H$25+VLOOKUP(VLOOKUP(1,属性投放!E$56:$N$65,COLUMNS(属性投放!E$56:$N$65),0),$F$8:$K$16,6,0)*H$26)*(5+$H$17)/5+1*SUM(H$22:H$26))*H22,1) -> 0 | I32: =ROUND(I$3/((VLOOKUP(VLOOKUP(1,属性投放!F$56:$N$65,COLUMNS(属性投放!F$56:$N$65),0),$F$8:$K$16,2,0)*I$22+VLOOKUP(VLOOKUP(1,属性投放!F$56:$N$65,COLUMNS(属性投放!F$56:$N$65),0),$F$8:$K$16,3,0)*I$23+VLOOKUP(VLOOKUP(1,属性投放!F$56:$N$65,COLUMNS(属性投放!F$56:$N$65),0),$F$8:$K$16,4,0)*I$24+VLOOKUP(VLOOKUP(1,属性投放!F$56:$N$65,COLUMNS(属性投放!F$56:$N$65),0),$F$8:$K$16,5,0)*I$25+VLOOKUP(VLOOKUP(1,属性投放!F$56:$N$65,COLUMNS(属性投放!F$56:$N$65),0),$F$8:$K$16,6,0)*I$26)*(5+$H$17)/5+1*SUM(I$22:I$26))*I22,1) -> 0 | J32: =ROUND(J$3/((VLOOKUP(VLOOKUP(1,属性投放!G$56:$N$65,COLUMNS(属性投放!G$56:$N$65),0),$F$8:$K$16,2,0)*J$22+VLOOKUP(VLOOKUP(1,属性投放!G$56:$N$65,COLUMNS(属性投放!G$56:$N$65),0),$F$8:$K$16,3,0)*J$23+VLOOKUP(VLOOKUP(1,属性投放!G$56:$N$65,COLUMNS(属性投放!G$56:$N$65),0),$F$8:$K$16,4,0)*J$24+VLOOKUP(VLOOKUP(1,属性投放!G$56:$N$65,COLUMNS(属性投放!G$56:$N$65),0),$F$8:$K$16,5,0)*J$25+VLOOKUP(VLOOKUP(1,属性投放!G$56:$N$65,COLUMNS(属性投放!G$56:$N$65),0),$F$8:$K$16,6,0)*J$26)*(5+$H$17)/5+1*SUM(J$22:J$26))*J22,1) -> 0 | K32: =ROUND(K$3/((VLOOKUP(VLOOKUP(1,属性投放!H$56:$N$65,COLUMNS(属性投放!H$56:$N$65),0),$F$8:$K$16,2,0)*K$22+VLOOKUP(VLOOKUP(1,属性投放!H$56:$N$65,COLUMNS(属性投放!H$56:$N$65),0),$F$8:$K$16,3,0)*K$23+VLOOKUP(VLOOKUP(1,属性投放!H$56:$N$65,COLUMNS(属性投放!H$56:$N$65),0),$F$8:$K$16,4,0)*K$24+VLOOKUP(VLOOKUP(1,属性投放!H$56:$N$65,COLUMNS(属性投放!H$56:$N$65),0),$F$8:$K$16,5,0)*K$25+VLOOKUP(VLOOKUP(1,属性投放!H$56:$N$65,COLUMNS(属性投放!H$56:$N$65),0),$F$8:$K$16,6,0)*K$26)*(5+$H$17)/5+1*SUM(K$22:K$26))*K22,1) -> 0 | L32: =ROUND(L$3/((VLOOKUP(VLOOKUP(1,属性投放!I$56:$N$65,COLUMNS(属性投放!I$56:$N$65),0),$F$8:$K$16,2,0)*L$22+VLOOKUP(VLOOKUP(1,属性投放!I$56:$N$65,COLUMNS(属性投放!I$56:$N$65),0),$F$8:$K$16,3,0)*L$23+VLOOKUP(VLOOKUP(1,属性投放!I$56:$N$65,COLUMNS(属性投放!I$56:$N$65),0),$F$8:$K$16,4,0)*L$24+VLOOKUP(VLOOKUP(1,属性投放!I$56:$N$65,COLUMNS(属性投放!I$56:$N$65),0),$F$8:$K$16,5,0)*L$25+VLOOKUP(VLOOKUP(1,属性投放!I$56:$N$65,COLUMNS(属性投放!I$56:$N$65),0),$F$8:$K$16,6,0)*L$26)*(5+$H$17)/5+1*SUM(L$22:L$26))*L22,1) -> 0.4 | M32: =ROUND(M$3/((VLOOKUP(VLOOKUP(1,属性投放!J$56:$N$65,COLUMNS(属性投放!J$56:$N$65),0),$F$8:$K$16,2,0)*M$22+VLOOKUP(VLOOKUP(1,属性投放!J$56:$N$65,COLUMNS(属性投放!J$56:$N$65),0),$F$8:$K$16,3,0)*M$23+VLOOKUP(VLOOKUP(1,属性投放!J$56:$N$65,COLUMNS(属性投放!J$56:$N$65),0),$F$8:$K$16,4,0)*M$24+VLOOKUP(VLOOKUP(1,属性投放!J$56:$N$65,COLUMNS(属性投放!J$56:$N$65),0),$F$8:$K$16,5,0)*M$25+VLOOKUP(VLOOKUP(1,属性投放!J$56:$N$65,COLUMNS(属性投放!J$56:$N$65),0),$F$8:$K$16,6,0)*M$26)*(5+$H$17)/5+1*SUM(M$22:M$26))*M22,1) -> 0.2 | N32: =G32*G$4+H32*H$4+I32*I$4+J32*J$4+K32*K$4+L32*L$4+M32*M$4 -> 3.9
E33: 20 | F33: 智力 | G33: =ROUND(G$3/((VLOOKUP(VLOOKUP(1,属性投放!D$56:$N$65,COLUMNS(属性投放!D$56:$N$65),0),$F$8:$K$16,2,0)*G$22+VLOOKUP(VLOOKUP(1,属性投放!D$56:$N$65,COLUMNS(属性投放!D$56:$N$65),0),$F$8:$K$16,3,0)*G$23+VLOOKUP(VLOOKUP(1,属性投放!D$56:$N$65,COLUMNS(属性投放!D$56:$N$65),0),$F$8:$K$16,4,0)*G$24+VLOOKUP(VLOOKUP(1,属性投放!D$56:$N$65,COLUMNS(属性投放!D$56:$N$65),0),$F$8:$K$16,5,0)*G$25+VLOOKUP(VLOOKUP(1,属性投放!D$56:$N$65,COLUMNS(属性投放!D$56:$N$65),0),$F$8:$K$16,6,0)*G$26)*(5+$H$17)/5+1*SUM(G$22:G$26))*G23,1) -> 0 | H33: =ROUND(H$3/((VLOOKUP(VLOOKUP(1,属性投放!E$56:$N$65,COLUMNS(属性投放!E$56:$N$65),0),$F$8:$K$16,2,0)*H$22+VLOOKUP(VLOOKUP(1,属性投放!E$56:$N$65,COLUMNS(属性投放!E$56:$N$65),0),$F$8:$K$16,3,0)*H$23+VLOOKUP(VLOOKUP(1,属性投放!E$56:$N$65,COLUMNS(属性投放!E$56:$N$65),0),$F$8:$K$16,4,0)*H$24+VLOOKUP(VLOOKUP(1,属性投放!E$56:$N$65,COLUMNS(属性投放!E$56:$N$65),0),$F$8:$K$16,5,0)*H$25+VLOOKUP(VLOOKUP(1,属性投放!E$56:$N$65,COLUMNS(属性投放!E$56:$N$65),0),$F$8:$K$16,6,0)*H$26)*(5+$H$17)/5+1*SUM(H$22:H$26))*H23,1) -> 5 | I33: =ROUND(I$3/((VLOOKUP(VLOOKUP(1,属性投放!F$56:$N$65,COLUMNS(属性投放!F$56:$N$65),0),$F$8:$K$16,2,0)*I$22+VLOOKUP(VLOOKUP(1,属性投放!F$56:$N$65,COLUMNS(属性投放!F$56:$N$65),0),$F$8:$K$16,3,0)*I$23+VLOOKUP(VLOOKUP(1,属性投放!F$56:$N$65,COLUMNS(属性投放!F$56:$N$65),0),$F$8:$K$16,4,0)*I$24+VLOOKUP(VLOOKUP(1,属性投放!F$56:$N$65,COLUMNS(属性投放!F$56:$N$65),0),$F$8:$K$16,5,0)*I$25+VLOOKUP(VLOOKUP(1,属性投放!F$56:$N$65,COLUMNS(属性投放!F$56:$N$65),0),$F$8:$K$16,6,0)*I$26)*(5+$H$17)/5+1*SUM(I$22:I$26))*I23,1) -> 0 | J33: =ROUND(J$3/((VLOOKUP(VLOOKUP(1,属性投放!G$56:$N$65,COLUMNS(属性投放!G$56:$N$65),0),$F$8:$K$16,2,0)*J$22+VLOOKUP(VLOOKUP(1,属性投放!G$56:$N$65,COLUMNS(属性投放!G$56:$N$65),0),$F$8:$K$16,3,0)*J$23+VLOOKUP(VLOOKUP(1,属性投放!G$56:$N$65,COLUMNS(属性投放!G$56:$N$65),0),$F$8:$K$16,4,0)*J$24+VLOOKUP(VLOOKUP(1,属性投放!G$56:$N$65,COLUMNS(属性投放!G$56:$N$65),0),$F$8:$K$16,5,0)*J$25+VLOOKUP(VLOOKUP(1,属性投放!G$56:$N$65,COLUMNS(属性投放!G$56:$N$65),0),$F$8:$K$16,6,0)*J$26)*(5+$H$17)/5+1*SUM(J$22:J$26))*J23,1) -> 0 | K33: =ROUND(K$3/((VLOOKUP(VLOOKUP(1,属性投放!H$56:$N$65,COLUMNS(属性投放!H$56:$N$65),0),$F$8:$K$16,2,0)*K$22+VLOOKUP(VLOOKUP(1,属性投放!H$56:$N$65,COLUMNS(属性投放!H$56:$N$65),0),$F$8:$K$16,3,0)*K$23+VLOOKUP(VLOOKUP(1,属性投放!H$56:$N$65,COLUMNS(属性投放!H$56:$N$65),0),$F$8:$K$16,4,0)*K$24+VLOOKUP(VLOOKUP(1,属性投放!H$56:$N$65,COLUMNS(属性投放!H$56:$N$65),0),$F$8:$K$16,5,0)*K$25+VLOOKUP(VLOOKUP(1,属性投放!H$56:$N$65,COLUMNS(属性投放!H$56:$N$65),0),$F$8:$K$16,6,0)*K$26)*(5+$H$17)/5+1*SUM(K$22:K$26))*K23,1) -> 1 | L33: =ROUND(L$3/((VLOOKUP(VLOOKUP(1,属性投放!I$56:$N$65,COLUMNS(属性投放!I$56:$N$65),0),$F$8:$K$16,2,0)*L$22+VLOOKUP(VLOOKUP(1,属性投放!I$56:$N$65,COLUMNS(属性投放!I$56:$N$65),0),$F$8:$K$16,3,0)*L$23+VLOOKUP(VLOOKUP(1,属性投放!I$56:$N$65,COLUMNS(属性投放!I$56:$N$65),0),$F$8:$K$16,4,0)*L$24+VLOOKUP(VLOOKUP(1,属性投放!I$56:$N$65,COLUMNS(属性投放!I$56:$N$65),0),$F$8:$K$16,5,0)*L$25+VLOOKUP(VLOOKUP(1,属性投放!I$56:$N$65,COLUMNS(属性投放!I$56:$N$65),0),$F$8:$K$16,6,0)*L$26)*(5+$H$17)/5+1*SUM(L$22:L$26))*L23,1) -> 1 | M33: =ROUND(M$3/((VLOOKUP(VLOOKUP(1,属性投放!J$56:$N$65,COLUMNS(属性投放!J$56:$N$65),0),$F$8:$K$16,2,0)*M$22+VLOOKUP(VLOOKUP(1,属性投放!J$56:$N$65,COLUMNS(属性投放!J$56:$N$65),0),$F$8:$K$16,3,0)*M$23+VLOOKUP(VLOOKUP(1,属性投放!J$56:$N$65,COLUMNS(属性投放!J$56:$N$65),0),$F$8:$K$16,4,0)*M$24+VLOOKUP(VLOOKUP(1,属性投放!J$56:$N$65,COLUMNS(属性投放!J$56:$N$65),0),$F$8:$K$16,5,0)*M$25+VLOOKUP(VLOOKUP(1,属性投放!J$56:$N$65,COLUMNS(属性投放!J$56:$N$65),0),$F$8:$K$16,6,0)*M$26)*(5+$H$17)/5+1*SUM(M$22:M$26))*M23,1) -> 0 | N33: =G33*G$4+H33*H$4+I33*I$4+J33*J$4+K33*K$4+L33*L$4+M33*M$4 -> 5.05
E34: 30 | F34: 力量 | G34: =ROUND(G$3/((VLOOKUP(VLOOKUP(1,属性投放!D$56:$N$65,COLUMNS(属性投放!D$56:$N$65),0),$F$8:$K$16,2,0)*G$22+VLOOKUP(VLOOKUP(1,属性投放!D$56:$N$65,COLUMNS(属性投放!D$56:$N$65),0),$F$8:$K$16,3,0)*G$23+VLOOKUP(VLOOKUP(1,属性投放!D$56:$N$65,COLUMNS(属性投放!D$56:$N$65),0),$F$8:$K$16,4,0)*G$24+VLOOKUP(VLOOKUP(1,属性投放!D$56:$N$65,COLUMNS(属性投放!D$56:$N$65),0),$F$8:$K$16,5,0)*G$25+VLOOKUP(VLOOKUP(1,属性投放!D$56:$N$65,COLUMNS(属性投放!D$56:$N$65),0),$F$8:$K$16,6,0)*G$26)*(5+$H$17)/5+1*SUM(G$22:G$26))*G24,1) -> 0 | H34: =ROUND(H$3/((VLOOKUP(VLOOKUP(1,属性投放!E$56:$N$65,COLUMNS(属性投放!E$56:$N$65),0),$F$8:$K$16,2,0)*H$22+VLOOKUP(VLOOKUP(1,属性投放!E$56:$N$65,COLUMNS(属性投放!E$56:$N$65),0),$F$8:$K$16,3,0)*H$23+VLOOKUP(VLOOKUP(1,属性投放!E$56:$N$65,COLUMNS(属性投放!E$56:$N$65),0),$F$8:$K$16,4,0)*H$24+VLOOKUP(VLOOKUP(1,属性投放!E$56:$N$65,COLUMNS(属性投放!E$56:$N$65),0),$F$8:$K$16,5,0)*H$25+VLOOKUP(VLOOKUP(1,属性投放!E$56:$N$65,COLUMNS(属性投放!E$56:$N$65),0),$F$8:$K$16,6,0)*H$26)*(5+$H$17)/5+1*SUM(H$22:H$26))*H24,1) -> 0 | I34: =ROUND(I$3/((VLOOKUP(VLOOKUP(1,属性投放!F$56:$N$65,COLUMNS(属性投放!F$56:$N$65),0),$F$8:$K$16,2,0)*I$22+VLOOKUP(VLOOKUP(1,属性投放!F$56:$N$65,COLUMNS(属性投放!F$56:$N$65),0),$F$8:$K$16,3,0)*I$23+VLOOKUP(VLOOKUP(1,属性投放!F$56:$N$65,COLUMNS(属性投放!F$56:$N$65),0),$F$8:$K$16,4,0)*I$24+VLOOKUP(VLOOKUP(1,属性投放!F$56:$N$65,COLUMNS(属性投放!F$56:$N$65),0),$F$8:$K$16,5,0)*I$25+VLOOKUP(VLOOKUP(1,属性投放!F$56:$N$65,COLUMNS(属性投放!F$56:$N$65),0),$F$8:$K$16,6,0)*I$26)*(5+$H$17)/5+1*SUM(I$22:I$26))*I24,1) -> 1 | J34: =ROUND(J$3/((VLOOKUP(VLOOKUP(1,属性投放!G$56:$N$65,COLUMNS(属性投放!G$56:$N$65),0),$F$8:$K$16,2,0)*J$22+VLOOKUP(VLOOKUP(1,属性投放!G$56:$N$65,COLUMNS(属性投放!G$56:$N$65),0),$F$8:$K$16,3,0)*J$23+VLOOKUP(VLOOKUP(1,属性投放!G$56:$N$65,COLUMNS(属性投放!G$56:$N$65),0),$F$8:$K$16,4,0)*J$24+VLOOKUP(VLOOKUP(1,属性投放!G$56:$N$65,COLUMNS(属性投放!G$56:$N$65),0),$F$8:$K$16,5,0)*J$25+VLOOKUP(VLOOKUP(1,属性投放!G$56:$N$65,COLUMNS(属性投放!G$56:$N$65),0),$F$8:$K$16,6,0)*J$26)*(5+$H$17)/5+1*SUM(J$22:J$26))*J24,1) -> 0 | K34: =ROUND(K$3/((VLOOKUP(VLOOKUP(1,属性投放!H$56:$N$65,COLUMNS(属性投放!H$56:$N$65),0),$F$8:$K$16,2,0)*K$22+VLOOKUP(VLOOKUP(1,属性投放!H$56:$N$65,COLUMNS(属性投放!H$56:$N$65),0),$F$8:$K$16,3,0)*K$23+VLOOKUP(VLOOKUP(1,属性投放!H$56:$N$65,COLUMNS(属性投放!H$56:$N$65),0),$F$8:$K$16,4,0)*K$24+VLOOKUP(VLOOKUP(1,属性投放!H$56:$N$65,COLUMNS(属性投放!H$56:$N$65),0),$F$8:$K$16,5,0)*K$25+VLOOKUP(VLOOKUP(1,属性投放!H$56:$N$65,COLUMNS(属性投放!H$56:$N$65),0),$F$8:$K$16,6,0)*K$26)*(5+$H$17)/5+1*SUM(K$22:K$26))*K24,1) -> 0 | L34: =ROUND(L$3/((VLOOKUP(VLOOKUP(1,属性投放!I$56:$N$65,COLUMNS(属性投放!I$56:$N$65),0),$F$8:$K$16,2,0)*L$22+VLOOKUP(VLOOKUP(1,属性投放!I$56:$N$65,COLUMNS(属性投放!I$56:$N$65),0),$F$8:$K$16,3,0)*L$23+VLOOKUP(VLOOKUP(1,属性投放!I$56:$N$65,COLUMNS(属性投放!I$56:$N$65),0),$F$8:$K$16,4,0)*L$24+VLOOKUP(VLOOKUP(1,属性投放!I$56:$N$65,COLUMNS(属性投放!I$56:$N$65),0),$F$8:$K$16,5,0)*L$25+VLOOKUP(VLOOKUP(1,属性投放!I$56:$N$65,COLUMNS(属性投放!I$56:$N$65),0),$F$8:$K$16,6,0)*L$26)*(5+$H$17)/5+1*SUM(L$22:L$26))*L24,1) -> 0.6 | M34: =ROUND(M$3/((VLOOKUP(VLOOKUP(1,属性投放!J$56:$N$65,COLUMNS(属性投放!J$56:$N$65),0),$F$8:$K$16,2,0)*M$22+VLOOKUP(VLOOKUP(1,属性投放!J$56:$N$65,COLUMNS(属性投放!J$56:$N$65),0),$F$8:$K$16,3,0)*M$23+VLOOKUP(VLOOKUP(1,属性投放!J$56:$N$65,COLUMNS(属性投放!J$56:$N$65),0),$F$8:$K$16,4,0)*M$24+VLOOKUP(VLOOKUP(1,属性投放!J$56:$N$65,COLUMNS(属性投放!J$56:$N$65),0),$F$8:$K$16,5,0)*M$25+VLOOKUP(VLOOKUP(1,属性投放!J$56:$N$65,COLUMNS(属性投放!J$56:$N$65),0),$F$8:$K$16,6,0)*M$26)*(5+$H$17)/5+1*SUM(M$22:M$26))*M24,1) -> 0.2 | N34: =G34*G$4+H34*H$4+I34*I$4+J34*J$4+K34*K$4+L34*L$4+M34*M$4 -> 2.52
E35: 40 | F35: 耐力 | G35: =ROUND(G$3/((VLOOKUP(VLOOKUP(1,属性投放!D$56:$N$65,COLUMNS(属性投放!D$56:$N$65),0),$F$8:$K$16,2,0)*G$22+VLOOKUP(VLOOKUP(1,属性投放!D$56:$N$65,COLUMNS(属性投放!D$56:$N$65),0),$F$8:$K$16,3,0)*G$23+VLOOKUP(VLOOKUP(1,属性投放!D$56:$N$65,COLUMNS(属性投放!D$56:$N$65),0),$F$8:$K$16,4,0)*G$24+VLOOKUP(VLOOKUP(1,属性投放!D$56:$N$65,COLUMNS(属性投放!D$56:$N$65),0),$F$8:$K$16,5,0)*G$25+VLOOKUP(VLOOKUP(1,属性投放!D$56:$N$65,COLUMNS(属性投放!D$56:$N$65),0),$F$8:$K$16,6,0)*G$26)*(5+$H$17)/5+1*SUM(G$22:G$26))*G25,1) -> 0 | H35: =ROUND(H$3/((VLOOKUP(VLOOKUP(1,属性投放!E$56:$N$65,COLUMNS(属性投放!E$56:$N$65),0),$F$8:$K$16,2,0)*H$22+VLOOKUP(VLOOKUP(1,属性投放!E$56:$N$65,COLUMNS(属性投放!E$56:$N$65),0),$F$8:$K$16,3,0)*H$23+VLOOKUP(VLOOKUP(1,属性投放!E$56:$N$65,COLUMNS(属性投放!E$56:$N$65),0),$F$8:$K$16,4,0)*H$24+VLOOKUP(VLOOKUP(1,属性投放!E$56:$N$65,COLUMNS(属性投放!E$56:$N$65),0),$F$8:$K$16,5,0)*H$25+VLOOKUP(VLOOKUP(1,属性投放!E$56:$N$65,COLUMNS(属性投放!E$56:$N$65),0),$F$8:$K$16,6,0)*H$26)*(5+$H$17)/5+1*SUM(H$22:H$26))*H25,1) -> 0 | I35: =ROUND(I$3/((VLOOKUP(VLOOKUP(1,属性投放!F$56:$N$65,COLUMNS(属性投放!F$56:$N$65),0),$F$8:$K$16,2,0)*I$22+VLOOKUP(VLOOKUP(1,属性投放!F$56:$N$65,COLUMNS(属性投放!F$56:$N$65),0),$F$8:$K$16,3,0)*I$23+VLOOKUP(VLOOKUP(1,属性投放!F$56:$N$65,COLUMNS(属性投放!F$56:$N$65),0),$F$8:$K$16,4,0)*I$24+VLOOKUP(VLOOKUP(1,属性投放!F$56:$N$65,COLUMNS(属性投放!F$56:$N$65),0),$F$8:$K$16,5,0)*I$25+VLOOKUP(VLOOKUP(1,属性投放!F$56:$N$65,COLUMNS(属性投放!F$56:$N$65),0),$F$8:$K$16,6,0)*I$26)*(5+$H$17)/5+1*SUM(I$22:I$26))*I25,1) -> 0 | J35: =ROUND(J$3/((VLOOKUP(VLOOKUP(1,属性投放!G$56:$N$65,COLUMNS(属性投放!G$56:$N$65),0),$F$8:$K$16,2,0)*J$22+VLOOKUP(VLOOKUP(1,属性投放!G$56:$N$65,COLUMNS(属性投放!G$56:$N$65),0),$F$8:$K$16,3,0)*J$23+VLOOKUP(VLOOKUP(1,属性投放!G$56:$N$65,COLUMNS(属性投放!G$56:$N$65),0),$F$8:$K$16,4,0)*J$24+VLOOKUP(VLOOKUP(1,属性投放!G$56:$N$65,COLUMNS(属性投放!G$56:$N$65),0),$F$8:$K$16,5,0)*J$25+VLOOKUP(VLOOKUP(1,属性投放!G$56:$N$65,COLUMNS(属性投放!G$56:$N$65),0),$F$8:$K$16,6,0)*J$26)*(5+$H$17)/5+1*SUM(J$22:J$26))*J25,1) -> 2.2 | K35: =ROUND(K$3/((VLOOKUP(VLOOKUP(1,属性投放!H$56:$N$65,COLUMNS(属性投放!H$56:$N$65),0),$F$8:$K$16,2,0)*K$22+VLOOKUP(VLOOKUP(1,属性投放!H$56:$N$65,COLUMNS(属性投放!H$56:$N$65),0),$F$8:$K$16,3,0)*K$23+VLOOKUP(VLOOKUP(1,属性投放!H$56:$N$65,COLUMNS(属性投放!H$56:$N$65),0),$F$8:$K$16,4,0)*K$24+VLOOKUP(VLOOKUP(1,属性投放!H$56:$N$65,COLUMNS(属性投放!H$56:$N$65),0),$F$8:$K$16,5,0)*K$25+VLOOKUP(VLOOKUP(1,属性投放!H$56:$N$65,COLUMNS(属性投放!H$56:$N$65),0),$F$8:$K$16,6,0)*K$26)*(5+$H$17)/5+1*SUM(K$22:K$26))*K25,1) -> 0 | L35: =ROUND(L$3/((VLOOKUP(VLOOKUP(1,属性投放!I$56:$N$65,COLUMNS(属性投放!I$56:$N$65),0),$F$8:$K$16,2,0)*L$22+VLOOKUP(VLOOKUP(1,属性投放!I$56:$N$65,COLUMNS(属性投放!I$56:$N$65),0),$F$8:$K$16,3,0)*L$23+VLOOKUP(VLOOKUP(1,属性投放!I$56:$N$65,COLUMNS(属性投放!I$56:$N$65),0),$F$8:$K$16,4,0)*L$24+VLOOKUP(VLOOKUP(1,属性投放!I$56:$N$65,COLUMNS(属性投放!I$56:$N$65),0),$F$8:$K$16,5,0)*L$25+VLOOKUP(VLOOKUP(1,属性投放!I$56:$N$65,COLUMNS(属性投放!I$56:$N$65),0),$F$8:$K$16,6,0)*L$26)*(5+$H$17)/5+1*SUM(L$22:L$26))*L25,1) -> 0.4 | M35: =ROUND(M$3/((VLOOKUP(VLOOKUP(1,属性投放!J$56:$N$65,COLUMNS(属性投放!J$56:$N$65),0),$F$8:$K$16,2,0)*M$22+VLOOKUP(VLOOKUP(1,属性投放!J$56:$N$65,COLUMNS(属性投放!J$56:$N$65),0),$F$8:$K$16,3,0)*M$23+VLOOKUP(VLOOKUP(1,属性投放!J$56:$N$65,COLUMNS(属性投放!J$56:$N$65),0),$F$8:$K$16,4,0)*M$24+VLOOKUP(VLOOKUP(1,属性投放!J$56:$N$65,COLUMNS(属性投放!J$56:$N$65),0),$F$8:$K$16,5,0)*M$25+VLOOKUP(VLOOKUP(1,属性投放!J$56:$N$65,COLUMNS(属性投放!J$56:$N$65),0),$F$8:$K$16,6,0)*M$26)*(5+$H$17)/5+1*SUM(M$22:M$26))*M25,1) -> 0.2 | N35: =G35*G$4+H35*H$4+I35*I$4+J35*J$4+K35*K$4+L35*L$4+M35*M$4 -> 5.58
E36: 50 | F36: 敏捷 | G36: =ROUND(G$3/((VLOOKUP(VLOOKUP(1,属性投放!D$56:$N$65,COLUMNS(属性投放!D$56:$N$65),0),$F$8:$K$16,2,0)*G$22+VLOOKUP(VLOOKUP(1,属性投放!D$56:$N$65,COLUMNS(属性投放!D$56:$N$65),0),$F$8:$K$16,3,0)*G$23+VLOOKUP(VLOOKUP(1,属性投放!D$56:$N$65,COLUMNS(属性投放!D$56:$N$65),0),$F$8:$K$16,4,0)*G$24+VLOOKUP(VLOOKUP(1,属性投放!D$56:$N$65,COLUMNS(属性投放!D$56:$N$65),0),$F$8:$K$16,5,0)*G$25+VLOOKUP(VLOOKUP(1,属性投放!D$56:$N$65,COLUMNS(属性投放!D$56:$N$65),0),$F$8:$K$16,6,0)*G$26)*(5+$H$17)/5+1*SUM(G$22:G$26))*G26,1) -> 0 | H36: =ROUND(H$3/((VLOOKUP(VLOOKUP(1,属性投放!E$56:$N$65,COLUMNS(属性投放!E$56:$N$65),0),$F$8:$K$16,2,0)*H$22+VLOOKUP(VLOOKUP(1,属性投放!E$56:$N$65,COLUMNS(属性投放!E$56:$N$65),0),$F$8:$K$16,3,0)*H$23+VLOOKUP(VLOOKUP(1,属性投放!E$56:$N$65,COLUMNS(属性投放!E$56:$N$65),0),$F$8:$K$16,4,0)*H$24+VLOOKUP(VLOOKUP(1,属性投放!E$56:$N$65,COLUMNS(属性投放!E$56:$N$65),0),$F$8:$K$16,5,0)*H$25+VLOOKUP(VLOOKUP(1,属性投放!E$56:$N$65,COLUMNS(属性投放!E$56:$N$65),0),$F$8:$K$16,6,0)*H$26)*(5+$H$17)/5+1*SUM(H$22:H$26))*H26,1) -> 0 | I36: =ROUND(I$3/((VLOOKUP(VLOOKUP(1,属性投放!F$56:$N$65,COLUMNS(属性投放!F$56:$N$65),0),$F$8:$K$16,2,0)*I$22+VLOOKUP(VLOOKUP(1,属性投放!F$56:$N$65,COLUMNS(属性投放!F$56:$N$65),0),$F$8:$K$16,3,0)*I$23+VLOOKUP(VLOOKUP(1,属性投放!F$56:$N$65,COLUMNS(属性投放!F$56:$N$65),0),$F$8:$K$16,4,0)*I$24+VLOOKUP(VLOOKUP(1,属性投放!F$56:$N$65,COLUMNS(属性投放!F$56:$N$65),0),$F$8:$K$16,5,0)*I$25+VLOOKUP(VLOOKUP(1,属性投放!F$56:$N$65,COLUMNS(属性投放!F$56:$N$65),0),$F$8:$K$16,6,0)*I$26)*(5+$H$17)/5+1*SUM(I$22:I$26))*I26,1) -> 0 | J36: =ROUND(J$3/((VLOOKUP(VLOOKUP(1,属性投放!G$56:$N$65,COLUMNS(属性投放!G$56:$N$65),0),$F$8:$K$16,2,0)*J$22+VLOOKUP(VLOOKUP(1,属性投放!G$56:$N$65,COLUMNS(属性投放!G$56:$N$65),0),$F$8:$K$16,3,0)*J$23+VLOOKUP(VLOOKUP(1,属性投放!G$56:$N$65,COLUMNS(属性投放!G$56:$N$65),0),$F$8:$K$16,4,0)*J$24+VLOOKUP(VLOOKUP(1,属性投放!G$56:$N$65,COLUMNS(属性投放!G$56:$N$65),0),$F$8:$K$16,5,0)*J$25+VLOOKUP(VLOOKUP(1,属性投放!G$56:$N$65,COLUMNS(属性投放!G$56:$N$65),0),$F$8:$K$16,6,0)*J$26)*(5+$H$17)/5+1*SUM(J$22:J$26))*J26,1) -> 0 | K36: =ROUND(K$3/((VLOOKUP(VLOOKUP(1,属性投放!H$56:$N$65,COLUMNS(属性投放!H$56:$N$65),0),$F$8:$K$16,2,0)*K$22+VLOOKUP(VLOOKUP(1,属性投放!H$56:$N$65,COLUMNS(属性投放!H$56:$N$65),0),$F$8:$K$16,3,0)*K$23+VLOOKUP(VLOOKUP(1,属性投放!H$56:$N$65,COLUMNS(属性投放!H$56:$N$65),0),$F$8:$K$16,4,0)*K$24+VLOOKUP(VLOOKUP(1,属性投放!H$56:$N$65,COLUMNS(属性投放!H$56:$N$65),0),$F$8:$K$16,5,0)*K$25+VLOOKUP(VLOOKUP(1,属性投放!H$56:$N$65,COLUMNS(属性投放!H$56:$N$65),0),$F$8:$K$16,6,0)*K$26)*(5+$H$17)/5+1*SUM(K$22:K$26))*K26,1) -> 0 | L36: =ROUND(L$3/((VLOOKUP(VLOOKUP(1,属性投放!I$56:$N$65,COLUMNS(属性投放!I$56:$N$65),0),$F$8:$K$16,2,0)*L$22+VLOOKUP(VLOOKUP(1,属性投放!I$56:$N$65,COLUMNS(属性投放!I$56:$N$65),0),$F$8:$K$16,3,0)*L$23+VLOOKUP(VLOOKUP(1,属性投放!I$56:$N$65,COLUMNS(属性投放!I$56:$N$65),0),$F$8:$K$16,4,0)*L$24+VLOOKUP(VLOOKUP(1,属性投放!I$56:$N$65,COLUMNS(属性投放!I$56:$N$65),0),$F$8:$K$16,5,0)*L$25+VLOOKUP(VLOOKUP(1,属性投放!I$56:$N$65,COLUMNS(属性投放!I$56:$N$65),0),$F$8:$K$16,6,0)*L$26)*(5+$H$17)/5+1*SUM(L$22:L$26))*L26,1) -> 0 | M36: =ROUND(M$3/((VLOOKUP(VLOOKUP(1,属性投放!J$56:$N$65,COLUMNS(属性投放!J$56:$N$65),0),$F$8:$K$16,2,0)*M$22+VLOOKUP(VLOOKUP(1,属性投放!J$56:$N$65,COLUMNS(属性投放!J$56:$N$65),0),$F$8:$K$16,3,0)*M$23+VLOOKUP(VLOOKUP(1,属性投放!J$56:$N$65,COLUMNS(属性投放!J$56:$N$65),0),$F$8:$K$16,4,0)*M$24+VLOOKUP(VLOOKUP(1,属性投放!J$56:$N$65,COLUMNS(属性投放!J$56:$N$65),0),$F$8:$K$16,5,0)*M$25+VLOOKUP(VLOOKUP(1,属性投放!J$56:$N$65,COLUMNS(属性投放!J$56:$N$65),0),$F$8:$K$16,6,0)*M$26)*(5+$H$17)/5+1*SUM(M$22:M$26))*M26,1) -> 1.5 | N36: =G36*G$4+H36*H$4+I36*I$4+J36*J$4+K36*K$4+L36*L$4+M36*M$4 -> 3.75
F37: 每级自然成长 | G37: =SUM(G32:G36) -> 8 | H37: =SUM(H32:H36) -> 5 | I37: =SUM(I32:I36) -> 1 | J37: =SUM(J32:J36) -> 2.2 | K37: =SUM(K32:K36) -> 1 | L37: =SUM(L32:L36) -> 2.4 | M37: =SUM(M32:M36) -> 2.1
F38: 加1点最大投放量 | G38: =MAX(G32:G36) -> 8 | H38: =MAX(H32:H36) -> 5 | I38: =MAX(I32:I36) -> 1 | J38: =MAX(J32:J36) -> 2.2 | K38: =MAX(K32:K36) -> 1 | L38: =MAX(L32:L36) -> 1 | M38: =MAX(M32:M36) -> 1.5
F39: 手动加点各属性极限 | G39: =G38*5 -> 40 | H39: =H38*5 -> 25 | I39: =I38*5 -> 5 | J39: =J38*5 -> 11 | K39: =K38*5 -> 5 | L39: =L38*5 -> 5 | M39: =M38*5 -> 7.5
E40: 选择加点属性
F41: 加点方式 | G41: 生命 | H41: 魔法 | I41: 物攻 | J41: 物防 | K41: 法攻 | L41: 法防 | M41: 速度 | N41: 治疗强度 | O41: 控制命中 | P41: 控制抗性
E42: 物攻推荐 | F42: 10400 | G42: =G$32*MID($F42,1,1)+G$33*MID($F42,2,1)+G$34*MID($F42,3,1)+G$35*MID($F42,4,1)+G$36*MID($F42,5,1) -> 8 | H42: =H$32*MID($F42,1,1)+H$33*MID($F42,2,1)+H$34*MID($F42,3,1)+H$35*MID($F42,4,1)+H$36*MID($F42,5,1) -> 0 | I42: =I$32*MID($F42,1,1)+I$33*MID($F42,2,1)+I$34*MID($F42,3,1)+I$35*MID($F42,4,1)+I$36*MID($F42,5,1) -> 4 | J42: =J$32*MID($F42,1,1)+J$33*MID($F42,2,1)+J$34*MID($F42,3,1)+J$35*MID($F42,4,1)+J$36*MID($F42,5,1) -> 0 | K42: =K$32*MID($F42,1,1)+K$33*MID($F42,2,1)+K$34*MID($F42,3,1)+K$35*MID($F42,4,1)+K$36*MID($F42,5,1) -> 0 | L42: =L$32*MID($F42,1,1)+L$33*MID($F42,2,1)+L$34*MID($F42,3,1)+L$35*MID($F42,4,1)+L$36*MID($F42,5,1) -> 2.8 | M42: =M$32*MID($F42,1,1)+M$33*MID($F42,2,1)+M$34*MID($F42,3,1)+M$35*MID($F42,4,1)+M$36*MID($F42,5,1) -> 1 | N42: 0 | O42: 0 | P42: 0
E43: 法攻推荐 | F43: 14000 | G43: =G$32*MID($F43,1,1)+G$33*MID($F43,2,1)+G$34*MID($F43,3,1)+G$35*MID($F43,4,1)+G$36*MID($F43,5,1) -> 8 | H43: =H$32*MID($F43,1,1)+H$33*MID($F43,2,1)+H$34*MID($F43,3,1)+H$35*MID($F43,4,1)+H$36*MID($F43,5,1) -> 20 | I43: =I$32*MID($F43,1,1)+I$33*MID($F43,2,1)+I$34*MID($F43,3,1)+I$35*MID($F43,4,1)+I$36*MID($F43,5,1) -> 0 | J43: =J$32*MID($F43,1,1)+J$33*MID($F43,2,1)+J$34*MID($F43,3,1)+J$35*MID($F43,4,1)+J$36*MID($F43,5,1) -> 0 | K43: =K$32*MID($F43,1,1)+K$33*MID($F43,2,1)+K$34*MID($F43,3,1)+K$35*MID($F43,4,1)+K$36*MID($F43,5,1) -> 4 | L43: =L$32*MID($F43,1,1)+L$33*MID($F43,2,1)+L$34*MID($F43,3,1)+L$35*MID($F43,4,1)+L$36*MID($F43,5,1) -> 4.4 | M43: =M$32*MID($F43,1,1)+M$33*MID($F43,2,1)+M$34*MID($F43,3,1)+M$35*MID($F43,4,1)+M$36*MID($F43,5,1) -> 0.2 | N43: 0 | O43: 0 | P43: 0
E44: 物控推荐 | F44: 10301 | G44: =G$32*MID($F44,1,1)+G$33*MID($F44,2,1)+G$34*MID($F44,3,1)+G$35*MID($F44,4,1)+G$36*MID($F44,5,1) -> 8 | H44: =H$32*MID($F44,1,1)+H$33*MID($F44,2,1)+H$34*MID($F44,3,1)+H$35*MID($F44,4,1)+H$36*MID($F44,5,1) -> 0 | I44: =I$32*MID($F44,1,1)+I$33*MID($F44,2,1)+I$34*MID($F44,3,1)+I$35*MID($F44,4,1)+I$36*MID($F44,5,1) -> 3 | J44: =J$32*MID($F44,1,1)+J$33*MID($F44,2,1)+J$34*MID($F44,3,1)+J$35*MID($F44,4,1)+J$36*MID($F44,5,1) -> 0 | K44: =K$32*MID($F44,1,1)+K$33*MID($F44,2,1)+K$34*MID($F44,3,1)+K$35*MID($F44,4,1)+K$36*MID($F44,5,1) -> 0 | L44: =L$32*MID($F44,1,1)+L$33*MID($F44,2,1)+L$34*MID($F44,3,1)+L$35*MID($F44,4,1)+L$36*MID($F44,5,1) -> 2.2 | M44: =M$32*MID($F44,1,1)+M$33*MID($F44,2,1)+M$34*MID($F44,3,1)+M$35*MID($F44,4,1)+M$36*MID($F44,5,1) -> 2.3 | N44: 0 | O44: 0 | P44: 0
E45: 法控推荐 | F45: 13001 | G45: =G$32*MID($F45,1,1)+G$33*MID($F45,2,1)+G$34*MID($F45,3,1)+G$35*MID($F45,4,1)+G$36*MID($F45,5,1) -> 8 | H45: =H$32*MID($F45,1,1)+H$33*MID($F45,2,1)+H$34*MID($F45,3,1)+H$35*MID($F45,4,1)+H$36*MID($F45,5,1) -> 15 | I45: =I$32*MID($F45,1,1)+I$33*MID($F45,2,1)+I$34*MID($F45,3,1)+I$35*MID($F45,4,1)+I$36*MID($F45,5,1) -> 0 | J45: =J$32*MID($F45,1,1)+J$33*MID($F45,2,1)+J$34*MID($F45,3,1)+J$35*MID($F45,4,1)+J$36*MID($F45,5,1) -> 0 | K45: =K$32*MID($F45,1,1)+K$33*MID($F45,2,1)+K$34*MID($F45,3,1)+K$35*MID($F45,4,1)+K$36*MID($F45,5,1) -> 3 | L45: =L$32*MID($F45,1,1)+L$33*MID($F45,2,1)+L$34*MID($F45,3,1)+L$35*MID($F45,4,1)+L$36*MID($F45,5,1) -> 3.4 | M45: =M$32*MID($F45,1,1)+M$33*MID($F45,2,1)+M$34*MID($F45,3,1)+M$35*MID($F45,4,1)+M$36*MID($F45,5,1) -> 1.7 | N45: 0 | O45: 0 | P45: 0
E46: 物辅推荐 | F46: 10310 | G46: =G$32*MID($F46,1,1)+G$33*MID($F46,2,1)+G$34*MID($F46,3,1)+G$35*MID($F46,4,1)+G$36*MID($F46,5,1) -> 8 | H46: =H$32*MID($F46,1,1)+H$33*MID($F46,2,1)+H$34*MID($F46,3,1)+H$35*MID($F46,4,1)+H$36*MID($F46,5,1) -> 0 | I46: =I$32*MID($F46,1,1)+I$33*MID($F46,2,1)+I$34*MID($F46,3,1)+I$35*MID($F46,4,1)+I$36*MID($F46,5,1) -> 3 | J46: =J$32*MID($F46,1,1)+J$33*MID($F46,2,1)+J$34*MID($F46,3,1)+J$35*MID($F46,4,1)+J$36*MID($F46,5,1) -> 2.2 | K46: =K$32*MID($F46,1,1)+K$33*MID($F46,2,1)+K$34*MID($F46,3,1)+K$35*MID($F46,4,1)+K$36*MID($F46,5,1) -> 0 | L46: =L$32*MID($F46,1,1)+L$33*MID($F46,2,1)+L$34*MID($F46,3,1)+L$35*MID($F46,4,1)+L$36*MID($F46,5,1) -> 2.6 | M46: =M$32*MID($F46,1,1)+M$33*MID($F46,2,1)+M$34*MID($F46,3,1)+M$35*MID($F46,4,1)+M$36*MID($F46,5,1) -> 1 | N46: 0 | O46: 0 | P46: 0
E47: 法辅推荐 | F47: 13001 | G47: =G$32*MID($F47,1,1)+G$33*MID($F47,2,1)+G$34*MID($F47,3,1)+G$35*MID($F47,4,1)+G$36*MID($F47,5,1) -> 8 | H47: =H$32*MID($F47,1,1)+H$33*MID($F47,2,1)+H$34*MID($F47,3,1)+H$35*MID($F47,4,1)+H$36*MID($F47,5,1) -> 15 | I47: =I$32*MID($F47,1,1)+I$33*MID($F47,2,1)+I$34*MID($F47,3,1)+I$35*MID($F47,4,1)+I$36*MID($F47,5,1) -> 0 | J47: =J$32*MID($F47,1,1)+J$33*MID($F47,2,1)+J$34*MID($F47,3,1)+J$35*MID($F47,4,1)+J$36*MID($F47,5,1) -> 0 | K47: =K$32*MID($F47,1,1)+K$33*MID($F47,2,1)+K$34*MID($F47,3,1)+K$35*MID($F47,4,1)+K$36*MID($F47,5,1) -> 3 | L47: =L$32*MID($F47,1,1)+L$33*MID($F47,2,1)+L$34*MID($F47,3,1)+L$35*MID($F47,4,1)+L$36*MID($F47,5,1) -> 3.4 | M47: =M$32*MID($F47,1,1)+M$33*MID($F47,2,1)+M$34*MID($F47,3,1)+M$35*MID($F47,4,1)+M$36*MID($F47,5,1) -> 1.7 | N47: 0 | O47: 0 | P47: 0
...

Sheet 装备属性
D3: 生命 | E3: 魔法 | F3: 物攻 | G3: 物防 | H3: 法攻 | I3: 法防 | J3: 速度 | K3: 治疗强度 | L3: 控制命中 | M3: 控制抗性
C4: 装备标准属性成长 | D4: =属性投放!E36 -> 16.4 | E4: =属性投放!F36 -> 8.2 | F4: =属性投放!G36 -> 8.2 | G4: =属性投放!H36 -> 4.1 | H4: =属性投放!I36 -> 4.1 | I4: =属性投放!J36 -> 2.4 | J4: =属性投放!K36 -> 1.3 | K4: =属性投放!L36 -> 3 | ... M4: =属性投放!N36 -> 0
C5: 二级属性能力价值 | D5: =属性价值和能力评分!F6 -> 0.34 | E5: =属性价值和能力评分!G6 -> 0.4 | F5: =属性价值和能力评分!H6 -> 1 | G5: =属性价值和能力评分!I6 -> 2 | H5: =属性价值和能力评分!J6 -> 1.35 | I5: =属性价值和能力评分!K6 -> 1.7 | J5: =属性价值和能力评分!L6 -> 2.5 | K5: =属性价值和能力评分!M6 -> 4 | ... M5: =属性价值和能力评分!O6 -> 1.7
C6: 投放属性能力价值 | D6: =ROUND(D5*D4,2) -> 5.58 | E6: =ROUND(E5*E4,2) -> 3.28 | F6: =ROUND(F5*F4,2) -> 8.2 | G6: =ROUND(G5*G4,2) -> 8.2 | H6: =ROUND(H5*H4,2) -> 5.54 | I6: =ROUND(I5*I4,2) -> 4.08 | J6: =ROUND(J5*J4,2) -> 3.25 | K6: =ROUND(K5*K4,2) -> 12 | ... M6: =ROUND(M5*M4,2) -> 0
C8: 部件id | D8: 装备部件 | K8: 属性比重 | L8: 生命 | M8: 魔法 | N8: 物攻 | O8: 物防 | P8: 法攻 | Q8: 法防 | R8: 速度 | S8: 治疗强度 | T8: 控制命中 | U8: 控制抗性 | V8: 装备部件价值评分系数 | W8: 白属性最大能力评分
C9: 1 | D9: 武器 | E9: 剑 | F9: 锤 | G9: 弓箭 | H9: 爪 | I9: 魔棒 | J9: 法杖 | N9: 1 | P9: 0.45 | S9: 1 | V9: 2.45 | W9: =ROUND((D$6*L9+E$6*M9+F$6*N9+G$6*O9+H$6*P9+I$6*Q9+J$6*R9+K$6*S9+L$6*T9+M$6*U9)/V9,2) -> 9.26
C10: 2 | D10: 衣甲 | E10: 男衣 | F10: 女衣 | L10: 0.4 | O10: 0.5 | V10: 1 | W10: =ROUND((D$6*L10+E$6*M10+F$6*N10+G$6*O10+H$6*P10+I$6*Q10+J$6*R10+K$6*S10+L$6*T10+M$6*U10)/V10,2) -> 6.33
C11: 3 | D11: 头盔 | E11: 男头盔 | F11: 女头饰 | M11: 1 | O11: 0.3 | V11: 1 | W11: =ROUND((D$6*L11+E$6*M11+F$6*N11+G$6*O11+H$6*P11+I$6*Q11+J$6*R11+K$6*S11+L$6*T11+M$6*U11)/V11,2) -> 5.74
C12: 4 | D12: 项链 | E12: 项链 | P12: 0.55 | Q12: 0.5 | V12: 1 | W12: =ROUND((D$6*L12+E$6*M12+F$6*N12+G$6*O12+H$6*P12+I$6*Q12+J$6*R12+K$6*S12+L$6*T12+M$6*U12)/V12,2) -> 5.09
C13: 5 | D13: 腰带 | E13: 腰带 | L13: 0.6 | O13: 0.2 | V13: 1 | W13: =ROUND((D$6*L13+E$6*M13+F$6*N13+G$6*O13+H$6*P13+I$6*Q13+J$6*R13+K$6*S13+L$6*T13+M$6*U13)/V13,2) -> 4.99
C14: 6 | D14: 鞋子 | E14: 鞋子 | Q14: 0.5 | R14: 1 | V14: 1 | W14: =ROUND((D$6*L14+E$6*M14+F$6*N14+G$6*O14+H$6*P14+I$6*Q14+J$6*R14+K$6*S14+L$6*T14+M$6*U14)/V14,2) -> 5.29
V15: 附加一级属性区间 | W15: 附加一级属性几率 | X15: 特效 | Y15: 特技 | Z15: 普通打造几率 | AA15: 强化打造几率
K16: 普通最低系数 | L16: 0.7 | M16: 0.7 | N16: 0.7 | O16: 0.7 | P16: 0.7 | Q16: 0.7 | R16: 0.5 | S16: 0.5 | V16: 0.3 | W16: 0.5 | X16: 0.25 | Y16: 0.15 | Z16: 1 | AA16: 0
K17: 普通最高系数 | L17: 0.9 | M17: 0.9 | N17: 0.9 | O17: 0.9 | P17: 0.9 | Q17: 0.9 | R17: 0.9 | S17: 0.9 | V17: 1
K18: 强化最低系数 | L18: 0.78 | M18: 0.78 | N18: 0.78 | O18: 0.78 | P18: 0.78 | Q18: 0.78 | R18: 0.55 | S18: 0.55 | V18: 0.3 | W18: 0.5 | X18: 0.25 | Y18: 0.15 | Z18: 0 | AA18: 1
K19: 强化最高系数 | L19: 1 | M19: 1 | N19: 1 | O19: 1 | P19: 1 | Q19: 1 | R19: 1 | S19: 1 | V19: 1
E20: 20 | F20: 30 | G20: 40 | H20: 50 | I20: 60 | J20: 70
D21: 白装最低 | E21: =$L21*E$20 -> 14 | F21: =$L21*F$20 -> 21 | G21: =$L21*G$20 -> 28 | H21: =$L21*H$20 -> 35 | I21: =$L21*I$20 -> 42 | J21: =$L21*J$20 -> 49 | K21: 白装最低 | L21: 0.7 | M21: =L21 -> 0.7 | N21: =M21 -> 0.7 | O21: =N21 -> 0.7 | P21: =O21 -> 0.7 | Q21: =P21 -> 0.7 | R21: 0.5 | S21: =R21 -> 0.5 | W21: 0 | X21: 0 | Y21: 0 | Z21: 0 | AA21: 0
D22: 白装最高 | E22: =$L22*E$20 -> 14 | F22: =$L22*F$20 -> 21 | G22: =$L22*G$20 -> 28 | H22: =$L22*H$20 -> 35 | I22: =$L22*I$20 -> 42 | J22: =$L22*J$20 -> 49 | K22: 白装最高 | L22: 0.7 | M22: =L22 -> 0.7 | N22: =M22 -> 0.7 | O22: =N22 -> 0.7 | P22: =O22 -> 0.7 | Q22: =P22 -> 0.7 | R22: 0.5 | S22: =R22 -> 0.5
D23: 绿装最低 | E23: =$L23*E$20 -> 14 | F23: =$L23*F$20 -> 21 | G23: =$L23*G$20 -> 28 | H23: =$L23*H$20 -> 35 | I23: =$L23*I$20 -> 42 | J23: =$L23*J$20 -> 49 | K23: 绿装最低 | L23: 0.7 | M23: =L23 -> 0.7 | N23: =M23 -> 0.7 | O23: =N23 -> 0.7 | P23: =O23 -> 0.7 | Q23: =P23 -> 0.7 | R23: 0.5 | S23: =R23 -> 0.5 | V23: 0.3 | W23: 0.333 | X23: 0 | Y23: 0 | Z23: 0.55 | AA23: 0
D24: 绿装最高 | E24: =$L24*E$20 -> 15.2 | F24: =$L24*F$20 -> 22.8 | G24: =$L24*G$20 -> 30.4 | H24: =$L24*H$20 -> 38 | I24: =$L24*I$20 -> 45.6 | J24: =$L24*J$20 -> 53.2 | K24: 绿装最高 | L24: 0.76 | M24: =L24 -> 0.76 | N24: =M24 -> 0.76 | O24: =N24 -> 0.76 | P24: =O24 -> 0.76 | Q24: =P24 -> 0.76 | R24: 0.6 | S24: =R24 -> 0.6 | V24: 0.4
D25: 蓝装最低 | E25: =$L25*E$20 -> 15.2 | F25: =$L25*F$20 -> 22.8 | G25: =$L25*G$20 -> 30.4 | H25: =$L25*H$20 -> 38 | I25: =$L25*I$20 -> 45.6 | J25: =$L25*J$20 -> 53.2 | K25: 蓝装最低 | L25: 0.76 | M25: =L25 -> 0.76 | N25: =M25 -> 0.76 | O25: =N25 -> 0.76 | P25: =O25 -> 0.76 | Q25: =P25 -> 0.76 | R25: 0.6 | S25: =R25 -> 0.6 | V25: 0.4 | W25: 0.666 | X25: 0 | Y25: 0 | Z25: 0.4 | AA25: 0.75
D26: 蓝装最高 | E26: =$L26*E$20 -> 16.4 | F26: =$L26*F$20 -> 24.6 | G26: =$L26*G$20 -> 32.8 | H26: =$L26*H$20 -> 41 | I26: =$L26*I$20 -> 49.2 | J26: =$L26*J$20 -> 57.4 | K26: 蓝装最高 | L26: 0.82 | M26: =L26 -> 0.82 | N26: =M26 -> 0.82 | O26: =N26 -> 0.82 | P26: =O26 -> 0.82 | Q26: =P26 -> 0.82 | R26: 0.7 | S26: =R26 -> 0.7 | V26: 0.7
D27: 紫装最低 | E27: =$L27*E$20 -> 16.4 | F27: =$L27*F$20 -> 24.6 | G27: =$L27*G$20 -> 32.8 | H27: =$L27*H$20 -> 41 | I27: =$L27*I$20 -> 49.2 | J27: =$L27*J$20 -> 57.4 | K27: 紫装最低 | L27: 0.82 | M27: =L27 -> 0.82 | N27: =M27 -> 0.82 | O27: =N27 -> 0.82 | P27: =O27 -> 0.82 | Q27: =P27 -> 0.82 | R27: 0.7 | S27: =R27 -> 0.7 | V27: 0.5 | W27: 1 | X27: 0.15 | Y27: 0.1 | Z27: 0.05 | AA27: 0.25
D28: 紫装最高 | E28: =$L28*E$20 -> 20 | F28: =$L28*F$20 -> 30 | G28: =$L28*G$20 -> 40 | H28: =$L28*H$20 -> 50 | I28: =$L28*I$20 -> 60 | J28: =$L28*J$20 -> 70 | K28: 紫装最高 | L28: 1 | M28: =L28 -> 1 | N28: =M28 -> 1 | O28: =N28 -> 1 | P28: =O28 -> 1 | Q28: =P28 -> 1 | R28: 1 | S28: =R28 -> 1 | V28: 1
D29: 橙装最低 | E29: =$L29*E$20 -> 20.4 | F29: =$L29*F$20 -> 30.6 | G29: =$L29*G$20 -> 40.8 | H29: =$L29*H$20 -> 51 | I29: =$L29*I$20 -> 61.2 | J29: =$L29*J$20 -> 71.4 | K29: 橙装最低 | L29: 1.02 | M29: =L29 -> 1.02 | N29: =M29 -> 1.02 | O29: =N29 -> 1.02 | P29: =O29 -> 1.02 | Q29: =P29 -> 1.02 | R29: 1.02 | S29: =R29 -> 1.02 | V29: 0.7 | W29: 1 | X29: 1 | Y29: 1 | Z29: 0 | AA29: 0
D30: 橙装最高 | E30: =$L30*E$20 -> 20.4 | F30: =$L30*F$20 -> 30.6 | G30: =$L30*G$20 -> 40.8 | H30: =$L30*H$20 -> 51 | I30: =$L30*I$20 -> 61.2 | J30: =$L30*J$20 -> 71.4 | K30: 橙装最高 | L30: 1.02 | M30: 1.02 | N30: 1.02 | O30: 1.02 | P30: 1.02 | Q30: 1.02 | R30: 1.02 | S30: 1.02 | V30: 1
F33: 非强化白属性 | P33: 强化白属性
B34: 装备id | C34: 部件id | D34: 装备外形 | E34: 装备等级 | F34: 生命 | G34: 魔法 | H34: 物攻 | I34: 物防 | J34: 法攻 | K34: 法防 | L34: 速度 | M34: 治疗强度 | N34: 控制命中 | O34: 控制抗性 | P34: 生命 | Q34: 魔法 | R34: 物攻 | S34: 物防 | T34: 法攻 | U34: 法防 | V34: 速度 | W34: 治疗强度 | X34: 控制命中 | Y34: 控制抗性 | Z34: 白属性最大评分 | AA34: 珍品评分 | AB34: 附加一级属性最大评分 | AC34: 特效评分 | AD34: 特技评分
B35: 1 | C35: 1 | D35: 1 | E35: 1 | F35: =IF(VLOOKUP($C35,$C$9:$U$14,COLUMNS($C$9:L$14),0)="","",ROUND(D$4*$E35*VLOOKUP($C35,$C$9:$U$14,COLUMNS($C$9:L$14),0)*L$16,0)&"～"&ROUND(D$4*$E35*VLOOKUP($C35,$C$9:$U$14,COLUMNS($C$9:L$14),0)*L$17,0)) | G35: =IF(VLOOKUP($C35,$C$9:$U$14,COLUMNS($C$9:M$14),0)="","",ROUND(E$4*$E35*VLOOKUP($C35,$C$9:$U$14,COLUMNS($C$9:M$14),0)*M$16,0)&"～"&ROUND(E$4*$E35*VLOOKUP($C35,$C$9:$U$14,COLUMNS($C$9:M$14),0)*M$17,0)) | H35: =IF(VLOOKUP($C35,$C$9:$U$14,COLUMNS($C$9:N$14),0)="","",ROUND(F$4*$E35*VLOOKUP($C35,$C$9:$U$14,COLUMNS($C$9:N$14),0)*N$16,0)&"～"&ROUND(F$4*$E35*VLOOKUP($C35,$C$9:$U$14,COLUMNS($C$9:N$14),0)*N$17,0)) -> 6～7 | I35: =IF(VLOOKUP($C35,$C$9:$U$14,COLUMNS($C$9:O$14),0)="","",ROUND(G$4*$E35*VLOOKUP($C35,$C$9:$U$14,COLUMNS($C$9:O$14),0)*O$16,0)&"～"&ROUND(G$4*$E35*VLOOKUP($C35,$C$9:$U$14,COLUMNS($C$9:O$14),0)*O$17,0)) | J35: =IF(VLOOKUP($C35,$C$9:$U$14,COLUMNS($C$9:P$14),0)="","",ROUND(H$4*$E35*VLOOKUP($C35,$C$9:$U$14,COLUMNS($C$9:P$14),0)*P$16,0)&"～"&ROUND(H$4*$E35*VLOOKUP($C35,$C$9:$U$14,COLUMNS($C$9:P$14),0)*P$17,0)) -> 1～2 | K35: =IF(VLOOKUP($C35,$C$9:$U$14,COLUMNS($C$9:Q$14),0)="","",ROUND(I$4*$E35*VLOOKUP($C35,$C$9:$U$14,COLUMNS($C$9:Q$14),0)*Q$16,0)&"～"&ROUND(I$4*$E35*VLOOKUP($C35,$C$9:$U$14,COLUMNS($C$9:Q$14),0)*Q$17,0)) | L35: =IF(VLOOKUP($C35,$C$9:$U$14,COLUMNS($C$9:R$14),0)="","",ROUND(J$4*$E35*VLOOKUP($C35,$C$9:$U$14,COLUMNS($C$9:R$14),0)*R$16,0)&"～"&ROUND(J$4*$E35*VLOOKUP($C35,$C$9:$U$14,COLUMNS($C$9:R$14),0)*R$17,0)) | M35: =IF(VLOOKUP($C35,$C$9:$U$14,COLUMNS($C$9:S$14),0)="","",ROUND(K$4*$E35*VLOOKUP($C35,$C$9:$U$14,COLUMNS($C$9:S$14),0)*S$16,0)&"～"&ROUND(K$4*$E35*VLOOKUP($C35,$C$9:$U$14,COLUMNS($C$9:S$14),0)*S$17,0)) -> 2～3 | ... O35: =IF(VLOOKUP($C35,$C$9:$U$14,COLUMNS($C$9:U$14),0)="","",ROUND(M$4*$E35*VLOOKUP($C35,$C$9:$U$14,COLUMNS($C$9:U$14),0)*U$16,0)&"～"&ROUND(M$4*$E35*VLOOKUP($C35,$C$9:$U$14,COLUMNS($C$9:U$14),0)*U$17,0)) | P35: =IF(VLOOKUP($C35,$C$9:$U$14,COLUMNS($C$9:L$14),0)="","",ROUND(D$4*$E35*VLOOKUP($C35,$C$9:$U$14,COLUMNS($C$9:L$14),0)*L$18,0)&"～"&ROUND(D$4*$E35*VLOOKUP($C35,$C$9:$U$14,COLUMNS($C$9:L$14),0)*L$19,0)) | Q35: =IF(VLOOKUP($C35,$C$9:$U$14,COLUMNS($C$9:M$14),0)="","",ROUND(E$4*$E35*VLOOKUP($C35,$C$9:$U$14,COLUMNS($C$9:M$14),0)*M$18,0)&"～"&ROUND(E$4*$E35*VLOOKUP($C35,$C$9:$U$14,COLUMNS($C$9:M$14),0)*M$19,0)) | R35: =IF(VLOOKUP($C35,$C$9:$U$14,COLUMNS($C$9:N$14),0)="","",ROUND(F$4*$E35*VLOOKUP($C35,$C$9:$U$14,COLUMNS($C$9:N$14),0)*N$18,0)&"～"&ROUND(F$4*$E35*VLOOKUP($C35,$C$9:$U$14,COLUMNS($C$9:N$14),0)*N$19,0)) -> 6～8 | S35: =IF(VLOOKUP($C35,$C$9:$U$14,COLUMNS($C$9:O$14),0)="","",ROUND(G$4*$E35*VLOOKUP($C35,$C$9:$U$14,COLUMNS($C$9:O$14),0)*O$18,0)&"～"&ROUND(G$4*$E35*VLOOKUP($C35,$C$9:$U$14,COLUMNS($C$9:O$14),0)*O$19,0)) | T35: =IF(VLOOKUP($C35,$C$9:$U$14,COLUMNS($C$9:P$14),0)="","",ROUND(H$4*$E35*VLOOKUP($C35,$C$9:$U$14,COLUMNS($C$9:P$14),0)*P$18,0)&"～"&ROUND(H$4*$E35*VLOOKUP($C35,$C$9:$U$14,COLUMNS($C$9:P$14),0)*P$19,0)) -> 1～2 | U35: =IF(VLOOKUP($C35,$C$9:$U$14,COLUMNS($C$9:Q$14),0)="","",ROUND(I$4*$E35*VLOOKUP($C35,$C$9:$U$14,COLUMNS($C$9:Q$14),0)*Q$18,0)&"～"&ROUND(I$4*$E35*VLOOKUP($C35,$C$9:$U$14,COLUMNS($C$9:Q$14),0)*Q$19,0)) | V35: =IF(VLOOKUP($C35,$C$9:$U$14,COLUMNS($C$9:R$14),0)="","",ROUND(J$4*$E35*VLOOKUP($C35,$C$9:$U$14,COLUMNS($C$9:R$14),0)*R$18,0)&"～"&ROUND(J$4*$E35*VLOOKUP($C35,$C$9:$U$14,COLUMNS($C$9:R$14),0)*R$19,0)) | W35: =IF(VLOOKUP($C35,$C$9:$U$14,COLUMNS($C$9:S$14),0)="","",ROUND(K$4*$E35*VLOOKUP($C35,$C$9:$U$14,COLUMNS($C$9:S$14),0)*S$18,0)&"～"&ROUND(K$4*$E35*VLOOKUP($C35,$C$9:$U$14,COLUMNS($C$9:S$14),0)*S$19,0)) -> 2～3 | X35: =IF(VLOOKUP($C35,$C$9:$U$14,COLUMNS($C$9:T$14),0)="","",ROUND(L$4*$E35*VLOOKUP($C35,$C$9:$U$14,COLUMNS($C$9:T$14),0)*T$18,0)&"～"&ROUND(L$4*$E35*VLOOKUP($C35,$C$9:$U$14,COLUMNS($C$9:T$14),0)*T$19,0)) | Z35: =ROUND(VLOOKUP($C35,$C$9:$W$14,21,0)*E35,0) -> 9 | AA35: =ROUND(Z35*0.9,0) -> 8 | AB35: =IF(C35>2,0,ROUND(属性价值和能力评分!$F$38*一级属性!$H$17*装备属性!E35,0)) -> 5 | AC35: =ROUND($W$9*0.15*E35,0) -> 1 | AD35: =ROUND($W$9*0.3*E35,0) -> 3
B36: 2 | C36: 1 | D36: 2 | E36: 1 | F36: =IF(VLOOKUP($C36,$C$9:$U$14,COLUMNS($C$9:L$14),0)="","",ROUND(D$4*$E36*VLOOKUP($C36,$C$9:$U$14,COLUMNS($C$9:L$14),0)*L$16,0)&"～"&ROUND(D$4*$E36*VLOOKUP($C36,$C$9:$U$14,COLUMNS($C$9:L$14),0)*L$17,0)) | G36: =IF(VLOOKUP($C36,$C$9:$U$14,COLUMNS($C$9:M$14),0)="","",ROUND(E$4*$E36*VLOOKUP($C36,$C$9:$U$14,COLUMNS($C$9:M$14),0)*M$16,0)&"～"&ROUND(E$4*$E36*VLOOKUP($C36,$C$9:$U$14,COLUMNS($C$9:M$14),0)*M$17,0)) | H36: =IF(VLOOKUP($C36,$C$9:$U$14,COLUMNS($C$9:N$14),0)="","",ROUND(F$4*$E36*VLOOKUP($C36,$C$9:$U$14,COLUMNS($C$9:N$14),0)*N$16,0)&"～"&ROUND(F$4*$E36*VLOOKUP($C36,$C$9:$U$14,COLUMNS($C$9:N$14),0)*N$17,0)) -> 6～7 | I36: =IF(VLOOKUP($C36,$C$9:$U$14,COLUMNS($C$9:O$14),0)="","",ROUND(G$4*$E36*VLOOKUP($C36,$C$9:$U$14,COLUMNS($C$9:O$14),0)*O$16,0)&"～"&ROUND(G$4*$E36*VLOOKUP($C36,$C$9:$U$14,COLUMNS($C$9:O$14),0)*O$17,0)) | J36: =IF(VLOOKUP($C36,$C$9:$U$14,COLUMNS($C$9:P$14),0)="","",ROUND(H$4*$E36*VLOOKUP($C36,$C$9:$U$14,COLUMNS($C$9:P$14),0)*P$16,0)&"～"&ROUND(H$4*$E36*VLOOKUP($C36,$C$9:$U$14,COLUMNS($C$9:P$14),0)*P$17,0)) -> 1～2 | K36: =IF(VLOOKUP($C36,$C$9:$U$14,COLUMNS($C$9:Q$14),0)="","",ROUND(I$4*$E36*VLOOKUP($C36,$C$9:$U$14,COLUMNS($C$9:Q$14),0)*Q$16,0)&"～"&ROUND(I$4*$E36*VLOOKUP($C36,$C$9:$U$14,COLUMNS($C$9:Q$14),0)*Q$17,0)) | L36: =IF(VLOOKUP($C36,$C$9:$U$14,COLUMNS($C$9:R$14),0)="","",ROUND(J$4*$E36*VLOOKUP($C36,$C$9:$U$14,COLUMNS($C$9:R$14),0)*R$16,0)&"～"&ROUND(J$4*$E36*VLOOKUP($C36,$C$9:$U$14,COLUMNS($C$9:R$14),0)*R$17,0)) | M36: =IF(VLOOKUP($C36,$C$9:$U$14,COLUMNS($C$9:S$14),0)="","",ROUND(K$4*$E36*VLOOKUP($C36,$C$9:$U$14,COLUMNS($C$9:S$14),0)*S$16,0)&"～"&ROUND(K$4*$E36*VLOOKUP($C36,$C$9:$U$14,COLUMNS($C$9:S$14),0)*S$17,0)) -> 2～3 | ... O36: =IF(VLOOKUP($C36,$C$9:$U$14,COLUMNS($C$9:U$14),0)="","",ROUND(M$4*$E36*VLOOKUP($C36,$C$9:$U$14,COLUMNS($C$9:U$14),0)*U$16,0)&"～"&ROUND(M$4*$E36*VLOOKUP($C36,$C$9:$U$14,COLUMNS($C$9:U$14),0)*U$17,0)) | P36: =IF(VLOOKUP($C36,$C$9:$U$14,COLUMNS($C$9:L$14),0)="","",ROUND(D$4*$E36*VLOOKUP($C36,$C$9:$U$14,COLUMNS($C$9:L$14),0)*L$18,0)&"～"&ROUND(D$4*$E36*VLOOKUP($C36,$C$9:$U$14,COLUMNS($C$9:L$14),0)*L$19,0)) | Q36: =IF(VLOOKUP($C36,$C$9:$U$14,COLUMNS($C$9:M$14),0)="","",ROUND(E$4*$E36*VLOOKUP($C36,$C$9:$U$14,COLUMNS($C$9:M$14),0)*M$18,0)&"～"&ROUND(E$4*$E36*VLOOKUP($C36,$C$9:$U$14,COLUMNS($C$9:M$14),0)*M$19,0)) | R36: =IF(VLOOKUP($C36,$C$9:$U$14,COLUMNS($C$9:N$14),0)="","",ROUND(F$4*$E36*VLOOKUP($C36,$C$9:$U$14,COLUMNS($C$9:N$14),0)*N$18,0)&"～"&ROUND(F$4*$E36*VLOOKUP($C36,$C$9:$U$14,COLUMNS($C$9:N$14),0)*N$19,0)) -> 6～8 | S36: =IF(VLOOKUP($C36,$C$9:$U$14,COLUMNS($C$9:O$14),0)="","",ROUND(G$4*$E36*VLOOKUP($C36,$C$9:$U$14,COLUMNS($C$9:O$14),0)*O$18,0)&"～"&ROUND(G$4*$E36*VLOOKUP($C36,$C$9:$U$14,COLUMNS($C$9:O$14),0)*O$19,0)) | T36: =IF(VLOOKUP($C36,$C$9:$U$14,COLUMNS($C$9:P$14),0)="","",ROUND(H$4*$E36*VLOOKUP($C36,$C$9:$U$14,COLUMNS($C$9:P$14),0)*P$18,0)&"～"&ROUND(H$4*$E36*VLOOKUP($C36,$C$9:$U$14,COLUMNS($C$9:P$14),0)*P$19,0)) -> 1～2 | U36: =IF(VLOOKUP($C36,$C$9:$U$14,COLUMNS($C$9:Q$14),0)="","",ROUND(I$4*$E36*VLOOKUP($C36,$C$9:$U$14,COLUMNS($C$9:Q$14),0)*Q$18,0)&"～"&ROUND(I$4*$E36*VLOOKUP($C36,$C$9:$U$14,COLUMNS($C$9:Q$14),0)*Q$19,0)) | V36: =IF(VLOOKUP($C36,$C$9:$U$14,COLUMNS($C$9:R$14),0)="","",ROUND(J$4*$E36*VLOOKUP($C36,$C$9:$U$14,COLUMNS($C$9:R$14),0)*R$18,0)&"～"&ROUND(J$4*$E36*VLOOKUP($C36,$C$9:$U$14,COLUMNS($C$9:R$14),0)*R$19,0)) | W36: =IF(VLOOKUP($C36,$C$9:$U$14,COLUMNS($C$9:S$14),0)="","",ROUND(K$4*$E36*VLOOKUP($C36,$C$9:$U$14,COLUMNS($C$9:S$14),0)*S$18,0)&"～"&ROUND(K$4*$E36*VLOOKUP($C36,$C$9:$U$14,COLUMNS($C$9:S$14),0)*S$19,0)) -> 2～3 | X36: =IF(VLOOKUP($C36,$C$9:$U$14,COLUMNS($C$9:T$14),0)="","",ROUND(L$4*$E36*VLOOKUP($C36,$C$9:$U$14,COLUMNS($C$9:T$14),0)*T$18,0)&"～"&ROUND(L$4*$E36*VLOOKUP($C36,$C$9:$U$14,COLUMNS($C$9:T$14),0)*T$19,0)) | Z36: =ROUND(VLOOKUP($C36,$C$9:$W$14,21,0)*E36,0) -> 9 | AA36: =ROUND(Z36*0.9,0) -> 8 | AB36: =IF(C36>2,0,ROUND(属性价值和能力评分!$F$38*一级属性!$H$17*装备属性!E36,0)) -> 5 | AC36: =ROUND($W$9*0.15*E36,0) -> 1 | AD36: =ROUND($W$9*0.3*E36,0) -> 3
B37: 3 | C37: 1 | D37: 3 | E37: 1 | F37: =IF(VLOOKUP($C37,$C$9:$U$14,COLUMNS($C$9:L$14),0)="","",ROUND(D$4*$E37*VLOOKUP($C37,$C$9:$U$14,COLUMNS($C$9:L$14),0)*L$16,0)&"～"&ROUND(D$4*$E37*VLOOKUP($C37,$C$9:$U$14,COLUMNS($C$9:L$14),0)*L$17,0)) | G37: =IF(VLOOKUP($C37,$C$9:$U$14,COLUMNS($C$9:M$14),0)="","",ROUND(E$4*$E37*VLOOKUP($C37,$C$9:$U$14,COLUMNS($C$9:M$14),0)*M$16,0)&"～"&ROUND(E$4*$E37*VLOOKUP($C37,$C$9:$U$14,COLUMNS($C$9:M$14),0)*M$17,0)) | H37: =IF(VLOOKUP($C37,$C$9:$U$14,COLUMNS($C$9:N$14),0)="","",ROUND(F$4*$E37*VLOOKUP($C37,$C$9:$U$14,COLUMNS($C$9:N$14),0)*N$16,0)&"～"&ROUND(F$4*$E37*VLOOKUP($C37,$C$9:$U$14,COLUMNS($C$9:N$14),0)*N$17,0)) -> 6～7 | I37: =IF(VLOOKUP($C37,$C$9:$U$14,COLUMNS($C$9:O$14),0)="","",ROUND(G$4*$E37*VLOOKUP($C37,$C$9:$U$14,COLUMNS($C$9:O$14),0)*O$16,0)&"～"&ROUND(G$4*$E37*VLOOKUP($C37,$C$9:$U$14,COLUMNS($C$9:O$14),0)*O$17,0)) | J37: =IF(VLOOKUP($C37,$C$9:$U$14,COLUMNS($C$9:P$14),0)="","",ROUND(H$4*$E37*VLOOKUP($C37,$C$9:$U$14,COLUMNS($C$9:P$14),0)*P$16,0)&"～"&ROUND(H$4*$E37*VLOOKUP($C37,$C$9:$U$14,COLUMNS($C$9:P$14),0)*P$17,0)) -> 1～2 | K37: =IF(VLOOKUP($C37,$C$9:$U$14,COLUMNS($C$9:Q$14),0)="","",ROUND(I$4*$E37*VLOOKUP($C37,$C$9:$U$14,COLUMNS($C$9:Q$14),0)*Q$16,0)&"～"&ROUND(I$4*$E37*VLOOKUP($C37,$C$9:$U$14,COLUMNS($C$9:Q$14),0)*Q$17,0)) | L37: =IF(VLOOKUP($C37,$C$9:$U$14,COLUMNS($C$9:R$14),0)="","",ROUND(J$4*$E37*VLOOKUP($C37,$C$9:$U$14,COLUMNS($C$9:R$14),0)*R$16,0)&"～"&ROUND(J$4*$E37*VLOOKUP($C37,$C$9:$U$14,COLUMNS($C$9:R$14),0)*R$17,0)) | M37: =IF(VLOOKUP($C37,$C$9:$U$14,COLUMNS($C$9:S$14),0)="","",ROUND(K$4*$E37*VLOOKUP($C37,$C$9:$U$14,COLUMNS($C$9:S$14),0)*S$16,0)&"～"&ROUND(K$4*$E37*VLOOKUP($C37,$C$9:$U$14,COLUMNS($C$9:S$14),0)*S$17,0)) -> 2～3 | ... O37: =IF(VLOOKUP($C37,$C$9:$U$14,COLUMNS($C$9:U$14),0)="","",ROUND(M$4*$E37*VLOOKUP($C37,$C$9:$U$14,COLUMNS($C$9:U$14),0)*U$16,0)&"～"&ROUND(M$4*$E37*VLOOKUP($C37,$C$9:$U$14,COLUMNS($C$9:U$14),0)*U$17,0)) | P37: =IF(VLOOKUP($C37,$C$9:$U$14,COLUMNS($C$9:L$14),0)="","",ROUND(D$4*$E37*VLOOKUP($C37,$C$9:$U$14,COLUMNS($C$9:L$14),0)*L$18,0)&"～"&ROUND(D$4*$E37*VLOOKUP($C37,$C$9:$U$14,COLUMNS($C$9:L$14),0)*L$19,0)) | Q37: =IF(VLOOKUP($C37,$C$9:$U$14,COLUMNS($C$9:M$14),0)="","",ROUND(E$4*$E37*VLOOKUP($C37,$C$9:$U$14,COLUMNS($C$9:M$14),0)*M$18,0)&"～"&ROUND(E$4*$E37*VLOOKUP($C37,$C$9:$U$14,COLUMNS($C$9:M$14),0)*M$19,0)) | R37: =IF(VLOOKUP($C37,$C$9:$U$14,COLUMNS($C$9:N$14),0)="","",ROUND(F$4*$E37*VLOOKUP($C37,$C$9:$U$14,COLUMNS($C$9:N$14),0)*N$18,0)&"～"&ROUND(F$4*$E37*VLOOKUP($C37,$C$9:$U$14,COLUMNS($C$9:N$14),0)*N$19,0)) -> 6～8 | S37: =IF(VLOOKUP($C37,$C$9:$U$14,COLUMNS($C$9:O$14),0)="","",ROUND(G$4*$E37*VLOOKUP($C37,$C$9:$U$14,COLUMNS($C$9:O$14),0)*O$18,0)&"～"&ROUND(G$4*$E37*VLOOKUP($C37,$C$9:$U$14,COLUMNS($C$9:O$14),0)*O$19,0)) | T37: =IF(VLOOKUP($C37,$C$9:$U$14,COLUMNS($C$9:P$14),0)="","",ROUND(H$4*$E37*VLOOKUP($C37,$C$9:$U$14,COLUMNS($C$9:P$14),0)*P$18,0)&"～"&ROUND(H$4*$E37*VLOOKUP($C37,$C$9:$U$14,COLUMNS($C$9:P$14),0)*P$19,0)) -> 1～2 | U37: =IF(VLOOKUP($C37,$C$9:$U$14,COLUMNS($C$9:Q$14),0)="","",ROUND(I$4*$E37*VLOOKUP($C37,$C$9:$U$14,COLUMNS($C$9:Q$14),0)*Q$18,0)&"～"&ROUND(I$4*$E37*VLOOKUP($C37,$C$9:$U$14,COLUMNS($C$9:Q$14),0)*Q$19,0)) | V37: =IF(VLOOKUP($C37,$C$9:$U$14,COLUMNS($C$9:R$14),0)="","",ROUND(J$4*$E37*VLOOKUP($C37,$C$9:$U$14,COLUMNS($C$9:R$14),0)*R$18,0)&"～"&ROUND(J$4*$E37*VLOOKUP($C37,$C$9:$U$14,COLUMNS($C$9:R$14),0)*R$19,0)) | W37: =IF(VLOOKUP($C37,$C$9:$U$14,COLUMNS($C$9:S$14),0)="","",ROUND(K$4*$E37*VLOOKUP($C37,$C$9:$U$14,COLUMNS($C$9:S$14),0)*S$18,0)&"～"&ROUND(K$4*$E37*VLOOKUP($C37,$C$9:$U$14,COLUMNS($C$9:S$14),0)*S$19,0)) -> 2～3 | X37: =IF(VLOOKUP($C37,$C$9:$U$14,COLUMNS($C$9:T$14),0)="","",ROUND(L$4*$E37*VLOOKUP($C37,$C$9:$U$14,COLUMNS($C$9:T$14),0)*T$18,0)&"～"&ROUND(L$4*$E37*VLOOKUP($C37,$C$9:$U$14,COLUMNS($C$9:T$14),0)*T$19,0)) | Z37: =ROUND(VLOOKUP($C37,$C$9:$W$14,21,0)*E37,0) -> 9 | AA37: =ROUND(Z37*0.9,0) -> 8 | AB37: =IF(C37>2,0,ROUND(属性价值和能力评分!$F$38*一级属性!$H$17*装备属性!E37,0)) -> 5 | AC37: =ROUND($W$9*0.15*E37,0) -> 1 | AD37: =ROUND($W$9*0.3*E37,0) -> 3
