Workbook

Sheet 梦幻道具对照说明
A1: 分类 | B1: id | C1: 道具类型 | D1: 名称 | E1: 银币价格 | F1: 金币价格 | G1: 道具名称 | H1: 类型 | I1: 功能 | J1: 描述 | K1: 产出1 | L1: 产出2 | M1: 产出3 | N1: 产出4 | O1: 产出5 | P1: 产出6 | Q1: 产出7 | R1: 回收1 | S1: 回收2 | T1: 回收3
A2: 药
B3: 32037 | C3: 66 | D3: 小血瓶 | E3: 10000 | G3: 红罗羹 | H3: 日常药品 | I3: 功能：补充储备气血 | J3: 战斗外使用，可自动回复任务和宠物的血气10000点。 | K3: 酒店老板 | L3: 等级礼包 | M3: 答题 | N3: 师门-上交道具需品质类 | O3: 秘境降妖
B4: 32014 | C4: 66 | D4: 大血瓶 | E4: 100000 | G4: 大碗红罗羹 | H4: 日常药品 | I4: 功能：补充储备气血 | J4: 战斗外使用，可自动回复任务和宠物的血气100000点。 | K4: 酒店老板 | L4: 等级礼包
B5: 32038 | C5: 66 | D5: 小蓝瓶 | E5: 10000 | G5: 绿芦羹 | H5: 日常药品 | I5: 功能：补充储备魔法 | J5: 战斗外使用，可自动回复任务和宠物魔法10000点。 | K5: 酒店老板 | L5: 等级礼包 | M5: 答题 | N5: 师门-上交道具需品质类 | O5: 秘境降妖
B6: 32015 | C6: 66 | D6: 大蓝瓶 | E6: 100000 | G6: 大碗绿芦羹 | H6: 日常药品 | I6: 功能：补充储备魔法 | J6: 战斗外使用，可自动回复任务和宠物魔法100000点。 | K6: 酒店老板 | L6: 等级礼包
B7: 320000 | C7: 290 | D7: 硬肉干 | G7: 包子 | H7: 烹饪 | I7: 品质：无 | J7: 增加气血储备2000点，非战斗时可食用 | K7: 帮派技能-烹饪技巧 | R7: 师门任务
B8: 320001 | C8: 290 | D8: 煎蛋卷 | G8: 臭豆腐 | H8: 烹饪 | I8: 品质：xx | J8: 增加气血储备=品质*60+2000 | K8: 帮派技能-烹饪技巧 | R8: 师门任务
B9: 320002 | C9: 290 | D9: 樱桃饼 | G9: 佛跳墙 | H9: 烹饪 | I9: 品质：xx | J9: 增加魔法储备=品质*60+2000 | K9: 帮派技能-烹饪技巧 | R9: 师门任务
B10: 320003 | C10: 290 | D10: 美味风蛇 | G10: 桂花丸 | H10: 烹饪 | I10: 品质：xx | J10: 恢复召唤兽寿命=品质*0.5 | K10: 帮派技能-烹饪技巧 | R10: 师门任务
B11: 320004 | C11: 290 | D11: 凤梨佳酿 | G11: 珍露酒 | H11: 烹饪 | I11: 品质：xx | J11: 恢复愤怒值=品质*0.4+10 该物品只能在战斗中使用 | K11: 帮派技能-烹饪技巧 | R11: 师门任务
B12: 320005 | C12: 290 | D12: 辣味狼排 | G12: 翡翠豆腐 | H12: 烹饪 | I12: 品质：xx | J12: 增加气血储备=品质*32+1000 增加魔法储备=品质*32+1000 | K12: 帮派技能-烹饪技巧 | R12: 师门任务
B13: 320006 | C13: 290 | D13: 酸橙派 | G13: 长寿面 | H13: 烹饪 | I13: 品质：xx | J13: 恢复召唤兽寿命=品质*2+50 | K13: 帮派技能-烹饪技巧 | R13: 师门任务
B14: 320007 | C14: 290 | D14: 晨露酒 | G14: 蛇胆酒 | H14: 烹饪 | I14: 品质：xx | J14: 恢复愤怒值=品质*1，降低3~4回合无法防御 只能在战斗中使用 | K14: 帮派技能-烹饪技巧 | R14: 师门任务
B15: 320100 | C15: 291 | D15: 恢复合剂 | G15: 金创药 | H15: 基础药 | I15: 功效：恢复气血400点 | J15: 战斗中使用恢复气血400点，或直接使用增加500点储备气血 | K15: 药店 | L15: 帮派技能-中药医理 | R15: 帮派任务
B16: 320101 | C16: 291 | D16: 治疗药水 | G16: 金香玉 | H16: 三级药 | I16: 品质：xx | J16: 恢复气血（或气血储备）=品质*12+150 | K16: 帮派技能-中药医理 | R16: 师门任务
B17: 320102 | C17: 291 | D17: 法力药水 | G17: 定神香 | H17: 三级药 | I17: 品质：xx | J17: 恢复魔法（或魔法储备）=品质*5+50 | K17: 帮派技能-中药医理 | R17: 师门任务
B18: 320103 | C18: 291 | D18: 净化药剂 | G18: 五龙丹 | H18: 三级药 | I18: 品质：xx | J18: 解除封类异常状态，恢复气血=品质*3 | K18: 帮派技能-中药医理 | R18: 师门任务
B19: 320104 | C19: 291 | D19: 复苏药剂 | G19: 九转回魂丹 | H19: 三级药 | I19: 品质：xx | J19: 复活、恢复气血=品质*5+100 | K19: 帮派技能-中药医理 | R19: 师门任务
B20: 320105 | C20: 291 | D20: 重生药剂 | G20: 佛光舍利子 | H20: 基础药 | I20: 功效：复活并恢复气血 | J20: 只能在战斗内使用，可以复活倒地的角色，并回复100点气血 | K20: 药店 | R20: 帮派任务
B21: 320150 | C21: 275 | D21: 活根草 | G21: 血色茶花 | H21: 一级药 | I21: 功效：恢复气血200点 | J21: 可恢复200点气血（战斗外使用增加等量气血储备） | K21: 药店 | R21: 帮派任务
B22: 320151 | C22: 275 | D22: 野钢花 | G22: 鹿茸 | H22: 一级药 | I22: 功效：恢复气血150点 | J22: 可恢复150点气血（战斗外使用增加等量气血储备） | K22: 药店 | R22: 帮派任务
B23: 320152 | C23: 275 | D23: 银叶草 | G23: 仙狐涎 | H23: 一级药 | I23: 功效：恢复法力150点 | J23: 可恢复150点魔法（战斗外使用增加等量魔法储备） | K23: 药店 | R23: 帮派任务
B24: 320153 | C24: 275 | D24: 宁神花 | G24: 麝香 | H24: 一级药 | I24: 功效：恢复法力100点 | J24: 可恢复100点魔法（战斗外使用增加等量魔法储备） | K24: 药店 | R24: 帮派任务
B25: 320154 | C25: 275 | D25: 皇血草 | G25: 火凤之眼 | H25: 帮派二级药 | I25: 功效：恢复气血300点 | J25: 可恢复300点气血（战斗外使用增加等量气血储备）
B26: 320155 | C26: 275 | D26: 荆棘藻 | G26: 凤凰尾 | H26: 帮派二级药 | I26: 功效：恢复气血250点 | J26: 可恢复250点气血（战斗外使用增加等量气血储备）
B27: 320156 | C27: 275 | D27: 魔皇草 | G27: 孔雀红 | H27: 帮派二级药 | I27: 功效：恢复法力150点 | J27: 可恢复150点魔法（战斗外使用增加等量魔法储备）
B28: 320157 | C28: 275 | D28: 雨燕草 | G28: 血珊瑚 | H28: 帮派二级药 | I28: 功效：恢复法力100点 | J28: 可恢复100点魔法（战斗外使用增加等量魔法储备） | M28: 门派闯关
A30: 主角养成
B31: 338000 | C31: 4262 | D31: 经验宝珠 | G31: 心魔宝珠 | H31: 奖励 | I31: 功能：打开获得经验 | J31: 使用后获得大量经验，每天最多可使用10个 | K31: 师门 | L31: 挂机场景 | M31: 捉鬼 | N31: 秘境降妖 | O31: 商城-吉祥锦囊
B32: 336010 | C32: 4278 | D32: 歌唱水晶 | G32: 回梦丹 | H32: 丹药 | I32: 功能：提高奖励 | J32: 使用后增加100点双倍点数（双倍点数可在挂机与抓鬼中使用，抓鬼每次消耗4点，挂机每场消耗1点） | K32: 商城-20仙玉-每周限用4个
B33: 331000 | C33: 294 | D33: 还原卷轴•体 | G33: 人参果·木 | H33: 洗点材料 | I33: 功能：重置角色体力 | J33: 使用后将已分配的2点体质属性还原为潜能点
B34: 331001 | C34: 294 | D34: 还原卷轴•智 | G34: 人参果·火 | H34: 洗点材料 | I34: 功能：重置角色魔力 | J34: 使用后将已分配的2点魔力属性还原为潜能点
B35: 331002 | C35: 294 | D35: 还原卷轴•力 | G35: 人参果·金 | H35: 洗点材料 | I35: 功能：重置角色力量 | J35: 使用后将已分配的2点力量属性还原为潜能点
B36: 331003 | C36: 294 | D36: 还原卷轴•耐 | G36: 人参果·土 | H36: 洗点材料 | I36: 功能：重置角色耐力 | J36: 使用后将已分配的2点耐力属性还原为潜能点
B37: 331004 | C37: 294 | D37: 还原卷轴•敏 | G37: 人参果·水 | H37: 洗点材料 | I37: 功能：重置角色敏捷 | J37: 使用后将已分配的2点敏捷属性还原为潜能点
B38: 331005 | C38: 294 | D38: 麦迪文之书 | G38: 千年人参果 | H38: 洗点材料 | I38: 功能：重置角色加点 | J38: 使用后重置所有已分配的属性点 | K38: 等级礼包 | L38: 商城-25仙玉
B39: 334100 | C39: 566 | D39: 纪元之书 | G39: 九转金丹 | H39: 提升修炼经验 | I39: 要求：45级后可使用 | J39: 服用之后可以增加人物的修炼经验（10点） | K39: 师门 | L39: 答题 | M39: 科举 | N39: 捉鬼 | O39: 20点活跃度 | P39: 挖宝 | Q39: 侠义值兑换
B40: 334101 | C40: 550 | D40: 永曦露水 | G40: 修炼果 | H40: 提升修炼经验 | I40: 要求：55级后可使用 | J40: 可提高10点某项召唤兽修炼经验
B41: 335102 | C41: 4262 | D41: 活力水晶 | G41: 海马
...

Sheet 物品类型库
A1: id | B1: 名称 | C1: 物品id1 | D1: 物品id1权重 | E1: 物品id2 | F1: 物品id2权重 | G1: 物品id3 | H1: 物品id3权重 | I1: 物品id4 | J1: 物品id4权重 | K1: 物品id5 | L1: 物品id5权重 | M1: 物品id6 | N1: 物品id6权重 | O1: 物品id7 | P1: 物品id7权重 | Q1: 物品id8 | R1: 物品id8权重 | S1: 物品id9 | T1: 物品id9权重 | U1: 物品id10 | V1: 物品id10权重 | W1: 物品id11 | X1: 物品id11权重 | Y1: 物品id12 | Z1: 物品id12权重 | AA1: 物品id13 | AB1: 物品id13权重 | AC1: 物品id14 | AD1: 物品id14权重 | AE1: 物品id15 | AF1: 物品id15权重 | AG1: 物品id16 | AH1: 物品id16权重 | AI1: 物品id17 | AJ1: 物品id17权重 | AK1: 物品id18 | AL1: 物品id18权重 | AM1: 物品id19 | AN1: 物品id19权重 | AO1: 物品id20 | AP1: 物品id20权重 | AQ1: 物品id21 | AR1: 物品id21权重 | AS1: 物品id22 | AT1: 物品id22权重 | AU1: 物品id23 | AV1: 物品id23权重 | AW1: 物品id24 | AX1: 物品id24权重 | AY1: 物品id25 | AZ1: 物品id25权重 | BA1: 物品id26 | BB1: 物品id26权重 | BC1: 物品id27 | BD1: 物品id27权重 | BE1: 物品id28 | BF1: 物品id28权重 | BG1: 物品id29 | BH1: 物品id29权重 | BI1: 物品id30 | BJ1: 物品id30权重 | BK1: 物品id31 | BL1: 物品id31权重 | BM1: 物品id32 | BN1: 物品id32权重 | BO1: 物品id33 | BP1: 物品id33权重 | BQ1: 物品id34 | BR1: 物品id34权重 | BS1: 物品id35 | BT1: 物品id35权重 | BU1: 物品id36 | BV1: 物品id36权重 | BW1: 物品id37 | BX1: 物品id37权重 | BY1: 物品id38 | BZ1: 物品id38权重 | CA1: 物品id39 | CB1: 物品id39权重 | CC1: 物品id40 | CD1: 物品id40权重 | CE1: 物品id41 | CF1: 物品id41权重 | CG1: 物品id42 | CH1: 物品id42权重 | CI1: 物品id43 | CJ1: 物品id43权重 | CK1: 物品id44 | CL1: 物品id44权重 | CM1: 物品id45 | CN1: 物品id45权重 | CO1: 物品id46 | CP1: 物品id46权重 | CQ1: 物品id47 | CR1: 物品id47权重 | CS1: 物品id48 | CT1: 物品id48权重 | CU1: 物品id49 | CV1: 物品id49权重 | CW1: 物品id50 | CX1: 物品id50权重 | CY1: 物品id51 | CZ1: 物品id51权重 | DA1: 物品id52 | DB1: 物品id52权重 | DC1: 物品id53 | DD1: 物品id53权重 | DE1: 物品id54 | DF1: 物品id54权重 | DG1: 物品id55 | DH1: 物品id55权重 | DI1: 物品id56 | DJ1: 物品id56权重
A2: 200008 | B2: 藏宝图 | C2: 331300 | D2: 100
A3: 200009 | B3: 捉鬼任务奖励 | C3: 331350 | D3: 20 | E3: 331351 | F3: 20 | G3: 331352 | H3: 50 | I3: 331353 | J3: 100 | K3: 331354 | L3: 100 | M3: 35001 | N3: 500 | O3: 35002 | P3: 500 | Q3: 35003 | R3: 500 | S3: 35004 | T3: 500 | U3: 35005 | V3: 500 | W3: 35006 | X3: 500 | Y3: 35007 | Z3: 500 | AA3: 35008 | AB3: 500 | AC3: 35009 | AD3: 500
A4: 200010 | B4: 师门任务奖励 | C4: 35001 | D4: 100 | E4: 35002 | F4: 100 | G4: 35003 | H4: 100 | I4: 35004 | J4: 100 | K4: 35005 | L4: 100 | M4: 35006 | N4: 100 | O4: 35007 | P4: 100 | Q4: 35008 | R4: 100 | S4: 35009 | T4: 100
A5: 200011 | B5: 一级宝石奖励 | C5: 35001 | D5: 100 | E5: 35002 | F5: 100 | G5: 35003 | H5: 100 | I5: 35004 | J5: 100 | K5: 35005 | L5: 100 | M5: 35006 | N5: 100 | O5: 35007 | P5: 100 | Q5: 35008 | R5: 100 | S5: 35009 | T5: 100
A6: 200012 | B6: 二级宝石奖励 | C6: =C5+9 -> 35010 | D6: 100 | E6: =E5+9 -> 35011 | F6: 100 | G6: =G5+9 -> 35012 | H6: 100 | I6: =I5+9 -> 35013 | J6: 100 | K6: =K5+9 -> 35014 | L6: 100 | M6: =M5+9 -> 35015 | N6: 100 | O6: =O5+9 -> 35016 | P6: 100 | Q6: =Q5+9 -> 35017 | R6: 100 | S6: =S5+9 -> 35018 | T6: 100
A7: 200013 | B7: 三级宝石奖励 | C7: =C6+9 -> 35019 | D7: 100 | E7: =E6+9 -> 35020 | F7: 100 | G7: =G6+9 -> 35021 | H7: 100 | I7: =I6+9 -> 35022 | J7: 100 | K7: =K6+9 -> 35023 | L7: 100 | M7: =M6+9 -> 35024 | N7: 100 | O7: =O6+9 -> 35025 | P7: 100 | Q7: =Q6+9 -> 35026 | R7: 100 | S7: =S6+9 -> 35027 | T7: 100
A8: 200014 | B8: 魔宠秘籍 | C8: 311001 | D8: 100 | E8: 311002 | F8: 100 | G8: 311003 | H8: 100 | I8: 311004 | J8: 100 | K8: 311005 | L8: 100 | M8: 311006 | N8: 100 | O8: 311007 | P8: 100 | Q8: 311008 | R8: 100 | S8: 311009 | T8: 100 | U8: 311010 | V8: 100 | W8: 311011 | X8: 100 | Y8: 311012 | Z8: 100 | AA8: 311013 | AB8: 100 | AC8: 311014 | AD8: 100 | AE8: 311015 | AF8: 100 | AG8: 311016 | AH8: 100 | AI8: 311017 | AJ8: 100 | AK8: 311018 | AL8: 100 | AM8: 311019 | AN8: 100 | AO8: 311020 | AP8: 100 | AQ8: 311021 | AR8: 100 | AS8: 311022 | AT8: 100 | AU8: 311023 | AV8: 100 | AW8: 311024 | AX8: 100 | AY8: 311025 | AZ8: 100 | BA8: 311026 | BB8: 100 | BC8: 311027 | BD8: 100 | BE8: 311028 | BF8: 100 | BG8: 311029 | BH8: 100 | BI8: 311030 | BJ8: 100 | BK8: 311031 | BL8: 100 | BM8: 311032 | BN8: 100 | BO8: 311033 | BP8: 100 | BQ8: 311034 | BR8: 100 | BS8: 311035 | BT8: 100 | BU8: 311036 | BV8: 100 | BW8: 311037 | BX8: 100 | BY8: 311075 | BZ8: 100 | CA8: 311076 | CB8: 100 | CC8: 311077 | CD8: 100 | CE8: 311078 | CF8: 100
A9: 200015 | B9: 高级魔宠秘籍 | C9: 311038 | D9: 100 | E9: 311039 | F9: 100 | G9: 311040 | H9: 100 | I9: 311041 | J9: 100 | K9: 311042 | L9: 100 | M9: 311043 | N9: 100 | O9: 311044 | P9: 100 | Q9: 311045 | R9: 100 | S9: 311046 | T9: 100 | U9: 311047 | V9: 100 | W9: 311048 | X9: 100 | Y9: 311049 | Z9: 100 | AA9: 311050 | AB9: 100 | AC9: 311051 | AD9: 100 | AE9: 311052 | AF9: 100 | AG9: 311053 | AH9: 100 | AI9: 311054 | AJ9: 100 | AK9: 311055 | AL9: 100 | AM9: 311056 | AN9: 100 | AO9: 311057 | AP9: 100 | AQ9: 311058 | AR9: 100 | AS9: 311059 | AT9: 100 | AU9: 311060 | AV9: 100 | AW9: 311061 | AX9: 100 | AY9: 311062 | AZ9: 100 | BA9: 311063 | BB9: 100 | BC9: 311064 | BD9: 100 | BE9: 311065 | BF9: 100 | BG9: 311066 | BH9: 100 | BI9: 311067 | BJ9: 100 | BK9: 311068 | BL9: 100 | BM9: 311069 | BN9: 100 | BO9: 311070 | BP9: 100 | BQ9: 311071 | BR9: 100 | BS9: 311072 | BT9: 100 | BU9: 311073 | BV9: 100 | BW9: 311074 | BX9: 100 | BY9: 311079 | BZ9: 100 | CA9: 311080 | CB9: 100 | CC9: 311081 | CD9: 100 | CE9: 311082 | CF9: 100
A10: 200016 | B10: 远古宝藏宝箱 | C10: 331350 | D10: 20 | E10: 331351 | F10: 20 | G10: 331352 | H10: 50 | I10: 331353 | J10: 100 | K10: 331354 | L10: 100
A11: 200017 | B11: 40级蓝装库 | C11: 6040101 | D11: 50 | E11: 6040102 | F11: 50 | G11: 6040103 | H11: 50 | I11: 6040104 | J11: 50 | K11: 6040105 | L11: 50 | M11: 6040106 | N11: 50 | O11: 6040207 | P11: 100 | Q11: 6040208 | R11: 100 | S11: 6040309 | T11: 100 | U11: 6040310 | V11: 100 | W11: 6040411 | X11: 100 | Y11: 6040512 | Z11: 100 | AA11: 6040613 | AB11: 100
A12: 200018 | B12: 50级蓝装库 | C12: 6050101 | D12: 50 | E12: 6050102 | F12: 50 | G12: 6050103 | H12: 50 | I12: 6050104 | J12: 50 | K12: 6050105 | L12: 50 | M12: 6050106 | N12: 50 | O12: 6050207 | P12: 100 | Q12: 6050208 | R12: 100 | S12: 6050309 | T12: 100 | U12: 6050310 | V12: 100 | W12: 6050411 | X12: 100 | Y12: 6050512 | Z12: 100 | AA12: 6050613 | AB12: 100
A13: 200019 | B13: 60级蓝装库 | C13: 6060101 | D13: 50 | E13: 6060102 | F13: 50 | G13: 6060103 | H13: 50 | I13: 6060104 | J13: 50 | K13: 6060105 | L13: 50 | M13: 6060106 | N13: 50 | O13: 6060207 | P13: 100 | Q13: 6060208 | R13: 100 | S13: 6060309 | T13: 100 | U13: 6060310 | V13: 100 | W13: 6060411 | X13: 100 | Y13: 6060512 | Z13: 100 | AA13: 6060613 | AB13: 100
A14: 200020 | B14: 40级紫装库 | C14: 7040101 | D14: 50 | E14: 7040102 | F14: 50 | G14: 7040103 | H14: 50 | I14: 7040104 | J14: 50 | K14: 7040105 | L14: 50 | M14: 7040106 | N14: 50 | O14: 7040207 | P14: 100 | Q14: 7040208 | R14: 100 | S14: 7040309 | T14: 100 | U14: 7040310 | V14: 100 | W14: 7040411 | X14: 100 | Y14: 7040512 | Z14: 100 | AA14: 7040613 | AB14: 100
A15: 200021 | B15: 50级紫装库 | C15: 7050101 | D15: 50 | E15: 7050102 | F15: 50 | G15: 7050103 | H15: 50 | I15: 7050104 | J15: 50 | K15: 7050105 | L15: 50 | M15: 7050106 | N15: 50 | O15: 7050207 | P15: 100 | Q15: 7050208 | R15: 100 | S15: 7050309 | T15: 100 | U15: 7050310 | V15: 100 | W15: 7050411 | X15: 100 | Y15: 7050512 | Z15: 100 | AA15: 7050613 | AB15: 100
A16: 200022 | B16: 60级紫装库 | C16: 7060101 | D16: 50 | E16: 7060102 | F16: 50 | G16: 7060103 | H16: 50 | I16: 7060104 | J16: 50 | K16: 7060105 | L16: 50 | M16: 7060106 | N16: 50 | O16: 7060207 | P16: 100 | Q16: 7060208 | R16: 100 | S16: 7060309 | T16: 100 | U16: 7060310 | V16: 100 | W16: 7060411 | X16: 100 | Y16: 7060512 | Z16: 100 | AA16: 7060613 | AB16: 100
A17: 200023 | B17: 二级药库 | C17: 320150 | D17: 100 | E17: 320151 | F17: 100 | G17: 320152 | H17: 100 | I17: 320153 | J17: 100
A18: 200024 | B18: 帮派二级药库 | C18: 320154 | D18: 100 | E18: 320155 | F18: 100 | G18: 320156 | H18: 100 | I18: 320157 | J18: 100
A19: 200025 | B19: 40-50蓝装混合库 | C19: 6040101 | D19: 35 | E19: 6040102 | F19: 35 | G19: 6040103 | H19: 35 | I19: 6040104 | J19: 35 | K19: 6040105 | L19: 35 | M19: 6040106 | N19: 35 | O19: 6040207 | P19: 70 | Q19: 6040208 | R19: 70 | S19: 6040309 | T19: 70 | U19: 6040310 | V19: 70 | W19: 6040411 | X19: 70 | Y19: 6040512 | Z19: 70 | AA19: 6040613 | AB19: 70 | AC19: 6050101 | AD19: 15 | AE19: 6050102 | AF19: 15 | AG19: 6050103 | AH19: 15 | AI19: 6050104 | AJ19: 15 | AK19: 6050105 | AL19: 15 | AM19: 6050106 | AN19: 15 | AO19: 6050207 | AP19: 30 | AQ19: 6050208 | AR19: 30 | AS19: 6050309 | AT19: 30 | AU19: 6050310 | AV19: 30 | AW19: 6050411 | AX19: 30 | AY19: 6050512 | AZ19: 30 | BA19: 6050613 | BB19: 30
A20: 200026 | B20: 40-50紫装混合库A | C20: 7040101 | D20: 50 | E20: 7040102 | F20: 50 | G20: 7040103 | H20: 50 | I20: 7040104 | J20: 50 | K20: 7040105 | L20: 50 | M20: 7040106 | N20: 50 | O20: 7040207 | P20: 100 | Q20: 7040208 | R20: 100 | S20: 7040309 | T20: 100 | U20: 7040310 | V20: 100 | W20: 7040411 | X20: 100 | Y20: 7040512 | Z20: 100 | AA20: 7040613 | AB20: 100 | AC20: 7050101 | AD20: 10 | AE20: 7050102 | AF20: 10 | AG20: 7050103 | AH20: 10 | AI20: 7050104 | AJ20: 10 | AK20: 7050105 | AL20: 10 | AM20: 7050106 | AN20: 10 | AO20: 7050207 | AP20: 20 | AQ20: 7050208 | AR20: 20 | AS20: 7050309 | AT20: 20 | AU20: 7050310 | AV20: 20 | AW20: 7050411 | AX20: 20 | AY20: 7050512 | AZ20: 20 | BA20: 7050613 | BB20: 20
A21: 200027 | B21: 40-50紫装混合库B | C21: 7040101 | D21: 50 | E21: 7040102 | F21: 50 | G21: 7040103 | H21: 50 | I21: 7040104 | J21: 50 | K21: 7040105 | L21: 50 | M21: 7040106 | N21: 50 | O21: 7040207 | P21: 100 | Q21: 7040208 | R21: 100 | S21: 7040309 | T21: 100 | U21: 7040310 | V21: 100 | W21: 7040411 | X21: 100 | Y21: 7040512 | Z21: 100 | AA21: 7040613 | AB21: 100 | AC21: 7050101 | AD21: 15 | AE21: 7050102 | AF21: 15 | AG21: 7050103 | AH21: 15 | AI21: 7050104 | AJ21: 15 | AK21: 7050105 | AL21: 15 | AM21: 7050106 | AN21: 15 | AO21: 7050207 | AP21: 30 | AQ21: 7050208 | AR21: 30 | AS21: 7050309 | AT21: 30 | AU21: 7050310 | AV21: 30 | AW21: 7050411 | AX21: 30 | AY21: 7050512 | AZ21: 30 | BA21: 7050613 | BB21: 30
A22: 200028 | B22: 40-50-60蓝装混合库 | C22: 6040101 | D22: 30 | E22: 6040102 | F22: 30 | G22: 6040103 | H22: 30 | I22: 6040104 | J22: 30 | K22: 6040105 | L22: 30 | M22: 6040106 | N22: 30 | O22: 6040207 | P22: 60 | Q22: 6040208 | R22: 60 | S22: 6040309 | T22: 60 | U22: 6040310 | V22: 60 | W22: 6040411 | X22: 60 | Y22: 6040512 | Z22: 60 | AA22: 6040613 | AB22: 60 | AC22: 6050101 | AD22: 30 | AE22: 6050102 | AF22: 30 | AG22: 6050103 | AH22: 30 | AI22: 6050104 | AJ22: 30 | AK22: 6050105 | AL22: 30 | AM22: 6050106 | AN22: 30 | AO22: 6050207 | AP22: 60 | AQ22: 6050208 | AR22: 60 | AS22: 6050309 | AT22: 60 | AU22: 6050310 | AV22: 60 | AW22: 6050411 | AX22: 60 | AY22: 6050512 | AZ22: 60 | BA22: 6050613 | BB22: 60 | BC22: 6060101 | BD22: 5 | BE22: 6060102 | BF22: 5 | BG22: 6060103 | BH22: 5 | BI22: 6060104 | BJ22: 5 | BK22: 6060105 | BL22: 5 | BM22: 6060106 | BN22: 5 | BO22: 6060207 | BP22: 10 | BQ22: 6060208 | BR22: 10 | BS22: 6060309 | BT22: 10 | BU22: 6060310 | BV22: 10 | BW22: 6060411 | BX22: 10 | BY22: 6060512 | BZ22: 10 | CA22: 6060613 | CB22: 10
A23: 200029 | B23: 40-50-60紫装混合库 | C23: 7040101 | D23: 20 | E23: 7040102 | F23: 20 | G23: 7040103 | H23: 20 | I23: 7040104 | J23: 20 | K23: 7040105 | L23: 20 | M23: 7040106 | N23: 20 | O23: 7040207 | P23: 40 | Q23: 7040208 | R23: 40 | S23: 7040309 | T23: 40 | U23: 7040310 | V23: 40 | W23: 7040411 | X23: 40 | Y23: 7040512 | Z23: 40 | AA23: 7040613 | AB23: 40 | AC23: 7050101 | AD23: 15 | AE23: 7050102 | AF23: 15 | AG23: 7050103 | AH23: 15 | AI23: 7050104 | AJ23: 15 | AK23: 7050105 | AL23: 15 | AM23: 7050106 | AN23: 15 | AO23: 7050207 | AP23: 30 | AQ23: 7050208 | AR23: 30 | AS23: 7050309 | AT23: 30 | AU23: 7050310 | AV23: 30 | AW23: 7050411 | AX23: 30 | AY23: 7050512 | AZ23: 30 | BA23: 7050613 | BB23: 30 | BC23: 7060101 | BD23: 2 | BE23: 7060102 | BF23: 2 | BG23: 7060103 | BH23: 2 | BI23: 7060104 | BJ23: 2 | BK23: 7060105 | BL23: 2 | BM23: 7060106 | BN23: 2 | BO23: 7060207 | BP23: 4 | BQ23: 7060208 | BR23: 4 | BS23: 7060309 | BT23: 4 | BU23: 7060310 | BV23: 4 | BW23: 7060411 | BX23: 4 | BY23: 7060512 | BZ23: 4 | CA23: 7060613 | CB23: 4
A24: 200030 | B24: 50-60蓝装混合库 | C24: 6050101 | D24: 30 | E24: 6050102 | F24: 30 | G24: 6050103 | H24: 30 | I24: 6050104 | J24: 30 | K24: 6050105 | L24: 30 | M24: 6050106 | N24: 30 | O24: 6050207 | P24: 60 | Q24: 6050208 | R24: 60 | S24: 6050309 | T24: 60 | U24: 6050310 | V24: 60 | W24: 6050411 | X24: 60 | Y24: 6050512 | Z24: 60 | AA24: 6050613 | AB24: 60 | AC24: 6060101 | AD24: 10 | AE24: 6060102 | AF24: 10 | AG24: 6060103 | AH24: 10 | AI24: 6060104 | AJ24: 10 | AK24: 6060105 | AL24: 10 | AM24: 6060106 | AN24: 10 | AO24: 6060207 | AP24: 20 | AQ24: 6060208 | AR24: 20 | AS24: 6060309 | AT24: 20 | AU24: 6060310 | AV24: 20 | AW24: 6060411 | AX24: 20 | AY24: 6060512 | AZ24: 20 | BA24: 6060613 | BB24: 20
A25: 200031 | B25: 50-60紫装混合库 | C25: 7050101 | D25: 15 | E25: 7050102 | F25: 15 | G25: 7050103 | H25: 15 | I25: 7050104 | J25: 15 | K25: 7050105 | L25: 15 | M25: 7050106 | N25: 15 | O25: 7050207 | P25: 30 | Q25: 7050208 | R25: 30 | S25: 7050309 | T25: 30 | U25: 7050310 | V25: 30 | W25: 7050411 | X25: 30 | Y25: 7050512 | Z25: 30 | AA25: 7050613 | AB25: 30 | AC25: 7060101 | AD25: 5 | AE25: 7060102 | AF25: 5 | AG25: 7060103 | AH25: 5 | AI25: 7060104 | AJ25: 5 | AK25: 7060105 | AL25: 5 | AM25: 7060106 | AN25: 5 | AO25: 7060207 | AP25: 10 | AQ25: 7060208 | AR25: 10 | AS25: 7060309 | AT25: 10 | AU25: 7060310 | AV25: 10 | AW25: 7060411 | AX25: 10 | AY25: 7060512 | AZ25: 10 | BA25: 7060613 | BB25: 10
A26: 200032 | B26: 40-50精铁库 | C26: 341104 | D26: 50 | E26: 341105 | F26: 50
A27: 200033 | B27: 50-60-70精铁库 | C27: 341105 | D27: 50 | E27: 341106 | F27: 50 | G27: 341107 | H27: 10
A28: 200034 | B28: 40级环装库 | C28: =C11-2000000 -> 4040101 | D28: 80 | E28: =E11-2000000 -> 4040102 | F28: 80 | G28: =G11-2000000 -> 4040103 | H28: 80 | I28: =I11-2000000 -> 4040104 | J28: 80 | K28: =K11-2000000 -> 4040105 | L28: 80 | M28: =M11-2000000 -> 4040106 | N28: 80 | O28: =O11-2000000 -> 4040207 | P28: 80 | Q28: =Q11-2000000 -> 4040208 | R28: 80 | S28: =S11-2000000 -> 4040309 | T28: 80 | U28: =U11-2000000 -> 4040310 | V28: 80 | W28: =W11-2000000 -> 4040411 | X28: 80 | Y28: =Y11-2000000 -> 4040512 | Z28: 80 | AA28: =AA11-2000000 -> 4040613 | AB28: 80 | AC28: =C28+1000000 -> 5040101 | AD28: 20 | AE28: =E28+1000000 -> 5040102 | AF28: 20 | AG28: =G28+1000000 -> 5040103 | AH28: 20 | AI28: =I28+1000000 -> 5040104 | AJ28: 20 | AK28: =K28+1000000 -> 5040105 | AL28: 20 | AM28: =M28+1000000 -> 5040106 | AN28: 20 | AO28: =O28+1000000 -> 5040207 | AP28: 20 | AQ28: =Q28+1000000 -> 5040208 | AR28: 20 | AS28: =S28+1000000 -> 5040309 | AT28: 20 | AU28: =U28+1000000 -> 5040310 | AV28: 20 | AW28: =W28+1000000 -> 5040411 | AX28: 20 | AY28: =Y28+1000000 -> 5040512 | AZ28: 20 | BA28: =AA28+1000000 -> 5040613 | BB28: 20
A29: 200035 | B29: 50级环装库 | C29: =C12-2000000 -> 4050101 | D29: 80 | E29: =E12-2000000 -> 4050102 | F29: 80 | G29: =G12-2000000 -> 4050103 | H29: 80 | I29: =I12-2000000 -> 4050104 | J29: 80 | K29: =K12-2000000 -> 4050105 | L29: 80 | M29: =M12-2000000 -> 4050106 | N29: 80 | O29: =O12-2000000 -> 4050207 | P29: 80 | Q29: =Q12-2000000 -> 4050208 | R29: 80 | S29: =S12-2000000 -> 4050309 | T29: 80 | U29: =U12-2000000 -> 4050310 | V29: 80 | W29: =W12-2000000 -> 4050411 | X29: 80 | Y29: =Y12-2000000 -> 4050512 | Z29: 80 | AA29: =AA12-2000000 -> 4050613 | AB29: 80 | AC29: =C29+1000000 -> 5050101 | AD29: 20 | AE29: =E29+1000000 -> 5050102 | AF29: 20 | AG29: =G29+1000000 -> 5050103 | AH29: 20 | AI29: =I29+1000000 -> 5050104 | AJ29: 20 | AK29: =K29+1000000 -> 5050105 | AL29: 20 | AM29: =M29+1000000 -> 5050106 | AN29: 20 | AO29: =O29+1000000 -> 5050207 | AP29: 20 | AQ29: =Q29+1000000 -> 5050208 | AR29: 20 | AS29: =S29+1000000 -> 5050309 | AT29: 20 | AU29: =U29+1000000 -> 5050310 | AV29: 20 | AW29: =W29+1000000 -> 5050411 | AX29: 20 | AY29: =Y29+1000000 -> 5050512 | AZ29: 20 | BA29: =AA29+1000000 -> 5050613 | BB29: 20
A30: 200036 | B30: 60级环装库 | C30: =C13-2000000 -> 4060101 | D30: 80 | E30: =E13-2000000 -> 4060102 | F30: 80 | G30: =G13-2000000 -> 4060103 | H30: 80 | I30: =I13-2000000 -> 4060104 | J30: 80 | K30: =K13-2000000 -> 4060105 | L30: 80 | M30: =M13-2000000 -> 4060106 | N30: 80 | O30: =O13-2000000 -> 4060207 | P30: 80 | Q30: =Q13-2000000 -> 4060208 | R30: 80 | S30: =S13-2000000 -> 4060309 | T30: 80 | U30: =U13-2000000 -> 4060310 | V30: 80 | W30: =W13-2000000 -> 4060411 | X30: 80 | Y30: =Y13-2000000 -> 4060512 | Z30: 80 | AA30: =AA13-2000000 -> 4060613 | AB30: 80 | AC30: =C30+1000000 -> 5060101 | AD30: 20 | AE30: =E30+1000000 -> 5060102 | AF30: 20 | AG30: =G30+1000000 -> 5060103 | AH30: 20 | AI30: =I30+1000000 -> 5060104 | AJ30: 20 | AK30: =K30+1000000 -> 5060105 | AL30: 20 | AM30: =M30+1000000 -> 5060106 | AN30: 20 | AO30: =O30+1000000 -> 5060207 | AP30: 20 | AQ30: =Q30+1000000 -> 5060208 | AR30: 20 | AS30: =S30+1000000 -> 5060309 | AT30: 20 | AU30: =U30+1000000 -> 5060310 | AV30: 20 | AW30: =W30+1000000 -> 5060411 | AX30: 20 | AY30: =Y30+1000000 -> 5060512 | AZ30: 20 | BA30: =AA30+1000000 -> 5060613 | BB30: 20
A31: 200037 | B31: 10-20-30精铁库 | C31: 341101 | D31: 20 | E31: 341102 | F31: 20 | G31: 341103 | H31: 20
A32: 200038 | B32: 30-40精铁库 | C32: 341103 | D32: 50 | E32: 341104 | F32: 50
A33: 200039 | B33: 30-40-50精铁库 | C33: 341103 | D33: 50 | E33: 341104 | F33: 50 | G33: 341105 | H33: 50
A34: 200040 | B34: 40-50-60精铁库 | C34: 341104 | D34: 50 | E34: 341105 | F34: 50 | G34: 341106 | H34: 50
A35: 200041 | B35: 50-60精铁库 | C35: 341105 | D35: 50 | E35: 341106 | F35: 50
A36: 200042 | B36: 10-20-30制作书 | C36: 350100 | D36: 50 | E36: 350101 | F36: 50 | G36: 350102 | H36: 50 | I36: 350103 | J36: 50 | K36: 350104 | L36: 50 | M36: 350105 | N36: 50 | O36: 350106 | P36: 50 | Q36: 350107 | R36: 50 | S36: 350108 | T36: 50 | U36: 350109 | V36: 50 | W36: 350110 | X36: 50 | Y36: 350111 | Z36: 50 | AA36: 350112 | AB36: 50 | AC36: 350200 | AD36: 50 | AE36: 350201 | AF36: 50 | AG36: 350202 | AH36: 50 | AI36: 350203 | AJ36: 50 | AK36: 350204 | AL36: 50 | AM36: 350205 | AN36: 50 | AO36: 350206 | AP36: 50 | AQ36: 350207 | AR36: 50 | AS36: 350208 | AT36: 50 | AU36: 350209 | AV36: 50 | AW36: 350210 | AX36: 50 | AY36: 350211 | AZ36: 50 | BA36: 350212 | BB36: 50 | BC36: 350300 | BD36: 50 | BE36: 350301 | BF36: 50 | BG36: 350302 | BH36: 50 | BI36: 350303 | BJ36: 50 | BK36: 350304 | BL36: 50 | BM36: 350305 | BN36: 50 | BO36: 350306 | BP36: 50 | BQ36: 350307 | BR36: 50 | BS36: 350308 | BT36: 50 | BU36: 350309 | BV36: 50 | BW36: 350310 | BX36: 50 | BY36: 350311 | BZ36: 50 | CA36: 350312 | CB36: 50
A37: 200043 | B37: 30-40制作书 | C37: 350300 | D37: 50 | E37: 350301 | F37: 50 | G37: 350302 | H37: 50 | I37: 350303 | J37: 50 | K37: 350304 | L37: 50 | M37: 350305 | N37: 50 | O37: 350306 | P37: 50 | Q37: 350307 | R37: 50 | S37: 350308 | T37: 50 | U37: 350309 | V37: 50 | W37: 350310 | X37: 50 | Y37: 350311 | Z37: 50 | AA37: 350312 | AB37: 50 | AC37: 350400 | AD37: 50 | AE37: 350401 | AF37: 50 | AG37: 350402 | AH37: 50 | AI37: 350403 | AJ37: 50 | AK37: 350404 | AL37: 50 | AM37: 350405 | AN37: 50 | AO37: 350406 | AP37: 50 | AQ37: 350407 | AR37: 50 | AS37: 350408 | AT37: 50 | AU37: 350409 | AV37: 50 | AW37: 350410 | AX37: 50 | AY37: 350411 | AZ37: 50 | BA37: 350412 | BB37: 50
A38: 200044 | B38: 30-40-50制作书 | C38: 350300 | D38: 50 | E38: 350301 | F38: 50 | G38: 350302 | H38: 50 | I38: 350303 | J38: 50 | K38: 350304 | L38: 50 | M38: 350305 | N38: 50 | O38: 350306 | P38: 50 | Q38: 350307 | R38: 50 | S38: 350308 | T38: 50 | U38: 350309 | V38: 50 | W38: 350310 | X38: 50 | Y38: 350311 | Z38: 50 | AA38: 350312 | AB38: 50 | AC38: 350400 | AD38: 50 | AE38: 350401 | AF38: 50 | AG38: 350402 | AH38: 50 | AI38: 350403 | AJ38: 50 | AK38: 350404 | AL38: 50 | AM38: 350405 | AN38: 50 | AO38: 350406 | AP38: 50 | AQ38: 350407 | AR38: 50 | AS38: 350408 | AT38: 50 | AU38: 350409 | AV38: 50 | AW38: 350410 | AX38: 50 | AY38: 350411 | AZ38: 50 | BA38: 350412 | BB38: 50 | BC38: 350500 | BD38: 50 | BE38: 350501 | BF38: 50 | BG38: 350502 | BH38: 50 | BI38: 350503 | BJ38: 50 | BK38: 350504 | BL38: 50 | BM38: 350505 | BN38: 50 | BO38: 350506 | BP38: 50 | BQ38: 350507 | BR38: 50 | BS38: 350508 | BT38: 50 | BU38: 350509 | BV38: 50 | BW38: 350510 | BX38: 50 | BY38: 350511 | BZ38: 50 | CA38: 350512 | CB38: 50
A39: 200045 | B39: 40-50-60制作书 | C39: 350400 | D39: 50 | E39: 350401 | F39: 50 | G39: 350402 | H39: 50 | I39: 350403 | J39: 50 | K39: 350404 | L39: 50 | M39: 350405 | N39: 50 | O39: 350406 | P39: 50 | Q39: 350407 | R39: 50 | S39: 350408 | T39: 50 | U39: 350409 | V39: 50 | W39: 350410 | X39: 50 | Y39: 350411 | Z39: 50 | AA39: 350412 | AB39: 50 | AC39: 350500 | AD39: 50 | AE39: 350501 | AF39: 50 | AG39: 350502 | AH39: 50 | AI39: 350503 | AJ39: 50 | AK39: 350504 | AL39: 50 | AM39: 350505 | AN39: 50 | AO39: 350506 | AP39: 50 | AQ39: 350507 | AR39: 50 | AS39: 350508 | AT39: 50 | AU39: 350509 | AV39: 50 | AW39: 350510 | AX39: 50 | AY39: 350511 | AZ39: 50 | BA39: 350512 | BB39: 50 | BC39: 350600 | BD39: 50 | BE39: 350601 | BF39: 50 | BG39: 350602 | BH39: 50 | BI39: 350603 | BJ39: 50 | BK39: 350604 | BL39: 50 | BM39: 350605 | BN39: 50 | BO39: 350606 | BP39: 50 | BQ39: 350607 | BR39: 50 | BS39: 350608 | BT39: 50 | BU39: 350609 | BV39: 50 | BW39: 350610 | BX39: 50 | BY39: 350611 | BZ39: 50 | CA39: 350612 | CB39: 50
A40: 200046 | B40: 50-60制作书 | C40: 350500 | D40: 50 | E40: 350501 | F40: 50 | G40: 350502 | H40: 50 | I40: 350503 | J40: 50 | K40: 350504 | L40: 50 | M40: 350505 | N40: 50 | O40: 350506 | P40: 50 | Q40: 350507 | R40: 50 | S40: 350508 | T40: 50 | U40: 350509 | V40: 50 | W40: 350510 | X40: 50 | Y40: 350511 | Z40: 50 | AA40: 350512 | AB40: 50 | AC40: 350600 | AD40: 50 | AE40: 350601 | AF40: 50 | AG40: 350602 | AH40: 50 | AI40: 350603 | AJ40: 50 | AK40: 350604 | AL40: 50 | AM40: 350605 | AN40: 50 | AO40: 350606 | AP40: 50 | AQ40: 350607 | AR40: 50 | AS40: 350608 | AT40: 50 | AU40: 350609 | AV40: 50 | AW40: 350610 | AX40: 50 | AY40: 350611 | AZ40: 50 | BA40: 350612 | BB40: 50
...

Sheet 养成规划
B2: 标准角色养成开启 | C2: 养成极限 | O2: 标准角色养成 | AA2: 标准角色养成拟合
B3: 等级 | C3: 一级属性 | D3: 装备等级 | E3: 装备白属性 | F3: 装备附加属性 | G3: 装备附魔 | H3: 宝石1 | I3: 宝石2 | J3: 职业技能 | K3: 公会技能 | L3: 阵法 | M3: 修炼 | O3: 一级属性 | P3: 装备等级 | Q3: 装备白属性 | R3: 装备附加属性 | S3: 装备附魔 | T3: 宝石1 | U3: 宝石2 | V3: 职业技能 | W3: 公会技能 | X3: 阵法 | Y3: 修炼 | AA3: 一级属性 | AB3: 装备等级 | AC3: 装备白属性 | AD3: 装备附加属性 | AE3: 装备附魔 | AF3: 宝石1 | AG3: 宝石2 | AH3: 职业技能 | AI3: 公会技能 | AJ3: 阵法 | AK3: 修炼
B4: 1 | C4: =B4 -> 1 | D4: =IF(B4<10,1,ROUNDDOWN(B4,-1)) -> 1 | E4: 1 | F4: 0 | G4: 0 | H4: 0 | I4: 0 | J4: 1 | K4: 0 | L4: 0 | M4: 0 | O4: =C4 -> 1 | P4: =D4 -> 1 | Q4: =E4*$D$25 -> 20 | R4: =F4*$D$36 -> 0 | S4: =G4*$D$27 -> 0 | T4: =H4*$D$39 -> 0 | U4: =H4*$D$40 -> 0 | V4: =J4 -> 1 | W4: =K4*0.7 -> 0 | X4: 1 | Y4: =ROUND(MAX(M4*0.7,),0) -> 0 | AA4: =C4 -> 1 | AB4: =B4 -> 1 | AC4: =$D$25 -> 20 | AD4: =$D$36 -> 30 | AE4: =$D$27 -> 20 | AF4: =B4*0.1*$D$39 -> 3 | AG4: =B4*0.1*$D$40 -> 3 | AH4: =B4 -> 1 | AI4: =B4*$D$26 -> 20 | AJ4: 1 | AK4: =MIN(AA4*0.1,20) -> 0.1
B5: 2 | C5: =B5 -> 2 | D5: =IF(B5<10,1,ROUNDDOWN(B5,-1)) -> 1 | E5: 1 | F5: 0 | G5: 0 | H5: 0 | I5: 0 | J5: 1 | K5: 0 | L5: 0 | M5: 0 | O5: =C5 -> 2 | P5: =D5 -> 1 | Q5: =E5*$D$25 -> 20 | R5: =F5*$D$36 -> 0 | S5: =G5*$D$27 -> 0 | T5: =H5*$D$39 -> 0 | U5: =H5*$D$40 -> 0 | V5: =J5 -> 1 | W5: =K5*0.7 -> 0 | X5: 1 | Y5: =ROUND(MAX(M5*0.7,),0) -> 0 | AA5: =C5 -> 2 | AB5: =B5 -> 2 | AC5: =$D$25 -> 20 | AD5: =$D$36 -> 30 | AE5: =$D$27 -> 20 | AF5: =B5*0.1*$D$39 -> 6 | AG5: =B5*0.1*$D$40 -> 6 | AH5: =B5 -> 2 | AI5: =B5*$D$26 -> 40 | AJ5: 1 | AK5: =MIN(AA5*0.1,20) -> 0.2
B6: 3 | C6: =B6 -> 3 | D6: =IF(B6<10,1,ROUNDDOWN(B6,-1)) -> 1 | E6: 1 | F6: 0 | G6: 0 | H6: 0 | I6: 0 | J6: 1 | K6: 0 | L6: 0 | M6: 0 | O6: =C6 -> 3 | P6: =D6 -> 1 | Q6: =E6*$D$25 -> 20 | R6: =F6*$D$36 -> 0 | S6: =G6*$D$27 -> 0 | T6: =H6*$D$39 -> 0 | U6: =H6*$D$40 -> 0 | V6: =J6 -> 1 | W6: =K6*0.7 -> 0 | X6: 1 | Y6: =ROUND(MAX(M6*0.7,),0) -> 0 | AA6: =C6 -> 3 | AB6: =B6 -> 3 | AC6: =$D$25 -> 20 | AD6: =$D$36 -> 30 | AE6: =$D$27 -> 20 | AF6: =B6*0.1*$D$39 -> 9 | AG6: =B6*0.1*$D$40 -> 9 | AH6: =B6 -> 3 | AI6: =B6*$D$26 -> 60 | AJ6: 1 | AK6: =MIN(AA6*0.1,20) -> 0.3
B7: 4 | C7: =B7 -> 4 | D7: =IF(B7<10,1,ROUNDDOWN(B7,-1)) -> 1 | E7: 1 | F7: 0 | G7: 0 | H7: 0 | I7: 0 | J7: 1 | K7: 0 | L7: 0 | M7: 0 | O7: =C7 -> 4 | P7: =D7 -> 1 | Q7: =E7*$D$25 -> 20 | R7: =F7*$D$36 -> 0 | S7: =G7*$D$27 -> 0 | T7: =H7*$D$39 -> 0 | U7: =H7*$D$40 -> 0 | V7: =J7 -> 1 | W7: =K7*0.7 -> 0 | X7: 1 | Y7: =ROUND(MAX(M7*0.7,),0) -> 0 | AA7: =C7 -> 4 | AB7: =B7 -> 4 | AC7: =$D$25 -> 20 | AD7: =$D$36 -> 30 | AE7: =$D$27 -> 20 | AF7: =B7*0.1*$D$39 -> 12 | AG7: =B7*0.1*$D$40 -> 12 | AH7: =B7 -> 4 | AI7: =B7*$D$26 -> 80 | AJ7: 1 | AK7: =MIN(AA7*0.1,20) -> 0.4
B8: 5 | C8: =B8 -> 5 | D8: =IF(B8<10,1,ROUNDDOWN(B8,-1)) -> 1 | E8: 1 | F8: 0 | G8: 0 | H8: 0 | I8: 0 | J8: 1 | K8: 0 | L8: 0 | M8: 0 | O8: =C8 -> 5 | P8: =D8 -> 1 | Q8: =E8*$D$25 -> 20 | R8: =F8*$D$36 -> 0 | S8: =G8*$D$27 -> 0 | T8: =H8*$D$39 -> 0 | U8: =H8*$D$40 -> 0 | V8: =J8 -> 1 | W8: =K8*0.7 -> 0 | X8: 1 | Y8: =ROUND(MAX(M8*0.7,),0) -> 0 | AA8: =C8 -> 5 | AB8: =B8 -> 5 | AC8: =$D$25 -> 20 | AD8: =$D$36 -> 30 | AE8: =$D$27 -> 20 | AF8: =B8*0.1*$D$39 -> 15 | AG8: =B8*0.1*$D$40 -> 15 | AH8: =B8 -> 5 | AI8: =B8*$D$26 -> 100 | AJ8: 1 | AK8: =MIN(AA8*0.1,20) -> 0.5
B9: 6 | C9: =B9 -> 6 | D9: =IF(B9<10,1,ROUNDDOWN(B9,-1)) -> 1 | E9: 1 | F9: 0 | G9: 0 | H9: 0 | I9: 0 | J9: 1 | K9: 0 | L9: 0 | M9: 0 | O9: =C9 -> 6 | P9: =D9 -> 1 | Q9: =E9*$D$25 -> 20 | R9: =F9*$D$36 -> 0 | S9: =G9*$D$27 -> 0 | T9: =H9*$D$39 -> 0 | U9: =H9*$D$40 -> 0 | V9: =J9 -> 1 | W9: =K9*0.7 -> 0 | X9: 1 | Y9: =ROUND(MAX(M9*0.7,),0) -> 0 | AA9: =C9 -> 6 | AB9: =B9 -> 6 | AC9: =$D$25 -> 20 | AD9: =$D$36 -> 30 | AE9: =$D$27 -> 20 | AF9: =B9*0.1*$D$39 -> 18 | AG9: =B9*0.1*$D$40 -> 18 | AH9: =B9 -> 6 | AI9: =B9*$D$26 -> 120 | AJ9: 1 | AK9: =MIN(AA9*0.1,20) -> 0.6
B10: 7 | C10: =B10 -> 7 | D10: =IF(B10<10,1,ROUNDDOWN(B10,-1)) -> 1 | E10: 1 | F10: 0 | G10: 0 | H10: 0 | I10: 0 | J10: 1 | K10: 0 | L10: 0 | M10: 0 | O10: =C10 -> 7 | P10: =D10 -> 1 | Q10: =E10*$D$25 -> 20 | R10: =F10*$D$36 -> 0 | S10: =G10*$D$27 -> 0 | T10: =H10*$D$39 -> 0 | U10: =H10*$D$40 -> 0 | V10: =J10 -> 1 | W10: =K10*0.7 -> 0 | X10: 1 | Y10: =ROUND(MAX(M10*0.7,),0) -> 0 | AA10: =C10 -> 7 | AB10: =B10 -> 7 | AC10: =$D$25 -> 20 | AD10: =$D$36 -> 30 | AE10: =$D$27 -> 20 | AF10: =B10*0.1*$D$39 -> 21 | AG10: =B10*0.1*$D$40 -> 21 | AH10: =B10 -> 7 | AI10: =B10*$D$26 -> 140 | AJ10: 1 | AK10: =MIN(AA10*0.1,20) -> 0.7
B11: 8 | C11: =B11 -> 8 | D11: =IF(B11<10,1,ROUNDDOWN(B11,-1)) -> 1 | E11: 1 | F11: 0 | G11: 0 | H11: 0 | I11: 0 | J11: 1 | K11: 0 | L11: 0 | M11: 0 | O11: =C11 -> 8 | P11: =D11 -> 1 | Q11: =E11*$D$25 -> 20 | R11: =F11*$D$36 -> 0 | S11: =G11*$D$27 -> 0 | T11: =H11*$D$39 -> 0 | U11: =H11*$D$40 -> 0 | V11: =J11 -> 1 | W11: =K11*0.7 -> 0 | X11: 1 | Y11: =ROUND(MAX(M11*0.7,),0) -> 0 | AA11: =C11 -> 8 | AB11: =B11 -> 8 | AC11: =$D$25 -> 20 | AD11: =$D$36 -> 30 | AE11: =$D$27 -> 20 | AF11: =B11*0.1*$D$39 -> 24 | AG11: =B11*0.1*$D$40 -> 24 | AH11: =B11 -> 8 | AI11: =B11*$D$26 -> 160 | AJ11: 1 | AK11: =MIN(AA11*0.1,20) -> 0.8
B12: 9 | C12: =B12 -> 9 | D12: =IF(B12<10,1,ROUNDDOWN(B12,-1)) -> 1 | E12: 1 | F12: 0 | G12: 0 | H12: 0 | I12: 0 | J12: 1 | K12: 0 | L12: 0 | M12: 0 | O12: =C12 -> 9 | P12: =D12 -> 1 | Q12: =E12*$D$25 -> 20 | R12: =F12*$D$36 -> 0 | S12: =G12*$D$27 -> 0 | T12: =H12*$D$39 -> 0 | U12: =H12*$D$40 -> 0 | V12: =J12 -> 1 | W12: =K12*0.7 -> 0 | X12: 1 | Y12: =ROUND(MAX(M12*0.7,),0) -> 0 | AA12: =C12 -> 9 | AB12: =B12 -> 9 | AC12: =$D$25 -> 20 | AD12: =$D$36 -> 30 | AE12: =$D$27 -> 20 | AF12: =B12*0.1*$D$39 -> 27 | AG12: =B12*0.1*$D$40 -> 27 | AH12: =B12 -> 9 | AI12: =B12*$D$26 -> 180 | AJ12: 1 | AK12: =MIN(AA12*0.1,20) -> 0.9
B13: 10 | C13: =B13 -> 10 | D13: =IF(B13<10,1,ROUNDDOWN(B13,-1)) -> 10 | E13: 1 | F13: 0 | G13: 0 | H13: 0 | I13: 0 | J13: 10 | K13: 0 | L13: 0 | M13: 0 | O13: =C13 -> 10 | P13: =D13 -> 10 | Q13: =E13*$D$25 -> 20 | R13: =F13*$D$36 -> 0 | S13: =G13*$D$27 -> 0 | T13: =H13*$D$39 -> 0 | U13: =H13*$D$40 -> 0 | V13: =J13 -> 10 | W13: =K13*0.7 -> 0 | X13: 1 | Y13: =ROUND(MAX(M13*0.7,),0) -> 0 | AA13: =C13 -> 10 | AB13: =B13 -> 10 | AC13: =$D$25 -> 20 | AD13: =$D$36 -> 30 | AE13: =$D$27 -> 20 | AF13: =B13*0.1*$D$39 -> 30 | AG13: =B13*0.1*$D$40 -> 30 | AH13: =B13 -> 10 | AI13: =B13*$D$26 -> 200 | AJ13: 1 | AK13: =MIN(AA13*0.1,20) -> 1
B14: 11 | C14: =B14 -> 11 | D14: =IF(B14<10,1,ROUNDDOWN(B14,-1)) -> 10 | E14: 1 | F14: 0 | G14: 0 | H14: 0 | I14: 0 | J14: 11 | K14: 0 | L14: 0 | M14: 0 | O14: =C14 -> 11 | P14: =D14 -> 10 | Q14: =E14*$D$25 -> 20 | R14: =F14*$D$36 -> 0 | S14: =G14*$D$27 -> 0 | T14: =H14*$D$39 -> 0 | U14: =H14*$D$40 -> 0 | V14: =J14 -> 11 | W14: =K14*0.7 -> 0 | X14: 1 | Y14: =ROUND(MAX(M14*0.7,),0) -> 0 | AA14: =C14 -> 11 | AB14: =B14 -> 11 | AC14: =$D$25 -> 20 | AD14: =$D$36 -> 30 | AE14: =$D$27 -> 20 | AF14: =B14*0.1*$D$39 -> 33 | AG14: =B14*0.1*$D$40 -> 33 | AH14: =B14 -> 11 | AI14: =B14*$D$26 -> 220 | AJ14: 1 | AK14: =MIN(AA14*0.1,20) -> 1.1
B15: 12 | C15: =B15 -> 12 | D15: =IF(B15<10,1,ROUNDDOWN(B15,-1)) -> 10 | E15: 1 | F15: 0 | G15: 0 | H15: 0 | I15: 0 | J15: 12 | K15: 0 | L15: 0 | M15: 0 | O15: =C15 -> 12 | P15: =D15 -> 10 | Q15: =E15*$D$25 -> 20 | R15: =F15*$D$36 -> 0 | S15: =G15*$D$27 -> 0 | T15: =H15*$D$39 -> 0 | U15: =H15*$D$40 -> 0 | V15: =J15 -> 12 | W15: =K15*0.7 -> 0 | X15: 1 | Y15: =ROUND(MAX(M15*0.7,),0) -> 0 | AA15: =C15 -> 12 | AB15: =B15 -> 12 | AC15: =$D$25 -> 20 | AD15: =$D$36 -> 30 | AE15: =$D$27 -> 20 | AF15: =B15*0.1*$D$39 -> 36 | AG15: =B15*0.1*$D$40 -> 36 | AH15: =B15 -> 12 | AI15: =B15*$D$26 -> 240 | AJ15: 1 | AK15: =MIN(AA15*0.1,20) -> 1.2
... B37: 34 | C37: =B37 -> 34 | D37: =IF(B37<10,1,ROUNDDOWN(B37,-1)) -> 30 | E37: 1 | F37: 0 | G37: 0 | H37: 3 | I37: 0 | J37: 34 | K37: 0 | L37: 1 | M37: 0 | O37: =C37 -> 34 | P37: =D37 -> 30 | Q37: =E37*$D$25 -> 20 | R37: =F37*$D$36 -> 0 | S37: =G37*$D$27 -> 0 | T37: =H37*$D$39 -> 90 | U37: =H37*$D$40 -> 90 | V37: =J37 -> 34 | W37: =K37*0.7 -> 0 | X37: 1 | Y37: =ROUND(MAX(M37*0.7,),0) -> 0 | AA37: =C37 -> 34 | AB37: =B37 -> 34 | AC37: =$D$25 -> 20 | AD37: =$D$36 -> 30 | AE37: =$D$27 -> 20 | AF37: =B37*0.1*$D$39 -> 102 | AG37: =B37*0.1*$D$40 -> 102 | AH37: =B37 -> 34 | AI37: =B37*$D$26 -> 680 | AJ37: 1 | AK37: =MIN(AA37*0.1,20) -> 3.4
B38: 35 | C38: =B38 -> 35 | D38: =IF(B38<10,1,ROUNDDOWN(B38,-1)) -> 30 | E38: 1 | F38: 0 | G38: 0 | H38: 3 | I38: 0 | J38: 35 | K38: =B38 -> 35 | L38: 1 | M38: 0 | O38: =C38 -> 35 | P38: =D38 -> 30 | Q38: =E38*$D$25 -> 20 | R38: =F38*$D$36 -> 0 | S38: =G38*$D$27 -> 0 | T38: =H38*$D$39 -> 90 | U38: =H38*$D$40 -> 90 | V38: =J38 -> 35 | W38: =K38*0.7 -> 24.5 | X38: 1 | Y38: =ROUND(MAX(M38*0.7,),0) -> 0 | AA38: =C38 -> 35 | AB38: =B38 -> 35 | AC38: =$D$25 -> 20 | AD38: =$D$36 -> 30 | AE38: =$D$27 -> 20 | AF38: =B38*0.1*$D$39 -> 105 | AG38: =B38*0.1*$D$40 -> 105 | AH38: =B38 -> 35 | AI38: =B38*$D$26 -> 700 | AJ38: 1 | AK38: =MIN(AA38*0.1,20) -> 3.5
B39: 36 | C39: =B39 -> 36 | D39: =IF(B39<10,1,ROUNDDOWN(B39,-1)) -> 30 | E39: 1 | F39: 0 | G39: 0 | H39: 3 | I39: 0 | J39: 36 | K39: =B39 -> 36 | L39: 1 | M39: 0 | O39: =C39 -> 36 | P39: =D39 -> 30 | Q39: =E39*$D$25 -> 20 | R39: =F39*$D$36 -> 0 | S39: =G39*$D$27 -> 0 | T39: =H39*$D$39 -> 90 | U39: =H39*$D$40 -> 90 | V39: =J39 -> 36 | W39: =K39*0.7 -> 25.2 | X39: 1 | Y39: =ROUND(MAX(M39*0.7,),0) -> 0 | AA39: =C39 -> 36 | AB39: =B39 -> 36 | AC39: =$D$25 -> 20 | AD39: =$D$36 -> 30 | AE39: =$D$27 -> 20 | AF39: =B39*0.1*$D$39 -> 108 | AG39: =B39*0.1*$D$40 -> 108 | AH39: =B39 -> 36 | AI39: =B39*$D$26 -> 720 | AJ39: 1 | AK39: =MIN(AA39*0.1,20) -> 3.6
B40: 37 | C40: =B40 -> 37 | D40: =IF(B40<10,1,ROUNDDOWN(B40,-1)) -> 30 | E40: 1 | F40: 0 | G40: 0 | H40: 3 | I40: 0 | J40: 37 | K40: =B40 -> 37 | L40: 1 | M40: 0 | O40: =C40 -> 37 | P40: =D40 -> 30 | Q40: =E40*$D$25 -> 20 | R40: =F40*$D$36 -> 0 | S40: =G40*$D$27 -> 0 | T40: =H40*$D$39 -> 90 | U40: =H40*$D$40 -> 90 | V40: =J40 -> 37 | W40: =K40*0.7 -> 25.9 | X40: 1 | Y40: =ROUND(MAX(M40*0.7,),0) -> 0 | AA40: =C40 -> 37 | AB40: =B40 -> 37 | AC40: =$D$25 -> 20 | AD40: =$D$36 -> 30 | AE40: =$D$27 -> 20 | AF40: =B40*0.1*$D$39 -> 111 | AG40: =B40*0.1*$D$40 -> 111 | AH40: =B40 -> 37 | AI40: =B40*$D$26 -> 740 | AJ40: 1 | AK40: =MIN(AA40*0.1,20) -> 3.7
B41: 38 | C41: =B41 -> 38 | D41: =IF(B41<10,1,ROUNDDOWN(B41,-1)) -> 30 | E41: 1 | F41: 0 | G41: 0 | H41: 3 | I41: 0 | J41: 38 | K41: =B41 -> 38 | L41: 1 | M41: 0 | O41: =C41 -> 38 | P41: =D41 -> 30 | Q41: =E41*$D$25 -> 20 | R41: =F41*$D$36 -> 0 | S41: =G41*$D$27 -> 0 | T41: =H41*$D$39 -> 90 | U41: =H41*$D$40 -> 90 | V41: =J41 -> 38 | W41: =K41*0.7 -> 26.6 | X41: 1 | Y41: =ROUND(MAX(M41*0.7,),0) -> 0 | AA41: =C41 -> 38 | AB41: =B41 -> 38 | AC41: =$D$25 -> 20 | AD41: =$D$36 -> 30 | AE41: =$D$27 -> 20 | AF41: =B41*0.1*$D$39 -> 114 | AG41: =B41*0.1*$D$40 -> 114 | AH41: =B41 -> 38 | AI41: =B41*$D$26 -> 760 | AJ41: 1 | AK41: =MIN(AA41*0.1,20) -> 3.8
B42: 39 | C42: =B42 -> 39 | D42: =IF(B42<10,1,ROUNDDOWN(B42,-1)) -> 30 | E42: 1 | F42: 0 | G42: 0 | H42: 3 | I42: 0 | J42: 39 | K42: =B42 -> 39 | L42: 1 | M42: 0 | O42: =C42 -> 39 | P42: =D42 -> 30 | Q42: =E42*$D$25 -> 20 | R42: =F42*$D$36 -> 0 | S42: =G42*$D$27 -> 0 | T42: =H42*$D$39 -> 90 | U42: =H42*$D$40 -> 90 | V42: =J42 -> 39 | W42: =K42*0.7 -> 27.3 | X42: 1 | Y42: =ROUND(MAX(M42*0.7,),0) -> 0 | AA42: =C42 -> 39 | AB42: =B42 -> 39 | AC42: =$D$25 -> 20 | AD42: =$D$36 -> 30 | AE42: =$D$27 -> 20 | AF42: =B42*0.1*$D$39 -> 117 | AG42: =B42*0.1*$D$40 -> 117 | AH42: =B42 -> 39 | AI42: =B42*$D$26 -> 780 | AJ42: 1 | AK42: =MIN(AA42*0.1,20) -> 3.9
B43: 40 | C43: =B43 -> 40 | D43: =IF(B43<10,1,ROUNDDOWN(B43,-1)) -> 40 | E43: 1 | F43: 0.4 | G43: 0 | H43: 4 | I43: 0 | J43: 40 | K43: =B43 -> 40 | L43: 1 | M43: 0 | O43: =C43 -> 40 | P43: =D43 -> 40 | Q43: =E43*$D$25 -> 20 | R43: =F43*$D$36 -> 12 | S43: =G43*$D$27 -> 0 | T43: =H43*$D$39 -> 120 | U43: =H43*$D$40 -> 120 | V43: =J43 -> 40 | W43: =K43*0.7 -> 28 | X43: 1 | Y43: =ROUND(MAX(M43*0.7,),0) -> 0 | AA43: =C43 -> 40 | AB43: =B43 -> 40 | AC43: =$D$25 -> 20 | AD43: =$D$36 -> 30 | AE43: =$D$27 -> 20 | AF43: =B43*0.1*$D$39 -> 120 | AG43: =B43*0.1*$D$40 -> 120 | AH43: =B43 -> 40 | AI43: =B43*$D$26 -> 800 | AJ43: 1 | AK43: =MIN(AA43*0.1,20) -> 4
B44: 41 | C44: =B44 -> 41 | D44: =IF(B44<10,1,ROUNDDOWN(B44,-1)) -> 40 | E44: 1 | F44: 0.4 | G44: 0 | H44: 4 | I44: 0 | J44: 41 | K44: =B44 -> 41 | L44: 1 | M44: 0 | O44: =C44 -> 41 | P44: =D44 -> 40 | Q44: =E44*$D$25 -> 20 | R44: =F44*$D$36 -> 12 | S44: =G44*$D$27 -> 0 | T44: =H44*$D$39 -> 120 | U44: =H44*$D$40 -> 120 | V44: =J44 -> 41 | W44: =K44*0.7 -> 28.7 | X44: 1 | Y44: =ROUND(MAX(M44*0.7,),0) -> 0 | AA44: =C44 -> 41 | AB44: =B44 -> 41 | AC44: =$D$25 -> 20 | AD44: =$D$36 -> 30 | AE44: =$D$27 -> 20 | AF44: =B44*0.1*$D$39 -> 123 | AG44: =B44*0.1*$D$40 -> 123 | AH44: =B44 -> 41 | AI44: =B44*$D$26 -> 820 | AJ44: 1 | AK44: =MIN(AA44*0.1,20) -> 4.1
B45: 42 | C45: =B45 -> 42 | D45: =IF(B45<10,1,ROUNDDOWN(B45,-1)) -> 40 | E45: 1 | F45: 0.4 | G45: 0 | H45: 4 | I45: 0 | J45: 42 | K45: =B45 -> 42 | L45: 1 | M45: 0 | O45: =C45 -> 42 | P45: =D45 -> 40 | Q45: =E45*$D$25 -> 20 | R45: =F45*$D$36 -> 12 | S45: =G45*$D$27 -> 0 | T45: =H45*$D$39 -> 120 | U45: =H45*$D$40 -> 120 | V45: =J45 -> 42 | W45: =K45*0.7 -> 29.4 | X45: 1 | Y45: =ROUND(MAX(M45*0.7,),0) -> 0 | AA45: =C45 -> 42 | AB45: =B45 -> 42 | AC45: =$D$25 -> 20 | AD45: =$D$36 -> 30 | AE45: =$D$27 -> 20 | AF45: =B45*0.1*$D$39 -> 126 | AG45: =B45*0.1*$D$40 -> 126 | AH45: =B45 -> 42 | AI45: =B45*$D$26 -> 840 | AJ45: 1 | AK45: =MIN(AA45*0.1,20) -> 4.2
B46: 43 | C46: =B46 -> 43 | D46: =IF(B46<10,1,ROUNDDOWN(B46,-1)) -> 40 | E46: 1 | F46: 0.4 | G46: 0 | H46: 4 | I46: 0 | J46: 43 | K46: =B46 -> 43 | L46: 1 | M46: 0 | O46: =C46 -> 43 | P46: =D46 -> 40 | Q46: =E46*$D$25 -> 20 | R46: =F46*$D$36 -> 12 | S46: =G46*$D$27 -> 0 | T46: =H46*$D$39 -> 120 | U46: =H46*$D$40 -> 120 | V46: =J46 -> 43 | W46: =K46*0.7 -> 30.1 | X46: 1 | Y46: =ROUND(MAX(M46*0.7,),0) -> 0 | AA46: =C46 -> 43 | AB46: =B46 -> 43 | AC46: =$D$25 -> 20 | AD46: =$D$36 -> 30 | AE46: =$D$27 -> 20 | AF46: =B46*0.1*$D$39 -> 129 | AG46: =B46*0.1*$D$40 -> 129 | AH46: =B46 -> 43 | AI46: =B46*$D$26 -> 860 | AJ46: 1 | AK46: =MIN(AA46*0.1,20) -> 4.3
B47: 44 | C47: =B47 -> 44 | D47: =IF(B47<10,1,ROUNDDOWN(B47,-1)) -> 40 | E47: 1 | F47: 0.4 | G47: 0 | H47: 4 | I47: 0 | J47: 44 | K47: =B47 -> 44 | L47: 1 | M47: 0 | O47: =C47 -> 44 | P47: =D47 -> 40 | Q47: =E47*$D$25 -> 20 | R47: =F47*$D$36 -> 12 | S47: =G47*$D$27 -> 0 | T47: =H47*$D$39 -> 120 | U47: =H47*$D$40 -> 120 | V47: =J47 -> 44 | W47: =K47*0.7 -> 30.8 | X47: 1 | Y47: =ROUND(MAX(M47*0.7,),0) -> 0 | AA47: =C47 -> 44 | AB47: =B47 -> 44 | AC47: =$D$25 -> 20 | AD47: =$D$36 -> 30 | AE47: =$D$27 -> 20 | AF47: =B47*0.1*$D$39 -> 132 | AG47: =B47*0.1*$D$40 -> 132 | AH47: =B47 -> 44 | AI47: =B47*$D$26 -> 880 | AJ47: 1 | AK47: =MIN(AA47*0.1,20) -> 4.4
B48: 45 | C48: =B48 -> 45 | D48: =IF(B48<10,1,ROUNDDOWN(B48,-1)) -> 40 | E48: 1 | F48: 0.4 | G48: 0 | H48: 4 | I48: 0 | J48: 45 | K48: =B48 -> 45 | L48: 1 | M48: 1 | O48: =C48 -> 45 | P48: =D48 -> 40 | Q48: =E48*$D$25 -> 20 | R48: =F48*$D$36 -> 12 | S48: =G48*$D$27 -> 0 | T48: =H48*$D$39 -> 120 | U48: =H48*$D$40 -> 120 | V48: =J48 -> 45 | W48: =K48*0.7 -> 31.5 | X48: 1 | Y48: =ROUND(MAX(M48*0.7,),0) -> 1 | AA48: =C48 -> 45 | AB48: =B48 -> 45 | AC48: =$D$25 -> 20 | AD48: =$D$36 -> 30 | AE48: =$D$27 -> 20 | AF48: =B48*0.1*$D$39 -> 135 | AG48: =B48*0.1*$D$40 -> 135 | AH48: =B48 -> 45 | AI48: =B48*$D$26 -> 900 | AJ48: 1 | AK48: =MIN(AA48*0.1,20) -> 4.5
B49: 46 | C49: =B49 -> 46 | D49: =IF(B49<10,1,ROUNDDOWN(B49,-1)) -> 40 | E49: 1 | F49: 0.4 | G49: 0 | H49: 4 | I49: 0 | J49: 46 | K49: =B49 -> 46 | L49: 1 | M49: 1 | O49: =C49 -> 46 | P49: =D49 -> 40 | Q49: =E49*$D$25 -> 20 | R49: =F49*$D$36 -> 12 | S49: =G49*$D$27 -> 0 | T49: =H49*$D$39 -> 120 | U49: =H49*$D$40 -> 120 | V49: =J49 -> 46 | W49: =K49*0.7 -> 32.2 | X49: 1 | Y49: =ROUND(MAX(M49*0.7,),0) -> 1 | AA49: =C49 -> 46 | AB49: =B49 -> 46 | AC49: =$D$25 -> 20 | AD49: =$D$36 -> 30 | AE49: =$D$27 -> 20 | AF49: =B49*0.1*$D$39 -> 138 | AG49: =B49*0.1*$D$40 -> 138 | AH49: =B49 -> 46 | AI49: =B49*$D$26 -> 920 | AJ49: 1 | AK49: =MIN(AA49*0.1,20) -> 4.6
... B52: 49 | C52: =B52 -> 49 | D52: =IF(B52<10,1,ROUNDDOWN(B52,-1)) -> 40 | E52: 1 | F52: 0.4 | G52: 0 | H52: 4 | I52: 0 | J52: 49 | K52: =B52 -> 49 | L52: 1 | M52: 1 | O52: =C52 -> 49 | P52: =D52 -> 40 | Q52: =E52*$D$25 -> 20 | R52: =F52*$D$36 -> 12 | S52: =G52*$D$27 -> 0 | T52: =H52*$D$39 -> 120 | U52: =H52*$D$40 -> 120 | V52: =J52 -> 49 | W52: =K52*0.7 -> 34.3 | X52: 1 | Y52: =ROUND(MAX(M52*0.7,),0) -> 1 | AA52: =C52 -> 49 | AB52: =B52 -> 49 | AC52: =$D$25 -> 20 | AD52: =$D$36 -> 30 | AE52: =$D$27 -> 20 | AF52: =B52*0.1*$D$39 -> 147 | AG52: =B52*0.1*$D$40 -> 147 | AH52: =B52 -> 49 | AI52: =B52*$D$26 -> 980 | AJ52: 1 | AK52: =MIN(AA52*0.1,20) -> 4.9
B53: 50 | C53: =B53 -> 50 | D53: =IF(B53<10,1,ROUNDDOWN(B53,-1)) -> 50 | E53: 1 | F53: 0.7 | G53: =B53 -> 50 | H53: 5 | I53: 0 | J53: 50 | K53: =B53 -> 50 | L53: 1 | M53: 2 | O53: =C53 -> 50 | P53: =D53 -> 50 | Q53: =E53*$D$25 -> 20 | R53: =F53*$D$36 -> 21 | S53: =G53*$D$27 -> 1000 | T53: =H53*$D$39 -> 150 | U53: =H53*$D$40 -> 150 | V53: =J53 -> 50 | W53: =K53*0.7 -> 35 | X53: 1 | Y53: =ROUND(MAX(M53*0.7,),0) -> 1 | AA53: =C53 -> 50 | AB53: =B53 -> 50 | AC53: =$D$25 -> 20 | AD53: =$D$36 -> 30 | AE53: =$D$27 -> 20 | AF53: =B53*0.1*$D$39 -> 150 | AG53: =B53*0.1*$D$40 -> 150 | AH53: =B53 -> 50 | AI53: =B53*$D$26 -> 1000 | AJ53: 1 | AK53: =MIN(AA53*0.1,20) -> 5
B54: 51 | C54: =B54 -> 51 | D54: =IF(B54<10,1,ROUNDDOWN(B54,-1)) -> 50 | E54: 1 | F54: 0.7 | G54: =B54 -> 51 | H54: 5 | I54: 0 | J54: 51 | K54: =B54 -> 51 | L54: 1 | M54: 2 | O54: =C54 -> 51 | P54: =D54 -> 50 | Q54: =E54*$D$25 -> 20 | R54: =F54*$D$36 -> 21 | S54: =G54*$D$27 -> 1020 | T54: =H54*$D$39 -> 150 | U54: =H54*$D$40 -> 150 | V54: =J54 -> 51 | W54: =K54*0.7 -> 35.7 | X54: 1 | Y54: =ROUND(MAX(M54*0.7,),0) -> 1 | AA54: =C54 -> 51 | AB54: =B54 -> 51 | AC54: =$D$25 -> 20 | AD54: =$D$36 -> 30 | AE54: =$D$27 -> 20 | AF54: =B54*0.1*$D$39 -> 153 | AG54: =B54*0.1*$D$40 -> 153 | AH54: =B54 -> 51 | AI54: =B54*$D$26 -> 1020 | AJ54: 1 | AK54: =MIN(AA54*0.1,20) -> 5.1
B55: 52 | C55: =B55 -> 52 | D55: =IF(B55<10,1,ROUNDDOWN(B55,-1)) -> 50 | E55: 1 | F55: 0.7 | G55: =B55 -> 52 | H55: 5 | I55: 0 | J55: 52 | K55: =B55 -> 52 | L55: 1 | M55: 2 | O55: =C55 -> 52 | P55: =D55 -> 50 | Q55: =E55*$D$25 -> 20 | R55: =F55*$D$36 -> 21 | S55: =G55*$D$27 -> 1040 | T55: =H55*$D$39 -> 150 | U55: =H55*$D$40 -> 150 | V55: =J55 -> 52 | W55: =K55*0.7 -> 36.4 | X55: 1 | Y55: =ROUND(MAX(M55*0.7,),0) -> 1 | AA55: =C55 -> 52 | AB55: =B55 -> 52 | AC55: =$D$25 -> 20 | AD55: =$D$36 -> 30 | AE55: =$D$27 -> 20 | AF55: =B55*0.1*$D$39 -> 156 | AG55: =B55*0.1*$D$40 -> 156 | AH55: =B55 -> 52 | AI55: =B55*$D$26 -> 1040 | AJ55: 1 | AK55: =MIN(AA55*0.1,20) -> 5.2
B56: 53 | C56: =B56 -> 53 | D56: =IF(B56<10,1,ROUNDDOWN(B56,-1)) -> 50 | E56: 1 | F56: 0.7 | G56: =B56 -> 53 | H56: 5 | I56: 0 | J56: 53 | K56: =B56 -> 53 | L56: 1 | M56: 2 | O56: =C56 -> 53 | P56: =D56 -> 50 | Q56: =E56*$D$25 -> 20 | R56: =F56*$D$36 -> 21 | S56: =G56*$D$27 -> 1060 | T56: =H56*$D$39 -> 150 | U56: =H56*$D$40 -> 150 | V56: =J56 -> 53 | W56: =K56*0.7 -> 37.1 | X56: 1 | Y56: =ROUND(MAX(M56*0.7,),0) -> 1 | AA56: =C56 -> 53 | AB56: =B56 -> 53 | AC56: =$D$25 -> 20 | AD56: =$D$36 -> 30 | AE56: =$D$27 -> 20 | AF56: =B56*0.1*$D$39 -> 159 | AG56: =B56*0.1*$D$40 -> 159 | AH56: =B56 -> 53 | AI56: =B56*$D$26 -> 1060 | AJ56: 1 | AK56: =MIN(AA56*0.1,20) -> 5.3
B57: 54 | C57: =B57 -> 54 | D57: =IF(B57<10,1,ROUNDDOWN(B57,-1)) -> 50 | E57: 1 | F57: 0.7 | G57: =B57 -> 54 | H57: 5 | I57: 0 | J57: 54 | K57: =B57 -> 54 | L57: 1 | M57: 2 | O57: =C57 -> 54 | P57: =D57 -> 50 | Q57: =E57*$D$25 -> 20 | R57: =F57*$D$36 -> 21 | S57: =G57*$D$27 -> 1080 | T57: =H57*$D$39 -> 150 | U57: =H57*$D$40 -> 150 | V57: =J57 -> 54 | W57: =K57*0.7 -> 37.8 | X57: 1 | Y57: =ROUND(MAX(M57*0.7,),0) -> 1 | AA57: =C57 -> 54 | AB57: =B57 -> 54 | AC57: =$D$25 -> 20 | AD57: =$D$36 -> 30 | AE57: =$D$27 -> 20 | AF57: =B57*0.1*$D$39 -> 162 | AG57: =B57*0.1*$D$40 -> 162 | AH57: =B57 -> 54 | AI57: =B57*$D$26 -> 1080 | AJ57: 1 | AK57: =MIN(AA57*0.1,20) -> 5.4
B58: 55 | C58: =B58 -> 55 | D58: =IF(B58<10,1,ROUNDDOWN(B58,-1)) -> 50 | E58: 1 | F58: 0.7 | G58: =B58 -> 55 | H58: 5 | I58: 0 | J58: 55 | K58: =B58 -> 55 | L58: 1 | M58: 4 | O58: =C58 -> 55 | P58: =D58 -> 50 | Q58: =E58*$D$25 -> 20 | R58: =F58*$D$36 -> 21 | S58: =G58*$D$27 -> 1100 | T58: =H58*$D$39 -> 150 | U58: =H58*$D$40 -> 150 | V58: =J58 -> 55 | W58: =K58*0.7 -> 38.5 | X58: 1 | Y58: =ROUND(MAX(M58*0.7,),0) -> 3 | AA58: =C58 -> 55 | AB58: =B58 -> 55 | AC58: =$D$25 -> 20 | AD58: =$D$36 -> 30 | AE58: =$D$27 -> 20 | AF58: =B58*0.1*$D$39 -> 165 | AG58: =B58*0.1*$D$40 -> 165 | AH58: =B58 -> 55 | AI58: =B58*$D$26 -> 1100 | AJ58: 1 | AK58: =MIN(AA58*0.1,20) -> 5.5
B59: 56 | C59: =B59 -> 56 | D59: =IF(B59<10,1,ROUNDDOWN(B59,-1)) -> 50 | E59: 1 | F59: 0.7 | G59: =B59 -> 56 | H59: 5 | I59: 0 | J59: 56 | K59: =B59 -> 56 | L59: 1 | M59: 4 | O59: =C59 -> 56 | P59: =D59 -> 50 | Q59: =E59*$D$25 -> 20 | R59: =F59*$D$36 -> 21 | S59: =G59*$D$27 -> 1120 | T59: =H59*$D$39 -> 150 | U59: =H59*$D$40 -> 150 | V59: =J59 -> 56 | W59: =K59*0.7 -> 39.2 | X59: 1 | Y59: =ROUND(MAX(M59*0.7,),0) -> 3 | AA59: =C59 -> 56 | AB59: =B59 -> 56 | AC59: =$D$25 -> 20 | AD59: =$D$36 -> 30 | AE59: =$D$27 -> 20 | AF59: =B59*0.1*$D$39 -> 168 | AG59: =B59*0.1*$D$40 -> 168 | AH59: =B59 -> 56 | AI59: =B59*$D$26 -> 1120 | AJ59: 1 | AK59: =MIN(AA59*0.1,20) -> 5.6
B60: 57 | C60: =B60 -> 57 | D60: =IF(B60<10,1,ROUNDDOWN(B60,-1)) -> 50 | E60: 1 | F60: 0.7 | G60: =B60 -> 57 | H60: 5 | I60: 0 | J60: 57 | K60: =B60 -> 57 | L60: 1 | M60: 4 | O60: =C60 -> 57 | P60: =D60 -> 50 | Q60: =E60*$D$25 -> 20 | R60: =F60*$D$36 -> 21 | S60: =G60*$D$27 -> 1140 | T60: =H60*$D$39 -> 150 | U60: =H60*$D$40 -> 150 | V60: =J60 -> 57 | W60: =K60*0.7 -> 39.9 | X60: 1 | Y60: =ROUND(MAX(M60*0.7,),0) -> 3 | AA60: =C60 -> 57 | AB60: =B60 -> 57 | AC60: =$D$25 -> 20 | AD60: =$D$36 -> 30 | AE60: =$D$27 -> 20 | AF60: =B60*0.1*$D$39 -> 171 | AG60: =B60*0.1*$D$40 -> 171 | AH60: =B60 -> 57 | AI60: =B60*$D$26 -> 1140 | AJ60: 1 | AK60: =MIN(AA60*0.1,20) -> 5.7
B61: 58 | C61: =B61 -> 58 | D61: =IF(B61<10,1,ROUNDDOWN(B61,-1)) -> 50 | E61: 1 | F61: 0.7 | G61: =B61 -> 58 | H61: 5 | I61: 0 | J61: 58 | K61: =B61 -> 58 | L61: 1 | M61: 4 | O61: =C61 -> 58 | P61: =D61 -> 50 | Q61: =E61*$D$25 -> 20 | R61: =F61*$D$36 -> 21 | S61: =G61*$D$27 -> 1160 | T61: =H61*$D$39 -> 150 | U61: =H61*$D$40 -> 150 | V61: =J61 -> 58 | W61: =K61*0.7 -> 40.6 | X61: 1 | Y61: =ROUND(MAX(M61*0.7,),0) -> 3 | AA61: =C61 -> 58 | AB61: =B61 -> 58 | AC61: =$D$25 -> 20 | AD61: =$D$36 -> 30 | AE61: =$D$27 -> 20 | AF61: =B61*0.1*$D$39 -> 174 | AG61: =B61*0.1*$D$40 -> 174 | AH61: =B61 -> 58 | AI61: =B61*$D$26 -> 1160 | AJ61: 1 | AK61: =MIN(AA61*0.1,20) -> 5.8
B62: 59 | C62: =B62 -> 59 | D62: =IF(B62<10,1,ROUNDDOWN(B62,-1)) -> 50 | E62: 1 | F62: 0.7 | G62: =B62 -> 59 | H62: 5 | I62: 0 | J62: 59 | K62: =B62 -> 59 | L62: 1 | M62: 4 | O62: =C62 -> 59 | P62: =D62 -> 50 | Q62: =E62*$D$25 -> 20 | R62: =F62*$D$36 -> 21 | S62: =G62*$D$27 -> 1180 | T62: =H62*$D$39 -> 150 | U62: =H62*$D$40 -> 150 | V62: =J62 -> 59 | W62: =K62*0.7 -> 41.3 | X62: 1 | Y62: =ROUND(MAX(M62*0.7,),0) -> 3 | AA62: =C62 -> 59 | AB62: =B62 -> 59 | AC62: =$D$25 -> 20 | AD62: =$D$36 -> 30 | AE62: =$D$27 -> 20 | AF62: =B62*0.1*$D$39 -> 177 | AG62: =B62*0.1*$D$40 -> 177 | AH62: =B62 -> 59 | AI62: =B62*$D$26 -> 1180 | AJ62: 1 | AK62: =MIN(AA62*0.1,20) -> 5.9
B63: 60 | C63: =B63 -> 60 | D63: =IF(B63<10,1,ROUNDDOWN(B63,-1)) -> 60 | E63: 1 | F63: 1 | G63: =B63 -> 60 | H63: 7 | I63: 7 | J63: 60 | K63: =B63 -> 60 | L63: 2 | M63: 8 | O63: =C63 -> 60 | P63: =D63 -> 60 | Q63: =E63*$D$25 -> 20 | R63: =F63*$D$36 -> 30 | S63: =G63*$D$27 -> 1200 | T63: =H63*$D$39 -> 210 | U63: =H63*$D$40 -> 210 | V63: =J63 -> 60 | W63: =K63*0.7 -> 42 | X63: 1 | Y63: =ROUND(MAX(M63*0.7,),0) -> 6 | AA63: =C63 -> 60 | AB63: =B63 -> 60 | AC63: =$D$25 -> 20 | AD63: =$D$36 -> 30 | AE63: =$D$27 -> 20 | AF63: =B63*0.1*$D$39 -> 180 | AG63: =B63*0.1*$D$40 -> 180 | AH63: =B63 -> 60 | AI63: =B63*$D$26 -> 1200 | AJ63: 1 | AK63: =MIN(AA63*0.1,20) -> 6
B64: 61 | C64: =B64 -> 61 | D64: =IF(B64<10,1,ROUNDDOWN(B64,-1)) -> 60 | E64: 1 | F64: 1 | G64: =B64 -> 61 | H64: 7 | I64: 7 | J64: 61 | K64: =B64 -> 61 | L64: 2 | M64: 8 | O64: =C64 -> 61 | P64: =D64 -> 60 | Q64: =E64*$D$25 -> 20 | R64: =F64*$D$36 -> 30 | S64: =G64*$D$27 -> 1220 | T64: =H64*$D$39 -> 210 | U64: =H64*$D$40 -> 210 | V64: =J64 -> 61 | W64: =K64*0.7 -> 42.7 | X64: 1 | Y64: =ROUND(MAX(M64*0.7,),0) -> 6 | AA64: =C64 -> 61 | AB64: =B64 -> 61 | AC64: =$D$25 -> 20 | AD64: =$D$36 -> 30 | AE64: =$D$27 -> 20 | AF64: =B64*0.1*$D$39 -> 183 | AG64: =B64*0.1*$D$40 -> 183 | AH64: =B64 -> 61 | AI64: =B64*$D$26 -> 1220 | AJ64: 1 | AK64: =MIN(AA64*0.1,20) -> 6.1
...

Sheet 道具产出规划
D1: 各道具在各玩法的产出比重
A2: 道具ID | B2: 道具 | C2: 日总产量 | D2: 职业日常 | E2: 日常副本 | F2: 英雄试炼 | G2: 冰封王座 | H2: 考古 | I2: 运镖 | J2: 卡拉赞系列 | K2: 卡拉赞精英 | L2: 精英副本 | M2: 公会任务(周7轮) | N2: 暗夜马戏团(周20轮) | O2: 野外挂机/离线经验 | P2: 经验道具 | Q2: 分享 | R2: 双倍点数 | S2: 帮助战斗 | T2: 魔像 | U2: 巨龙护卫 | V2: 巨龙 | W2: 古神 | X2: 艾泽拉斯地理探索 | Y2: 艾泽拉斯百科竞赛 | Z2: 职业闯关(周2次) | AA2: 竞技场 | AB2: 公会副本(周1次) | AC2: 帮派强盗 | AD2: 帮派采药 | AE2: 节日活动1 | AF2: 节日活动2 | AG2: 活跃度打卡 | AH2: 日常副本roll | AI2: 迪奥布斯 | AJ2: 队长礼盒 | AK2: 迪奥布斯宝箱 | AL2: 精英副本roll
A3: 200061 | B3: 小血瓶蓝瓶库 | C3: =SUM(D3:BC3) -> 3.2 | D3: 1.2 | X3: 1 | Y3: 1
A4: 200062 | B4: 大血瓶蓝瓶库 | C4: =SUM(D4:BC4) -> 0.7 | D4: 0.2 | L4: 0.5
A5: 200063 | B5: 一级药库 | C5: =SUM(D5:BC5) -> 22.35 | E5: 10 | M5: 2 | Z5: 5.85 | AJ5: 3 | AK5: 1.5
A6: 200064 | B6: 二级药库 | C6: =SUM(D6:BC6) -> 12.9 | E6: 5 | M6: 1 | Z6: 3.9 | AJ6: 2 | AK6: 1
A7: 200065 | B7: 洗单点卷轴库 | C7: =SUM(D7:BC7) -> 0
A8: 200066 | B8: 修炼丹库 | C8: =SUM(D8:BC8) -> 12.1 | D8: 0.6 | G8: 2 | L8: 2 | V8: 0.5 | W8: 3 | X8: 1 | Y8: 1 | AG8: 1 | AK8: 1
A9: 200067 | B9: 打造强化石库 | C9: =SUM(D9:BC9) -> 1 | G9: 1
A10: 200068 | B10: 1级宝石库 | C10: =SUM(D10:BC10) -> 5.7 | G10: 1 | H10: 1 | L10: 1 | Y10: 1 | AA10: 0.5 | AG10: 1 | AK10: 0.2
A11: 200069 | B11: 2级宝石库 | C11: =SUM(D11:BC11) -> 0.895 | G11: 0.5 | Z11: 0.195 | AA11: 0.2
A12: 200070 | B12: 3级宝石库 | C12: =SUM(D12:BC12) -> 0.065 | Z12: 0.065
A13: 200071 | B13: 低级魔兽要诀库 | C13: =SUM(D13:BC13) -> 0.465 | H13: 0.2 | L13: 0.1 | Z13: 0.065 | AA13: 0.1
A14: 200072 | B14: 高级魔兽要诀库 | C14: =SUM(D14:BC14) -> 0.0025 | Z14: 0.0025
A15: 200073 | B15: 光环卷轴库 | C15: =SUM(D15:BC15) -> 0.3 | G15: 0.1 | H15: 0.2
A16: 200074 | B16: 珍稀五宝库 | C16: =SUM(D16:BC16) -> 0.635 | L16: 0.015 | W16: 0.3 | Z16: 0.02 | AA16: 0.2 | AJ16: 0.1
A17: 200075 | B17: 普通五宝库 | C17: =SUM(D17:BC17) -> 1.49 | H17: 0.3 | L17: 0.03 | V17: 0.5 | Z17: 0.06 | AA17: 0.6
A18: 200076 | B18: 坐骑库 | C18: =SUM(D18:BC18) -> 0
A19: 200167 | B19: 硬肉干 | C19: =SUM(D19:BC19) -> 0
A20: 200168 | B20: 恢复合剂 | C20: =SUM(D20:BC20) -> 1 | G20: 1
A21: 200169 | B21: 经验宝珠 | C21: =SUM(D21:BC21) -> 8.3 | D21: 0.6 | F21: 1 | G21: 0.5 | T21: 0.8 | V21: 0.6 | AJ21: 4 | AK21: 0.8
A22: 200170 | B22: 歌唱水晶 | C22: =SUM(D22:BC22) -> 0
A23: 200171 | B23: 修理宝石 | C23: =SUM(D23:BC23) -> 0.1 | V23: 0.1
A24: 200172 | B24: 光环卷轴碎片 | C24: =SUM(D24:BC24) -> 4.9 | G24: 2 | H24: 0.5 | X24: 1 | AJ24: 0.9 | AK24: 0.5
A25: 200173 | B25: 营养套餐 | C25: =SUM(D25:BC25) -> 1.9 | H25: 0.4 | U25: 1 | Y25: 0.5
A26: 200174 | B26: 高级营养套餐 | C26: =SUM(D26:BC26) -> 0.9 | H26: 0.2 | U26: 0.2 | V26: 0.5
A27: 200175 | B27: 资质影砂 | C27: =SUM(D27:BC27) -> 0.07 | L27: 0.02 | AA27: 0.05
A28: 200176 | B28: 兽王纲要 | C28: =SUM(D28:BC28) -> 0.04 | G28: 0.04
A29: 200177 | B29: 太阳井水 | C29: =SUM(D29:BC29) -> 2.8 | G29: 0.25 | H29: 0.25 | L29: 0.8 | T29: 0.5 | AG29: 1
A30: 200178 | B30: 永恒井水 | C30: =SUM(D30:BC30) -> 0
A31: 200179 | B31: 宠物零食 | C31: =SUM(D31:BC31) -> 0
A32: 200180 | B32: 藏宝图 | C32: =SUM(D32:BC32) -> 12.39 | H32: 10 | V32: 1 | Z32: 0.39 | AG32: 1
A33: 200181 | B33: 高级藏宝图 | C33: =SUM(D33:BC33) -> 0.0015 | Z33: 0.0015
A34: 200182 | B34: 染料 | C34: =SUM(D34:BC34) -> 0.072 | N34: 0.072
A35: 200183 | B35: 浓缩染料 | C35: =SUM(D35:BC35) -> 0.26 | L35: 0.1 | N35: 0.01 | T35: 0.05 | V35: 0.1
A36: 200184 | B36: 宠物染料 | C36: =SUM(D36:BC36) -> 0.02 | N36: 0.02
A37: 200185 | B37: 队长礼盒 | C37: =SUM(D37:BC37) -> 0
A38: 200186 | B38: 10级铁 | C38: =SUM(D38:BC38) -> 0
A39: 200187 | B39: 20级铁 | C39: =SUM(D39:BC39) -> 0
A40: 200188 | B40: 30级铁 | C40: =SUM(D40:BC40) -> 0.1 | H40: 0.1
...

Sheet 道具消耗核算

Sheet 掉落规则说明
B1: 奖励表中每个掉落点ID中掉落物品ID为道具经济表（道具产出规划）中的掉落物品ID。
B2: 掉落物品库的意思是同类型物品做在一个掉落ID中。库中的物品掉落几率按照类型个数均分。
B3: 掉落点ID一栏的物品1类至物品16类为这个掉落点ID所掉的所有掉落物品
B4: 物品N类权重是对应物品N类的掉落权重（总权重为1000，部分总权重有变动是为了必掉），
B5: 按照以上规则每个掉落点只能掉一个物品。为解决同一掉落点可以同时掉多个物品的问题，可以在奖励表中的必给物品ID一栏中添加其他掉落点ID，此掉落点可同时触发其他掉落点中的物品
B6: 道具经济表中的页签中是不同玩法所掉落的物品种类以及掉落权重
V10: 掉落物品ID | W10: 物品名称
B11: 掉落点ID | C11: 掉落包名称 | D11: 物品1类 | E11: 物品2类 | F11: 物品3类 | G11: 到物品16类 | I11: 物品1类权重 | J11: 物品2类权重 | K11: 物品3类权重 | L11: 到物品16类 | M11: 总权重 | V11: 200061 | W11: 小血瓶蓝瓶库 | X11: =SUM(Y11:BW11) -> 0
B12: 5000 | C12: 职业日常每环奖励0 | V12: 200062 | W12: 大血瓶蓝瓶库 | X12: =SUM(Y12:BW12) -> 0
B13: 5001 | C13: 职业日常每轮奖励0 | V13: 200063 | W13: 一级药库 | X13: =SUM(Y13:BW13) -> 0
B14: 5002 | C14: 职业日常每轮奖励附加 | V14: 200064 | W14: 二级药库 | X14: =SUM(Y14:BW14) -> 0
B15: 5003 | C15: 职业日常高品和额外 | V15: 200065 | W15: 洗单点卷轴库 | X15: =SUM(Y15:BW15) -> 0
B16: 5004 | C16: 特殊职业日常 | V16: 200066 | W16: 修炼丹库 | X16: =SUM(Y16:BW16) -> 0
B17: 5010 | C17: 日常副本开双附加道具20级 | V17: 200067 | W17: 打造强化石库 | X17: =SUM(Y17:BW17) -> 0
B18: 5020 | C18: 日常副本开双附加道具30级 | V18: 200068 | W18: 1级宝石库 | X18: =SUM(Y18:BW18) -> 0
B19: 5030 | C19: 日常副本开双附加道具40级 | V19: 200069 | W19: 2级宝石库 | X19: =SUM(Y19:BW19) -> 0
B20: 5040 | C20: 日常副本开双附加道具50级 | V20: 200070 | W20: 3级宝石库 | X20: =SUM(Y20:BW20) -> 0
B21: 5050 | C21: 日常副本开双附加道具60级 | V21: 200071 | W21: 低级魔兽要诀库 | X21: =SUM(Y21:BW21) -> 0
B22: 5060 | C22: 日常副本开双附加道具70级以上 | V22: 200072 | W22: 高级魔兽要诀库 | X22: =SUM(Y22:BW22) -> 0
B23: 5070 | C23: 日常副本基础20级0 | V23: 200073 | W23: 光环卷轴库 | X23: =SUM(Y23:BW23) -> 0
... B148: 6290 | C148: 公会副本宝箱 | V148: 200164 | W148: 10级橙装库 | X148: =SUM(Y148:BW148) -> 0
V149: 200165 | W149: 10级橙装库 | X149: =SUM(Y149:BW149) -> 0
V150: 200166 | W150: 10级橙装库 | X150: =SUM(Y150:BW150) -> 0

Sheet 职业日常
B3: 道具ID | C3: 道具 | D3: 日总产量 | E3: 职业日常 | F3: 概率 | G3: 掉落次数 | H3: 掉落权重 | I3: 总权重
B4: {=INDEX(道具产出规划!$A:$A,SMALL(IF(LEN(INDIRECT(ADDRESS(3,MATCH(E$3,道具产出规划!$2:$2,0),1,TRUE,"道具产出规划")):INDIRECT(ADDRESS(1000,MATCH(E$3,道具产出规划!$2:$2,0),1,TRUE,"道具产出规划")))>0,ROW(道具产出规划!$3:$998),2^20),ROW(道具产出规划!$A1)))&""} -> 200061 | C4: {=INDEX(道具产出规划!$B:$B,SMALL(IF(LEN(INDIRECT(ADDRESS(3,MATCH(E$3,道具产出规划!$2:$2,0),1,TRUE,"道具产出规划")):INDIRECT(ADDRESS(1000,MATCH(E$3,道具产出规划!$2:$2,0),1,TRUE,"道具产出规划")))>0,ROW(道具产出规划!$3:$998),2^20),ROW(道具产出规划!$A1)))&""} -> 小血瓶蓝瓶库 | D4: {=INDEX(道具产出规划!$C:$C,SMALL(IF(LEN(INDIRECT(ADDRESS(3,MATCH(E$3,道具产出规划!$2:$2,0),1,TRUE,"道具产出规划")):INDIRECT(ADDRESS(1000,MATCH(E$3,道具产出规划!$2:$2,0),1,TRUE,"道具产出规划")))>0,ROW(道具产出规划!$3:$998),2^20),ROW(道具产出规划!$A1)))&""} -> 3.2 | E4: =IF(B4="","",VLOOKUP(--B4,道具产出规划!$A$2:$AN$238,MATCH(E$3,道具产出规划!$2:$2,0),0)) -> 1.2 | F4: =E4/50 -> 0.024 | G4: 50 | H4: 200 | I4: 1000
B5: {=INDEX(道具产出规划!$A:$A,SMALL(IF(LEN(INDIRECT(ADDRESS(3,MATCH(E$3,道具产出规划!$2:$2,0),1,TRUE,"道具产出规划")):INDIRECT(ADDRESS(1000,MATCH(E$3,道具产出规划!$2:$2,0),1,TRUE,"道具产出规划")))>0,ROW(道具产出规划!$3:$998),2^20),ROW(道具产出规划!$A2)))&""} -> 200062 | C5: {=INDEX(道具产出规划!$B:$B,SMALL(IF(LEN(INDIRECT(ADDRESS(3,MATCH(E$3,道具产出规划!$2:$2,0),1,TRUE,"道具产出规划")):INDIRECT(ADDRESS(1000,MATCH(E$3,道具产出规划!$2:$2,0),1,TRUE,"道具产出规划")))>0,ROW(道具产出规划!$3:$998),2^20),ROW(道具产出规划!$A2)))&""} -> 大血瓶蓝瓶库 | D5: {=INDEX(道具产出规划!$C:$C,SMALL(IF(LEN(INDIRECT(ADDRESS(3,MATCH(E$3,道具产出规划!$2:$2,0),1,TRUE,"道具产出规划")):INDIRECT(ADDRESS(1000,MATCH(E$3,道具产出规划!$2:$2,0),1,TRUE,"道具产出规划")))>0,ROW(道具产出规划!$3:$998),2^20),ROW(道具产出规划!$A2)))&""} -> 0.7 | E5: =IF(B5="","",VLOOKUP(--B5,道具产出规划!$A$2:$AN$238,MATCH(E$3,道具产出规划!$2:$2,0),0)) -> 0.2 | F5: =E5/50 -> 0.004 | G5: 50 | H5: 100 | I5: 1000
B6: {=INDEX(道具产出规划!$A:$A,SMALL(IF(LEN(INDIRECT(ADDRESS(3,MATCH(E$3,道具产出规划!$2:$2,0),1,TRUE,"道具产出规划")):INDIRECT(ADDRESS(1000,MATCH(E$3,道具产出规划!$2:$2,0),1,TRUE,"道具产出规划")))>0,ROW(道具产出规划!$3:$998),2^20),ROW(道具产出规划!$A3)))&""} -> 200066 | C6: {=INDEX(道具产出规划!$B:$B,SMALL(IF(LEN(INDIRECT(ADDRESS(3,MATCH(E$3,道具产出规划!$2:$2,0),1,TRUE,"道具产出规划")):INDIRECT(ADDRESS(1000,MATCH(E$3,道具产出规划!$2:$2,0),1,TRUE,"道具产出规划")))>0,ROW(道具产出规划!$3:$998),2^20),ROW(道具产出规划!$A3)))&""} -> 修炼丹库 | D6: {=INDEX(道具产出规划!$C:$C,SMALL(IF(LEN(INDIRECT(ADDRESS(3,MATCH(E$3,道具产出规划!$2:$2,0),1,TRUE,"道具产出规划")):INDIRECT(ADDRESS(1000,MATCH(E$3,道具产出规划!$2:$2,0),1,TRUE,"道具产出规划")))>0,ROW(道具产出规划!$3:$998),2^20),ROW(道具产出规划!$A3)))&""} -> 12.1 | E6: =IF(B6="","",VLOOKUP(--B6,道具产出规划!$A$2:$AN$238,MATCH(E$3,道具产出规划!$2:$2,0),0)) -> 0.6 | F6: =E6/50 -> 0.012 | G6: 50 | H6: 160 | I6: 1000
